Workbook

Sheet Cover
B3: Configuration Parameters
B5: Generated: | C5: August 17, 2026
B6: Solution: | C6: Tmpy52K93Pk
B7: Customer: | C7: [Customer Name]
B8: Version: | C8: 1.0
B9: Status: | C9: Draft
C12: eoframework.org

Sheet All Parameters (Read Only)
A1: Total Parameters | B1: Categories | C1: Required | D1: Confidential/Secret
A2: 114 | B2: 8 | C2: 114 | D2: 44
A4: Parameter Name | B4: Category | C4: Production | D4: Test | E4: DR | F4: Description | G4: Required | H4: Data Type | I4: Validation Rules | J4: Security Level | K4: Owner Team | L4: Dependencies | M4: Notes | N4: Last Updated
A5: =IF('Project'!A3="","",'Project'!A3) | B5: Project | C5: =IF('Project'!B3="","",'Project'!B3) | D5: =IF('Project'!C3="","",'Project'!C3) | E5: =IF('Project'!D3="","",'Project'!D3) | F5: =IF('Project'!E3="","",'Project'!E3) | G5: =IF('Project'!F3="","",'Project'!F3) | H5: =IF('Project'!G3="","",'Project'!G3) | I5: =IF('Project'!H3="","",'Project'!H3) | J5: =IF('Project'!I3="","",'Project'!I3) | ... N5: =IF('Project'!M3="","",'Project'!M3)
A6: =IF('Project'!A4="","",'Project'!A4) | B6: Project | C6: =IF('Project'!B4="","",'Project'!B4) | D6: =IF('Project'!C4="","",'Project'!C4) | E6: =IF('Project'!D4="","",'Project'!D4) | F6: =IF('Project'!E4="","",'Project'!E4) | G6: =IF('Project'!F4="","",'Project'!F4) | H6: =IF('Project'!G4="","",'Project'!G4) | I6: =IF('Project'!H4="","",'Project'!H4) | J6: =IF('Project'!I4="","",'Project'!I4) | ... N6: =IF('Project'!M4="","",'Project'!M4)
A7: =IF('Project'!A5="","",'Project'!A5) | B7: Project | C7: =IF('Project'!B5="","",'Project'!B5) | D7: =IF('Project'!C5="","",'Project'!C5) | E7: =IF('Project'!D5="","",'Project'!D5) | F7: =IF('Project'!E5="","",'Project'!E5) | G7: =IF('Project'!F5="","",'Project'!F5) | H7: =IF('Project'!G5="","",'Project'!G5) | I7: =IF('Project'!H5="","",'Project'!H5) | J7: =IF('Project'!I5="","",'Project'!I5) | ... N7: =IF('Project'!M5="","",'Project'!M5)
A8: =IF('Project'!A6="","",'Project'!A6) | B8: Project | C8: =IF('Project'!B6="","",'Project'!B6) | D8: =IF('Project'!C6="","",'Project'!C6) | E8: =IF('Project'!D6="","",'Project'!D6) | F8: =IF('Project'!E6="","",'Project'!E6) | G8: =IF('Project'!F6="","",'Project'!F6) | H8: =IF('Project'!G6="","",'Project'!G6) | I8: =IF('Project'!H6="","",'Project'!H6) | J8: =IF('Project'!I6="","",'Project'!I6) | ... N8: =IF('Project'!M6="","",'Project'!M6)
A9: =IF('Project'!A7="","",'Project'!A7) | B9: Project | C9: =IF('Project'!B7="","",'Project'!B7) | D9: =IF('Project'!C7="","",'Project'!C7) | E9: =IF('Project'!D7="","",'Project'!D7) | F9: =IF('Project'!E7="","",'Project'!E7) | G9: =IF('Project'!F7="","",'Project'!F7) | H9: =IF('Project'!G7="","",'Project'!G7) | I9: =IF('Project'!H7="","",'Project'!H7) | J9: =IF('Project'!I7="","",'Project'!I7) | ... N9: =IF('Project'!M7="","",'Project'!M7)
A10: =IF('Project'!A8="","",'Project'!A8) | B10: Project | C10: =IF('Project'!B8="","",'Project'!B8) | D10: =IF('Project'!C8="","",'Project'!C8) | E10: =IF('Project'!D8="","",'Project'!D8) | F10: =IF('Project'!E8="","",'Project'!E8) | G10: =IF('Project'!F8="","",'Project'!F8) | H10: =IF('Project'!G8="","",'Project'!G8) | I10: =IF('Project'!H8="","",'Project'!H8) | J10: =IF('Project'!I8="","",'Project'!I8) | ... N10: =IF('Project'!M8="","",'Project'!M8)
A11: =IF('Project'!A9="","",'Project'!A9) | B11: Project | C11: =IF('Project'!B9="","",'Project'!B9) | D11: =IF('Project'!C9="","",'Project'!C9) | E11: =IF('Project'!D9="","",'Project'!D9) | F11: =IF('Project'!E9="","",'Project'!E9) | G11: =IF('Project'!F9="","",'Project'!F9) | H11: =IF('Project'!G9="","",'Project'!G9) | I11: =IF('Project'!H9="","",'Project'!H9) | J11: =IF('Project'!I9="","",'Project'!I9) | ... N11: =IF('Project'!M9="","",'Project'!M9)
A12: =IF('Project'!A10="","",'Project'!A10) | B12: Project | C12: =IF('Project'!B10="","",'Project'!B10) | D12: =IF('Project'!C10="","",'Project'!C10) | E12: =IF('Project'!D10="","",'Project'!D10) | F12: =IF('Project'!E10="","",'Project'!E10) | G12: =IF('Project'!F10="","",'Project'!F10) | H12: =IF('Project'!G10="","",'Project'!G10) | I12: =IF('Project'!H10="","",'Project'!H10) | J12: =IF('Project'!I10="","",'Project'!I10) | ... N12: =IF('Project'!M10="","",'Project'!M10)
A13: =IF('Project'!A11="","",'Project'!A11) | B13: Project | C13: =IF('Project'!B11="","",'Project'!B11) | D13: =IF('Project'!C11="","",'Project'!C11) | E13: =IF('Project'!D11="","",'Project'!D11) | F13: =IF('Project'!E11="","",'Project'!E11) | G13: =IF('Project'!F11="","",'Project'!F11) | H13: =IF('Project'!G11="","",'Project'!G11) | I13: =IF('Project'!H11="","",'Project'!H11) | J13: =IF('Project'!I11="","",'Project'!I11) | ... N13: =IF('Project'!M11="","",'Project'!M11)
A14: =IF('Project'!A12="","",'Project'!A12) | B14: Project | C14: =IF('Project'!B12="","",'Project'!B12) | D14: =IF('Project'!C12="","",'Project'!C12) | E14: =IF('Project'!D12="","",'Project'!D12) | F14: =IF('Project'!E12="","",'Project'!E12) | G14: =IF('Project'!F12="","",'Project'!F12) | H14: =IF('Project'!G12="","",'Project'!G12) | I14: =IF('Project'!H12="","",'Project'!H12) | J14: =IF('Project'!I12="","",'Project'!I12) | ... N14: =IF('Project'!M12="","",'Project'!M12)
A15: =IF('Project'!A13="","",'Project'!A13) | B15: Project | C15: =IF('Project'!B13="","",'Project'!B13) | D15: =IF('Project'!C13="","",'Project'!C13) | E15: =IF('Project'!D13="","",'Project'!D13) | F15: =IF('Project'!E13="","",'Project'!E13) | G15: =IF('Project'!F13="","",'Project'!F13) | H15: =IF('Project'!G13="","",'Project'!G13) | I15: =IF('Project'!H13="","",'Project'!H13) | J15: =IF('Project'!I13="","",'Project'!I13) | ... N15: =IF('Project'!M13="","",'Project'!M13)
A16: =IF('Project'!A14="","",'Project'!A14) | B16: Project | C16: =IF('Project'!B14="","",'Project'!B14) | D16: =IF('Project'!C14="","",'Project'!C14) | E16: =IF('Project'!D14="","",'Project'!D14) | F16: =IF('Project'!E14="","",'Project'!E14) | G16: =IF('Project'!F14="","",'Project'!F14) | H16: =IF('Project'!G14="","",'Project'!G14) | I16: =IF('Project'!H14="","",'Project'!H14) | J16: =IF('Project'!I14="","",'Project'!I14) | ... N16: =IF('Project'!M14="","",'Project'!M14)
... A24: =IF('Project'!A22="","",'Project'!A22) | B24: Project | C24: =IF('Project'!B22="","",'Project'!B22) | D24: =IF('Project'!C22="","",'Project'!C22) | E24: =IF('Project'!D22="","",'Project'!D22) | F24: =IF('Project'!E22="","",'Project'!E22) | G24: =IF('Project'!F22="","",'Project'!F22) | H24: =IF('Project'!G22="","",'Project'!G22) | I24: =IF('Project'!H22="","",'Project'!H22) | J24: =IF('Project'!I22="","",'Project'!I22) | ... N24: =IF('Project'!M22="","",'Project'!M22)
A25: =IF('Networking'!A3="","",'Networking'!A3) | B25: Networking | C25: =IF('Networking'!B3="","",'Networking'!B3) | D25: =IF('Networking'!C3="","",'Networking'!C3) | E25: =IF('Networking'!D3="","",'Networking'!D3) | F25: =IF('Networking'!E3="","",'Networking'!E3) | G25: =IF('Networking'!F3="","",'Networking'!F3) | H25: =IF('Networking'!G3="","",'Networking'!G3) | I25: =IF('Networking'!H3="","",'Networking'!H3) | J25: =IF('Networking'!I3="","",'Networking'!I3) | ... N25: =IF('Networking'!M3="","",'Networking'!M3)
A26: =IF('Networking'!A4="","",'Networking'!A4) | B26: Networking | C26: =IF('Networking'!B4="","",'Networking'!B4) | D26: =IF('Networking'!C4="","",'Networking'!C4) | E26: =IF('Networking'!D4="","",'Networking'!D4) | F26: =IF('Networking'!E4="","",'Networking'!E4) | G26: =IF('Networking'!F4="","",'Networking'!F4) | H26: =IF('Networking'!G4="","",'Networking'!G4) | I26: =IF('Networking'!H4="","",'Networking'!H4) | J26: =IF('Networking'!I4="","",'Networking'!I4) | ... N26: =IF('Networking'!M4="","",'Networking'!M4)
A27: =IF('Networking'!A5="","",'Networking'!A5) | B27: Networking | C27: =IF('Networking'!B5="","",'Networking'!B5) | D27: =IF('Networking'!C5="","",'Networking'!C5) | E27: =IF('Networking'!D5="","",'Networking'!D5) | F27: =IF('Networking'!E5="","",'Networking'!E5) | G27: =IF('Networking'!F5="","",'Networking'!F5) | H27: =IF('Networking'!G5="","",'Networking'!G5) | I27: =IF('Networking'!H5="","",'Networking'!H5) | J27: =IF('Networking'!I5="","",'Networking'!I5) | ... N27: =IF('Networking'!M5="","",'Networking'!M5)
A28: =IF('Networking'!A6="","",'Networking'!A6) | B28: Networking | C28: =IF('Networking'!B6="","",'Networking'!B6) | D28: =IF('Networking'!C6="","",'Networking'!C6) | E28: =IF('Networking'!D6="","",'Networking'!D6) | F28: =IF('Networking'!E6="","",'Networking'!E6) | G28: =IF('Networking'!F6="","",'Networking'!F6) | H28: =IF('Networking'!G6="","",'Networking'!G6) | I28: =IF('Networking'!H6="","",'Networking'!H6) | J28: =IF('Networking'!I6="","",'Networking'!I6) | ... N28: =IF('Networking'!M6="","",'Networking'!M6)
A29: =IF('Networking'!A7="","",'Networking'!A7) | B29: Networking | C29: =IF('Networking'!B7="","",'Networking'!B7) | D29: =IF('Networking'!C7="","",'Networking'!C7) | E29: =IF('Networking'!D7="","",'Networking'!D7) | F29: =IF('Networking'!E7="","",'Networking'!E7) | G29: =IF('Networking'!F7="","",'Networking'!F7) | H29: =IF('Networking'!G7="","",'Networking'!G7) | I29: =IF('Networking'!H7="","",'Networking'!H7) | J29: =IF('Networking'!I7="","",'Networking'!I7) | ... N29: =IF('Networking'!M7="","",'Networking'!M7)
A30: =IF('Networking'!A8="","",'Networking'!A8) | B30: Networking | C30: =IF('Networking'!B8="","",'Networking'!B8) | D30: =IF('Networking'!C8="","",'Networking'!C8) | E30: =IF('Networking'!D8="","",'Networking'!D8) | F30: =IF('Networking'!E8="","",'Networking'!E8) | G30: =IF('Networking'!F8="","",'Networking'!F8) | H30: =IF('Networking'!G8="","",'Networking'!G8) | I30: =IF('Networking'!H8="","",'Networking'!H8) | J30: =IF('Networking'!I8="","",'Networking'!I8) | ... N30: =IF('Networking'!M8="","",'Networking'!M8)
A31: =IF('Networking'!A9="","",'Networking'!A9) | B31: Networking | C31: =IF('Networking'!B9="","",'Networking'!B9) | D31: =IF('Networking'!C9="","",'Networking'!C9) | E31: =IF('Networking'!D9="","",'Networking'!D9) | F31: =IF('Networking'!E9="","",'Networking'!E9) | G31: =IF('Networking'!F9="","",'Networking'!F9) | H31: =IF('Networking'!G9="","",'Networking'!G9) | I31: =IF('Networking'!H9="","",'Networking'!H9) | J31: =IF('Networking'!I9="","",'Networking'!I9) | ... N31: =IF('Networking'!M9="","",'Networking'!M9)
A32: =IF('Networking'!A10="","",'Networking'!A10) | B32: Networking | C32: =IF('Networking'!B10="","",'Networking'!B10) | D32: =IF('Networking'!C10="","",'Networking'!C10) | E32: =IF('Networking'!D10="","",'Networking'!D10) | F32: =IF('Networking'!E10="","",'Networking'!E10) | G32: =IF('Networking'!F10="","",'Networking'!F10) | H32: =IF('Networking'!G10="","",'Networking'!G10) | I32: =IF('Networking'!H10="","",'Networking'!H10) | J32: =IF('Networking'!I10="","",'Networking'!I10) | ... N32: =IF('Networking'!M10="","",'Networking'!M10)
A33: =IF('Networking'!A11="","",'Networking'!A11) | B33: Networking | C33: =IF('Networking'!B11="","",'Networking'!B11) | D33: =IF('Networking'!C11="","",'Networking'!C11) | E33: =IF('Networking'!D11="","",'Networking'!D11) | F33: =IF('Networking'!E11="","",'Networking'!E11) | G33: =IF('Networking'!F11="","",'Networking'!F11) | H33: =IF('Networking'!G11="","",'Networking'!G11) | I33: =IF('Networking'!H11="","",'Networking'!H11) | J33: =IF('Networking'!I11="","",'Networking'!I11) | ... N33: =IF('Networking'!M11="","",'Networking'!M11)
A34: =IF('Networking'!A12="","",'Networking'!A12) | B34: Networking | C34: =IF('Networking'!B12="","",'Networking'!B12) | D34: =IF('Networking'!C12="","",'Networking'!C12) | E34: =IF('Networking'!D12="","",'Networking'!D12) | F34: =IF('Networking'!E12="","",'Networking'!E12) | G34: =IF('Networking'!F12="","",'Networking'!F12) | H34: =IF('Networking'!G12="","",'Networking'!G12) | I34: =IF('Networking'!H12="","",'Networking'!H12) | J34: =IF('Networking'!I12="","",'Networking'!I12) | ... N34: =IF('Networking'!M12="","",'Networking'!M12)
A35: =IF('Networking'!A13="","",'Networking'!A13) | B35: Networking | C35: =IF('Networking'!B13="","",'Networking'!B13) | D35: =IF('Networking'!C13="","",'Networking'!C13) | E35: =IF('Networking'!D13="","",'Networking'!D13) | F35: =IF('Networking'!E13="","",'Networking'!E13) | G35: =IF('Networking'!F13="","",'Networking'!F13) | H35: =IF('Networking'!G13="","",'Networking'!G13) | I35: =IF('Networking'!H13="","",'Networking'!H13) | J35: =IF('Networking'!I13="","",'Networking'!I13) | ... N35: =IF('Networking'!M13="","",'Networking'!M13)
A36: =IF('Networking'!A14="","",'Networking'!A14) | B36: Networking | C36: =IF('Networking'!B14="","",'Networking'!B14) | D36: =IF('Networking'!C14="","",'Networking'!C14) | E36: =IF('Networking'!D14="","",'Networking'!D14) | F36: =IF('Networking'!E14="","",'Networking'!E14) | G36: =IF('Networking'!F14="","",'Networking'!F14) | H36: =IF('Networking'!G14="","",'Networking'!G14) | I36: =IF('Networking'!H14="","",'Networking'!H14) | J36: =IF('Networking'!I14="","",'Networking'!I14) | ... N36: =IF('Networking'!M14="","",'Networking'!M14)
... A39: =IF('Networking'!A17="","",'Networking'!A17) | B39: Networking | C39: =IF('Networking'!B17="","",'Networking'!B17) | D39: =IF('Networking'!C17="","",'Networking'!C17) | E39: =IF('Networking'!D17="","",'Networking'!D17) | F39: =IF('Networking'!E17="","",'Networking'!E17) | G39: =IF('Networking'!F17="","",'Networking'!F17) | H39: =IF('Networking'!G17="","",'Networking'!G17) | I39: =IF('Networking'!H17="","",'Networking'!H17) | J39: =IF('Networking'!I17="","",'Networking'!I17) | ... N39: =IF('Networking'!M17="","",'Networking'!M17)
A40: =IF('Security'!A3="","",'Security'!A3) | B40: Security | C40: =IF('Security'!B3="","",'Security'!B3) | D40: =IF('Security'!C3="","",'Security'!C3) | E40: =IF('Security'!D3="","",'Security'!D3) | F40: =IF('Security'!E3="","",'Security'!E3) | G40: =IF('Security'!F3="","",'Security'!F3) | H40: =IF('Security'!G3="","",'Security'!G3) | I40: =IF('Security'!H3="","",'Security'!H3) | J40: =IF('Security'!I3="","",'Security'!I3) | ... N40: =IF('Security'!M3="","",'Security'!M3)
A41: =IF('Security'!A4="","",'Security'!A4) | B41: Security | C41: =IF('Security'!B4="","",'Security'!B4) | D41: =IF('Security'!C4="","",'Security'!C4) | E41: =IF('Security'!D4="","",'Security'!D4) | F41: =IF('Security'!E4="","",'Security'!E4) | G41: =IF('Security'!F4="","",'Security'!F4) | H41: =IF('Security'!G4="","",'Security'!G4) | I41: =IF('Security'!H4="","",'Security'!H4) | J41: =IF('Security'!I4="","",'Security'!I4) | ... N41: =IF('Security'!M4="","",'Security'!M4)
A42: =IF('Security'!A5="","",'Security'!A5) | B42: Security | C42: =IF('Security'!B5="","",'Security'!B5) | D42: =IF('Security'!C5="","",'Security'!C5) | E42: =IF('Security'!D5="","",'Security'!D5) | F42: =IF('Security'!E5="","",'Security'!E5) | G42: =IF('Security'!F5="","",'Security'!F5) | H42: =IF('Security'!G5="","",'Security'!G5) | I42: =IF('Security'!H5="","",'Security'!H5) | J42: =IF('Security'!I5="","",'Security'!I5) | ... N42: =IF('Security'!M5="","",'Security'!M5)
A43: =IF('Security'!A6="","",'Security'!A6) | B43: Security | C43: =IF('Security'!B6="","",'Security'!B6) | D43: =IF('Security'!C6="","",'Security'!C6) | E43: =IF('Security'!D6="","",'Security'!D6) | F43: =IF('Security'!E6="","",'Security'!E6) | G43: =IF('Security'!F6="","",'Security'!F6) | H43: =IF('Security'!G6="","",'Security'!G6) | I43: =IF('Security'!H6="","",'Security'!H6) | J43: =IF('Security'!I6="","",'Security'!I6) | ... N43: =IF('Security'!M6="","",'Security'!M6)
A44: =IF('Security'!A7="","",'Security'!A7) | B44: Security | C44: =IF('Security'!B7="","",'Security'!B7) | D44: =IF('Security'!C7="","",'Security'!C7) | E44: =IF('Security'!D7="","",'Security'!D7) | F44: =IF('Security'!E7="","",'Security'!E7) | G44: =IF('Security'!F7="","",'Security'!F7) | H44: =IF('Security'!G7="","",'Security'!G7) | I44: =IF('Security'!H7="","",'Security'!H7) | J44: =IF('Security'!I7="","",'Security'!I7) | ... N44: =IF('Security'!M7="","",'Security'!M7)
A45: =IF('Security'!A8="","",'Security'!A8) | B45: Security | C45: =IF('Security'!B8="","",'Security'!B8) | D45: =IF('Security'!C8="","",'Security'!C8) | E45: =IF('Security'!D8="","",'Security'!D8) | F45: =IF('Security'!E8="","",'Security'!E8) | G45: =IF('Security'!F8="","",'Security'!F8) | H45: =IF('Security'!G8="","",'Security'!G8) | I45: =IF('Security'!H8="","",'Security'!H8) | J45: =IF('Security'!I8="","",'Security'!I8) | ... N45: =IF('Security'!M8="","",'Security'!M8)
A46: =IF('Security'!A9="","",'Security'!A9) | B46: Security | C46: =IF('Security'!B9="","",'Security'!B9) | D46: =IF('Security'!C9="","",'Security'!C9) | E46: =IF('Security'!D9="","",'Security'!D9) | F46: =IF('Security'!E9="","",'Security'!E9) | G46: =IF('Security'!F9="","",'Security'!F9) | H46: =IF('Security'!G9="","",'Security'!G9) | I46: =IF('Security'!H9="","",'Security'!H9) | J46: =IF('Security'!I9="","",'Security'!I9) | ... N46: =IF('Security'!M9="","",'Security'!M9)
A47: =IF('Security'!A10="","",'Security'!A10) | B47: Security | C47: =IF('Security'!B10="","",'Security'!B10) | D47: =IF('Security'!C10="","",'Security'!C10) | E47: =IF('Security'!D10="","",'Security'!D10) | F47: =IF('Security'!E10="","",'Security'!E10) | G47: =IF('Security'!F10="","",'Security'!F10) | H47: =IF('Security'!G10="","",'Security'!G10) | I47: =IF('Security'!H10="","",'Security'!H10) | J47: =IF('Security'!I10="","",'Security'!I10) | ... N47: =IF('Security'!M10="","",'Security'!M10)
A48: =IF('Security'!A11="","",'Security'!A11) | B48: Security | C48: =IF('Security'!B11="","",'Security'!B11) | D48: =IF('Security'!C11="","",'Security'!C11) | E48: =IF('Security'!D11="","",'Security'!D11) | F48: =IF('Security'!E11="","",'Security'!E11) | G48: =IF('Security'!F11="","",'Security'!F11) | H48: =IF('Security'!G11="","",'Security'!G11) | I48: =IF('Security'!H11="","",'Security'!H11) | J48: =IF('Security'!I11="","",'Security'!I11) | ... N48: =IF('Security'!M11="","",'Security'!M11)
A49: =IF('Security'!A12="","",'Security'!A12) | B49: Security | C49: =IF('Security'!B12="","",'Security'!B12) | D49: =IF('Security'!C12="","",'Security'!C12) | E49: =IF('Security'!D12="","",'Security'!D12) | F49: =IF('Security'!E12="","",'Security'!E12) | G49: =IF('Security'!F12="","",'Security'!F12) | H49: =IF('Security'!G12="","",'Security'!G12) | I49: =IF('Security'!H12="","",'Security'!H12) | J49: =IF('Security'!I12="","",'Security'!I12) | ... N49: =IF('Security'!M12="","",'Security'!M12)
A50: =IF('Security'!A13="","",'Security'!A13) | B50: Security | C50: =IF('Security'!B13="","",'Security'!B13) | D50: =IF('Security'!C13="","",'Security'!C13) | E50: =IF('Security'!D13="","",'Security'!D13) | F50: =IF('Security'!E13="","",'Security'!E13) | G50: =IF('Security'!F13="","",'Security'!F13) | H50: =IF('Security'!G13="","",'Security'!G13) | I50: =IF('Security'!H13="","",'Security'!H13) | J50: =IF('Security'!I13="","",'Security'!I13) | ... N50: =IF('Security'!M13="","",'Security'!M13)
...

Sheet Project
A1: Project Parameters
A2: Parameter Name | B2: Production | C2: Test | D2: DR | E2: Description | F2: Required | G2: Data Type | H2: Validation Rules | I2: Security Level | J2: Owner Team | K2: Dependencies | L2: Notes | M2: Last Updated
A3: solution.name | B3: aws-landing-zone | C3: aws-landing-zone | D3: aws-landing-zone | E3: Solution identifier used for resource naming and tagging across all accounts | F3: Yes | G3: String | H3: lowercase alphanumeric and hyphens only; max 50 chars | I3: Public | J3: Cloud CoE | M3: 2025-01-31
A4: solution.region.primary | B4: us-east-1 | C4: us-east-1 | D4: us-east-2 | E4: Primary AWS region for all Control Tower management-plane and hub resources | F4: Yes | G4: String | H4: Valid AWS region code | I4: Public | J4: Cloud CoE | L4: SOW commits to us-east-1 primary; us-east-2 is DR | M4: 2025-01-31
A5: solution.region.secondary | B5: us-east-2 | C5: us-east-2 | D5: us-east-1 | E5: Secondary AWS region governed by Control Tower for DR and multi-region coverage | F5: Yes | G5: String | H5: Valid AWS region code | I5: Public | J5: Cloud CoE | K5: solution.region.primary | L5: DR region mirrors primary governance posture | M5: 2025-01-31
A6: solution.environment | B6: prod | C6: nonprod | D6: prod | E6: Deployment environment identifier applied to all tagged resources | F6: Yes | G6: String | H6: prod | nonprod | sandbox | I6: Public | J6: Cloud CoE | L6: DR mirrors production environment identifier | M6: 2025-01-31
A7: solution.version | B7: 1.0.0 | C7: 1.0.0 | D7: 1.0.0 | E7: Current solution version used in IaC state labels and runbook references | F7: Yes | G7: String | H7: Semantic versioning X.Y.Z | I7: Public | J7: Cloud CoE | M7: 2025-01-31
A8: aws.account_id.management | B8: [management-account-id] | C8: [management-account-id] | D8: [management-account-id] | E8: AWS Management account ID hosting Control Tower and AWS Organizations | F8: Yes | G8: String | H8: 12-digit numeric | I8: Confidential | J8: Cloud CoE | L8: Store in Secrets Manager; used by AFT and Terraform workspaces | M8: 2025-01-31
A9: aws.account_id.log_archive | B9: [log-archive-account-id] | C9: [log-archive-account-id] | D9: [log-archive-account-id] | E9: AWS account ID for the centralised Log Archive account | F9: Yes | G9: String | H9: 12-digit numeric | I9: Confidential | J9: Cloud CoE | K9: aws.account_id.management | L9: Required by CloudTrail and Config delivery configurations | M9: 2025-01-31
A10: aws.account_id.audit | B10: [audit-account-id] | C10: [audit-account-id] | D10: [audit-account-id] | E10: AWS account ID for the Audit/Security Tooling account (GuardDuty and Security Hub delegated admin) | F10: Yes | G10: String | H10: 12-digit numeric | I10: Confidential | J10: Cloud CoE | K10: aws.account_id.management | L10: Used as delegated administrator for GuardDuty and Security Hub | M10: 2025-01-31
A11: aws.account_id.network_hub | B11: [network-hub-account-id] | C11: [network-hub-account-id] | D11: [network-hub-account-id] | E11: AWS account ID for the Network Hub account hosting TGW and Network Firewall | F11: Yes | G11: String | H11: 12-digit numeric | I11: Confidential | J11: Cloud CoE | K11: aws.account_id.management | L11: Required for TGW sharing and spoke VPC attachment configurations | M11: 2025-01-31
A12: aws.account_id.shared_services | B12: [shared-services-account-id] | C12: [shared-services-account-id] | D12: [shared-services-account-id] | E12: AWS account ID for the Shared Services account hosting centralised CloudWatch dashboards | F12: Yes | G12: String | H12: 12-digit numeric | I12: Confidential | J12: Cloud CoE | K12: aws.account_id.management | L12: Required for cross-account CloudWatch metrics sharing | M12: 2025-01-31
A13: aws.organizations.id | B13: [org-id] | C13: [org-id] | D13: [org-id] | E13: AWS Organizations organisation ID used in SCPs and RCP data perimeter policies | F13: Yes | G13: String | H13: ^o-[a-z0-9]{10,32}$ | I13: Confidential | J13: Cloud CoE | K13: aws.account_id.management | L13: Used in RCP conditions to enforce org-boundary data perimeter | M13: 2025-01-31
A14: aws.organizations.root_id | B14: [org-root-id] | C14: [org-root-id] | D14: [org-root-id] | E14: Root ID of the AWS Organizations hierarchy for SCP and tag policy attachment | F14: Yes | G14: String | H14: ^r-[a-z0-9]{4}$ | I14: Confidential | J14: Cloud CoE | K14: aws.organizations.id | L14: Required for OU creation and policy attachment via Terraform | M14: 2025-01-31
A15: controltower.governed_regions | B15: us-east-1,us-east-2 | C15: us-east-1,us-east-2 | D15: us-east-1,us-east-2 | E15: Comma-separated list of AWS regions governed by Control Tower | F15: Yes | G15: List(String) | H15: Valid AWS region codes; minimum 2 regions per SOW | I15: Public | J15: Cloud CoE | K15: solution.region.primary; solution.region.secondary | L15: SOW mandates both us-east-1 and us-east-2 governed from day one | M15: 2025-01-31
A16: controltower.landing_zone_version | B16: 3.3 | C16: 3.3 | D16: 3.3 | E16: AWS Control Tower landing zone manifest version deployed | F16: Yes | G16: String | H16: Valid Control Tower version string | I16: Public | J16: Cloud CoE | L16: Pin version during active deployment; upgrade only during maintenance windows | M16: 2025-01-31
A17: ou.security.id | B17: [ou-security-id] | C17: [ou-security-id] | D17: [ou-security-id] | E17: OU ID for the Security OU hosting Log Archive and Audit accounts | F17: Yes | G17: String | H17: ^ou-[a-z0-9]{4}-[a-z0-9]{8,32}$ | I17: Confidential | J17: Cloud CoE | K17: aws.organizations.root_id | L17: Required for SCP attachment and Control Tower OU registration | M17: 2025-01-31
A18: ou.infrastructure.id | B18: [ou-infrastructure-id] | C18: [ou-infrastructure-id] | D18: [ou-infrastructure-id] | E18: OU ID for the Infrastructure OU hosting Network Hub and Shared Services accounts | F18: Yes | G18: String | H18: ^ou-[a-z0-9]{4}-[a-z0-9]{8,32}$ | I18: Confidential | J18: Cloud CoE | K18: aws.organizations.root_id | L18: Required for SCP attachment targeting infrastructure accounts | M18: 2025-01-31
A19: ou.workloads_prod.id | B19: [ou-workloads-prod-id] | C19: [ou-workloads-prod-id] | D19: [ou-workloads-prod-id] | E19: OU ID for the Workloads-Prod OU; maximum SCP enforcement applied here | F19: Yes | G19: String | H19: ^ou-[a-z0-9]{4}-[a-z0-9]{8,32}$ | I19: Confidential | J19: Cloud CoE | K19: aws.organizations.root_id | L19: All Production workload accounts must be in this OU at go-live | M19: 2025-01-31
A20: ou.workloads_nonprod.id | B20: [ou-workloads-nonprod-id] | C20: [ou-workloads-nonprod-id] | D20: [ou-workloads-nonprod-id] | E20: OU ID for the Workloads-NonProd OU with relaxed (but enforced) guardrails | F20: Yes | G20: String | H20: ^ou-[a-z0-9]{4}-[a-z0-9]{8,32}$ | I20: Confidential | J20: Cloud CoE | K20: aws.organizations.root_id | L20: Used by AFT to route Non-Production account vending requests | M20: 2025-01-31
A21: ou.sandbox.id | B21: [ou-sandbox-id] | C21: [ou-sandbox-id] | D21: [ou-sandbox-id] | E21: OU ID for the Sandbox OU; region restriction and root-deny SCPs remain active | F21: Yes | G21: String | H21: ^ou-[a-z0-9]{4}-[a-z0-9]{8,32}$ | I21: Confidential | J21: Cloud CoE | K21: aws.organizations.root_id | L21: Production guardrails relaxed for experimentation per SOW design | M21: 2025-01-31
A22: ou.suspended.id | B22: [ou-suspended-id] | C22: [ou-suspended-id] | D22: [ou-suspended-id] | E22: OU ID for the Suspended OU; deny-all SCP applied to isolated decommissioned accounts | F22: Yes | G22: String | H22: ^ou-[a-z0-9]{4}-[a-z0-9]{8,32}$ | I22: Confidential | J22: Cloud CoE | K22: aws.organizations.root_id | L22: Accounts moved here pending formal closure process | M22: 2025-01-31

Sheet Networking
A1: Networking Parameters
A2: Parameter Name | B2: Production | C2: Test | D2: DR | E2: Description | F2: Required | G2: Data Type | H2: Validation Rules | I2: Security Level | J2: Owner Team | K2: Dependencies | L2: Notes | M2: Last Updated
A3: networking.ipam.supernet_cidr | B3: 10.0.0.0/8 | C3: 10.0.0.0/8 | D3: 10.0.0.0/8 | E3: VPC IPAM top-level supernet CIDR managed in the Network Hub account | F3: Yes | G3: String | H3: Valid CIDR block; must not overlap with on-premises ranges | I3: Confidential | J3: Network Team | K3: aws.account_id.network_hub | L3: Confirmed non-overlapping with on-premises IP space during Phase 1 discovery | M3: 2025-01-31
A4: networking.ipam.pool_us_east_1_cidr | B4: 10.0.0.0/10 | C4: 10.0.0.0/10 | D4: 10.0.0.0/10 | E4: IPAM regional sub-pool CIDR for us-east-1; supports up to 256 /20 spoke VPCs | F4: Yes | G4: String | H4: Valid CIDR within networking.ipam.supernet_cidr | I4: Confidential | J4: Network Team | K4: networking.ipam.supernet_cidr | L4: Allocates /20 blocks automatically to each new spoke VPC in us-east-1 | M4: 2025-01-31
A5: networking.ipam.pool_us_east_2_cidr | B5: 10.64.0.0/10 | C5: 10.64.0.0/10 | D5: 10.64.0.0/10 | E5: IPAM regional sub-pool CIDR for us-east-2; supports up to 256 /20 spoke VPCs | F5: Yes | G5: String | H5: Valid CIDR within networking.ipam.supernet_cidr | I5: Confidential | J5: Network Team | K5: networking.ipam.supernet_cidr | L5: Non-overlapping with us-east-1 pool; mirrors spoke count capacity | M5: 2025-01-31
A6: networking.hub_vpc.us_east_1_cidr | B6: 10.128.0.0/20 | C6: 10.128.0.0/20 | D6: 10.192.0.0/20 | E6: Network Hub VPC CIDR block in us-east-1; must not be allocated from the spoke IPAM pool | F6: Yes | G6: String | H6: Valid /20 CIDR; must not overlap with IPAM regional pool | I6: Confidential | J6: Network Team | K6: networking.ipam.supernet_cidr | L6: Hub VPC uses static allocation outside the spoke IPAM pool by design | M6: 2025-01-31
A7: networking.hub_vpc.us_east_2_cidr | B7: 10.192.0.0/20 | C7: 10.192.0.0/20 | D7: 10.128.0.0/20 | E7: Network Hub VPC CIDR block in us-east-2; mirrors hub layout with a different offset | F7: Yes | G7: String | H7: Valid /20 CIDR; must not overlap with IPAM regional pool | I7: Confidential | J7: Network Team | K7: networking.ipam.supernet_cidr | L7: Non-overlapping with us-east-1 hub VPC; same subnet tier layout | M7: 2025-01-31
A8: networking.spoke_vpc.cidr_prefix_length | B8: 20 | C8: 20 | D8: 20 | E8: CIDR prefix length auto-allocated from IPAM for each new spoke VPC | F8: Yes | G8: Integer | H8: 16-28 | I8: Public | J8: Network Team | K8: networking.ipam.pool_us_east_1_cidr; networking.ipam.pool_us_east_2_cidr | L8: SOW specifies /20 per spoke (4096 hosts); change requires IPAM reconfiguration | M8: 2025-01-31
A9: networking.tgw.id.us_east_1 | B9: [tgw-id-use1] | C9: [tgw-id-use1] | D9: [tgw-id-use1] | E9: Transit Gateway ID in us-east-1; shared to all spoke accounts via RAM | F9: Yes | G9: String | H9: ^tgw-[a-f0-9]{17}$ | I9: Confidential | J9: Network Team | K9: aws.account_id.network_hub | L9: All spoke VPC attachments target this TGW; shared via AWS Resource Access Manager | M9: 2025-01-31
A10: networking.tgw.id.us_east_2 | B10: [tgw-id-use2] | C10: [tgw-id-use2] | D10: [tgw-id-use2] | E10: Transit Gateway ID in us-east-2; inter-region peering links it to us-east-1 TGW | F10: Yes | G10: String | H10: ^tgw-[a-f0-9]{17}$ | I10: Confidential | J10: Network Team | K10: aws.account_id.network_hub; networking.tgw.id.us_east_1 | L10: Static inter-region TGW peering attachment configured between both TGWs | M10: 2025-01-31
A11: networking.nat_gateway.count_per_region | B11: 2 | C11: 1 | D11: 2 | E11: Number of NAT Gateway instances per region; one per AZ in production for HA | F11: Yes | G11: Integer | H11: 1-3 | I11: Public | J11: Network Team | K11: networking.hub_vpc.us_east_1_cidr | L11: SOW specifies one NAT Gateway per AZ in production; test uses single NAT to reduce cost | M11: 2025-01-31
A12: networking.vpn.customer_gateway_ip | B12: [on-prem-gateway-ip] | C12: [on-prem-gateway-ip] | D12: [on-prem-gateway-ip] | E12: On-premises VPN gateway public IP for the AWS Site-to-Site VPN Customer Gateway | F12: Yes | G12: String | H12: Valid public IPv4 address | I12: Confidential | J12: Network Team | L12: Confirmed at kick-off per Dependency D5; required before Phase 2 networking deployment | M12: 2025-01-31
A13: networking.vpn.customer_gateway_asn | B13: [on-prem-bgp-asn] | C13: [on-prem-bgp-asn] | D13: [on-prem-bgp-asn] | E13: BGP ASN of the on-premises Customer Gateway; used for dynamic route propagation | F13: Yes | G13: Integer | H13: 1-4294967295 | I13: Confidential | J13: Network Team | K13: networking.vpn.customer_gateway_ip | L13: Static routing configured as fallback if BGP is not supported on-premises | M13: 2025-01-31
A14: networking.firewall.policy_arn.us_east_1 | B14: [nfw-policy-arn-use1] | C14: [nfw-policy-arn-use1] | D14: [nfw-policy-arn-use2] | E14: ARN of the AWS Network Firewall stateful policy in us-east-1 | F14: Yes | G14: String | H14: Valid Network Firewall policy ARN | I14: Confidential | J14: Network Team | K14: aws.account_id.network_hub | L14: Default-deny stance; all permit rules managed as Terraform in IaC repository | M14: 2025-01-31
A15: networking.firewall.policy_arn.us_east_2 | B15: [nfw-policy-arn-use2] | C15: [nfw-policy-arn-use2] | D15: [nfw-policy-arn-use1] | E15: ARN of the AWS Network Firewall stateful policy in us-east-2 | F15: Yes | G15: String | H15: Valid Network Firewall policy ARN | I15: Confidential | J15: Network Team | K15: aws.account_id.network_hub; networking.firewall.policy_arn.us_east_1 | L15: Policy mirrors us-east-1 for symmetric east-west and north-south enforcement | M15: 2025-01-31
A16: networking.vpc_flow_logs.enabled | B16: true | C16: true | D16: true | E16: Enable VPC Flow Logs on all spoke and hub VPCs delivered to Log Archive S3 | F16: Yes | G16: Boolean | H16: true|false | I16: Public | J16: Network Team | K16: aws.account_id.log_archive | L16: Flow Logs delivered to Log Archive S3 under /vpc-flow-logs/ prefix | M16: 2025-01-31
A17: networking.vpc_flow_logs.retention_days | B17: 90 | C17: 30 | D17: 90 | E17: Retention period in days for VPC Flow Logs in the Log Archive S3 bucket before Glacier transition | F17: Yes | G17: Integer | H17: 1-3653 | I17: Public | J17: Network Team | K17: networking.vpc_flow_logs.enabled | L17: Lifecycle policy transitions logs to Glacier Instant Retrieval after this period | M17: 2025-01-31

Sheet Security
A1: Security Parameters
A2: Parameter Name | B2: Production | C2: Test | D2: DR | E2: Description | F2: Required | G2: Data Type | H2: Validation Rules | I2: Security Level | J2: Owner Team | K2: Dependencies | L2: Notes | M2: Last Updated
A3: iam_identity_center.instance_arn | B3: [sso-instance-arn] | C3: [sso-instance-arn] | D3: [sso-instance-arn] | E3: ARN of the IAM Identity Center instance used for all cross-account SSO | F3: Yes | G3: String | H3: ^arn:aws:sso:::instance/ssoins-[a-zA-Z0-9]{16}$ | I3: Confidential | J3: Security Team | K3: aws.account_id.management | L3: Required by all permission set and assignment Terraform resources | M3: 2025-01-31
A4: iam_identity_center.identity_store_id | B4: [identity-store-id] | C4: [identity-store-id] | D4: [identity-store-id] | E4: Identity Store ID associated with the IAM Identity Center instance | F4: Yes | G4: String | H4: ^d-[a-zA-Z0-9]{10}$ | I4: Confidential | J4: Security Team | K4: iam_identity_center.instance_arn | L4: Used for group and user lookup in Terraform IAM Identity Center resources | M4: 2025-01-31
A5: iam_identity_center.identity_source | B5: NATIVE | C5: NATIVE | D5: NATIVE | E5: Identity source type for IAM Identity Center; NATIVE or EXTERNAL_IDP | F5: Yes | G5: String | H5: NATIVE | EXTERNAL_IDP | I5: Public | J5: Security Team | K5: iam_identity_center.instance_arn | L5: Confirmed at kick-off per Dependency D4; NATIVE until IdP is confirmed | M5: 2025-01-31
A6: iam_identity_center.session_duration_hours | B6: 8 | C6: 8 | D6: 8 | E6: Maximum session duration in hours for all IAM Identity Center permission sets | F6: Yes | G6: Integer | H6: 1-12 | I6: Public | J6: Security Team | K6: iam_identity_center.instance_arn | L6: SOW specifies 8-hour cap; applies to all permission sets uniformly | M6: 2025-01-31
A7: security.mfa_enabled | B7: true | C7: true | D7: true | E7: Enforce MFA for all IAM Identity Center users via SCP deny on aws:MultiFactorAuthPresent=false | F7: Yes | G7: Boolean | H7: true|false | I7: Public | J7: Security Team | K7: iam_identity_center.instance_arn | L7: SOW mandates MFA via SCP; must not be disabled in any environment | M7: 2025-01-31
A8: security.scp.deny_root_enabled | B8: true | C8: true | D8: true | E8: Enable SCP that denies all root account API actions across all member accounts | F8: Yes | G8: Boolean | H8: true|false | I8: Public | J8: Security Team | K8: aws.organizations.root_id | L8: Core preventative control per SOW; apply at Root OU level | M8: 2025-01-31
A9: security.scp.restrict_regions_enabled | B9: true | C9: true | D9: true | E9: Enable SCP restricting all API calls to us-east-1 and us-east-2 only | F9: Yes | G9: Boolean | H9: true|false | I9: Public | J9: Security Team | K9: aws.organizations.root_id; controltower.governed_regions | L9: Enforces US data residency requirement at the control-plane level | M9: 2025-01-31
A10: security.scp.cloudtrail_lock_enabled | B10: true | C10: true | D10: true | E10: Enable SCP preventing disabling or modification of the CloudTrail organisation trail | F10: Yes | G10: Boolean | H10: true|false | I10: Public | J10: Security Team | K10: aws.organizations.root_id | L10: Prevents tampering with the immutable audit trail; required for SOC 2 / HIPAA | M10: 2025-01-31
A11: security.scp.config_lock_enabled | B11: true | C11: true | D11: true | E11: Enable SCP preventing disabling of AWS Config recording across member accounts | F11: Yes | G11: Boolean | H11: true|false | I11: Public | J11: Security Team | K11: aws.organizations.root_id | L11: Ensures continuous compliance monitoring cannot be circumvented | M11: 2025-01-31
A12: security.rcp.data_perimeter_enabled | B12: true | C12: false | D12: true | E12: Enable Resource Control Policy enforcing org-boundary data perimeter on all member accounts | F12: Yes | G12: Boolean | H12: true|false | I12: Public | J12: Security Team | K12: aws.organizations.id | L12: Prevents data exfiltration to principals outside the Organisation; not applied to NonProd to reduce friction | M12: 2025-01-31
A13: security.kms.key_rotation_enabled | B13: true | C13: true | D13: true | E13: Enable automatic annual rotation for all customer-managed KMS keys in both regions | F13: Yes | G13: Boolean | H13: true|false | I13: Public | J13: Security Team | L13: Satisfies FSBP kms-key-rotation-enabled control; applied via Config conformance pack | M13: 2025-01-31
A14: security.kms.key_arn.us_east_1 | B14: [kms-key-arn-use1] | C14: [kms-key-arn-use1] | D14: [kms-key-arn-use2] | E14: ARN of the customer-managed KMS key in us-east-1 for S3/CloudTrail/EBS encryption | F14: Yes | G14: String | H14: ^arn:aws:kms:us-east-[12]:[0-9]{12}:key/[a-f0-9-]{36}$ | I14: Secret | J14: Security Team | K14: solution.region.primary | L14: Store in Secrets Manager; used by Log Archive S3 bucket and CloudTrail config | M14: 2025-01-31
A15: security.kms.key_arn.us_east_2 | B15: [kms-key-arn-use2] | C15: [kms-key-arn-use2] | D15: [kms-key-arn-use1] | E15: ARN of the customer-managed KMS key in us-east-2 for DR region encryption | F15: Yes | G15: String | H15: ^arn:aws:kms:us-east-[12]:[0-9]{12}:key/[a-f0-9-]{36}$ | I15: Secret | J15: Security Team | K15: solution.region.secondary | L15: Store in Secrets Manager; replicate key policy from primary region | M15: 2025-01-31
A16: security.breakglass.secret_arn | B16: [breakglass-secret-arn] | C16: [breakglass-secret-arn] | D16: [breakglass-secret-arn] | E16: Secrets Manager ARN for the sealed management-account root break-glass credentials | F16: Yes | G16: String | H16: Valid Secrets Manager ARN format | I16: Secret | J16: Security Team | K16: aws.account_id.management | L16: Access restricted to PlatformAdministrator + MFA; rotate immediately after any use | M16: 2025-01-31
A17: security.breakglass.rotation_days | B17: 90 | C17: 90 | D17: 90 | E17: Maximum number of days before break-glass credentials must be rotated | F17: Yes | G17: Integer | H17: 1-365 | I17: Public | J17: Security Team | K17: security.breakglass.secret_arn | L17: SNS alert is triggered on each rotation event via CloudTrail rule | M17: 2025-01-31
A18: security.tls_minimum_version | B18: TLS1_2 | C18: TLS1_2 | D18: TLS1_2 | E18: Minimum TLS version enforced by S3 bucket policies and Network Firewall egress rules | F18: Yes | G18: String | H18: TLS1_2 | TLS1_3 | I18: Public | J18: Security Team | L18: Enforced via s3:SecureTransport S3 bucket condition and NFW stateful rules | M18: 2025-01-31
A19: security.s3_block_public_access | B19: true | C19: true | D19: true | E19: Enforce S3 Block Public Access setting at the AWS account level across all member accounts | F19: Yes | G19: Boolean | H19: true|false | I19: Public | J19: Security Team | K19: aws.organizations.root_id | L19: Enforced via SCP and Config rule s3-account-level-public-access-blocks | M19: 2025-01-31
A20: security.ebs_encryption_by_default | B20: true | C20: true | D20: true | E20: Enable EBS encryption by default in all member accounts via Config rule | F20: Yes | G20: Boolean | H20: true|false | I20: Public | J20: Security Team | L20: Config rule ec2-ebs-encryption-by-default applied via conformance pack | M20: 2025-01-31

Sheet Storage
A1: Storage Parameters
A2: Parameter Name | B2: Production | C2: Test | D2: DR | E2: Description | F2: Required | G2: Data Type | H2: Validation Rules | I2: Security Level | J2: Owner Team | K2: Dependencies | L2: Notes | M2: Last Updated
A3: storage.log_archive.bucket_name_primary | B3: [log-archive-s3-bucket-use1] | C3: [log-archive-s3-bucket-use1] | D3: [log-archive-s3-bucket-use2] | E3: Primary Log Archive S3 bucket name in the Log Archive account (us-east-1) | F3: Yes | G3: String | H3: Globally unique; follows ins-log-archive-use1-{account-id} naming convention | I3: Confidential | J3: Cloud CoE | K3: aws.account_id.log_archive | L3: Object Lock compliance mode; SSE-S3 default; restricted to SecurityAuditor and PlatformAdministrator | M3: 2025-01-31
A4: storage.log_archive.bucket_name_replica | B4: [log-archive-s3-bucket-use2] | C4: [log-archive-s3-bucket-use2] | D4: [log-archive-s3-bucket-use1] | E4: CRR destination S3 bucket name in us-east-2 for log archive cross-region replication | F4: Yes | G4: String | H4: Globally unique; follows ins-log-archive-use2-{account-id} naming convention | I4: Confidential | J4: Cloud CoE | K4: storage.log_archive.bucket_name_primary | L4: S3 CRR replicates within < 15 minutes to meet Log Archive RPO; enables DR restore | M4: 2025-01-31
A5: storage.log_archive.glacier_transition_days | B5: 90 | C5: 30 | D5: 90 | E5: Days after which Log Archive objects transition from S3 Standard to Glacier Instant Retrieval | F5: Yes | G5: Integer | H5: 30-3650 | I5: Public | J5: Cloud CoE | K5: storage.log_archive.bucket_name_primary | L5: Reduces storage cost while maintaining rapid retrieval for audit evidence requests | M5: 2025-01-31
A6: storage.terraform_state.bucket_name | B6: [tf-state-bucket] | C6: [tf-state-bucket] | D6: [tf-state-bucket] | E6: S3 bucket name for Terraform remote state storage; versioning and MFA delete enabled | F6: Yes | G6: String | H6: Globally unique S3 bucket name | I6: Confidential | J6: Cloud CoE | K6: aws.account_id.management | L6: State versioning with 90-day version retention; PITR enabled on DynamoDB lock table | M6: 2025-01-31
A7: storage.terraform_state.dynamodb_lock_table | B7: [tf-lock-table] | C7: [tf-lock-table] | D7: [tf-lock-table] | E7: DynamoDB table name for Terraform state locking to prevent concurrent apply conflicts | F7: Yes | G7: String | H7: Valid DynamoDB table name; max 255 chars | I7: Confidential | J7: Cloud CoE | K7: storage.terraform_state.bucket_name | L7: Point-in-Time Recovery enabled; LockID is the primary key attribute | M7: 2025-01-31

Sheet Application
A1: Application Parameters
A2: Parameter Name | B2: Production | C2: Test | D2: DR | E2: Description | F2: Required | G2: Data Type | H2: Validation Rules | I2: Security Level | J2: Owner Team | K2: Dependencies | L2: Notes | M2: Last Updated
A3: aft.pipeline.account_request_repo | B3: [aft-account-request-repo-url] | C3: [aft-account-request-repo-url] | D3: [aft-account-request-repo-url] | E3: VCS repository URL for AFT account request Terraform configuration files | F3: Yes | G3: String | H3: Valid HTTPS VCS URL | I3: Confidential | J3: Cloud CoE | L3: VCS provider confirmed per Dependency D6; CodeCommit used if no preference stated | M3: 2025-01-31
A4: aft.pipeline.terraform_version | B4: 1.9.0 | C4: 1.9.0 | D4: 1.9.0 | E4: Terraform version pinned for all AFT pipeline executions | F4: Yes | G4: String | H4: Semantic versioning X.Y.Z; must be >= 1.5.0 for AFT | I4: Public | J4: Cloud CoE | K4: aft.pipeline.account_request_repo | L4: Pin version in AFT settings to prevent unintended upgrades during the engagement | M4: 2025-01-31
A5: aft.pipeline.codebuild_compute_type | B5: BUILD_GENERAL1_SMALL | C5: BUILD_GENERAL1_SMALL | D5: BUILD_GENERAL1_SMALL | E5: AWS CodeBuild compute type for AFT account vending and customisation stages | F5: Yes | G5: String | H5: BUILD_GENERAL1_SMALL | BUILD_GENERAL1_MEDIUM | BUILD_GENERAL1_LARGE | I5: Public | J5: Cloud CoE | L5: SMALL (2 vCPU / 3 GB RAM) is sufficient for Terraform apply workloads at this scale | M5: 2025-01-31
A6: aft.pipeline.vending_sla_minutes | B6: 30 | C6: 30 | D6: 30 | E6: Maximum time in minutes for a complete AFT account vending run including all customisations | F6: Yes | G6: Integer | H6: 1-120 | I6: Public | J6: Cloud CoE | L6: SOW hard success metric: < 30 min validated across 3 consecutive test runs at go-live | M6: 2025-01-31
A7: aft.pipeline.max_concurrent_vending | B7: 5 | C7: 2 | D7: 5 | E7: Maximum number of concurrent AFT account vending pipelines permitted | F7: Yes | G7: Integer | H7: 1-20 | I7: Public | J7: Cloud CoE | K7: aft.pipeline.account_request_repo | L7: Limit prevents AWS API throttling during bulk account provisioning events | M7: 2025-01-31
A8: aft.customisation.mandatory_tags.environment_key | B8: Environment | C8: Environment | D8: Environment | E8: Mandatory tag key for environment classification applied to all resources via AFT | F8: Yes | G8: String | H8: Non-empty string; valid AWS tag key | I8: Public | J8: Cloud CoE | L8: Valid values: development, non-production, production, platform, sandbox | M8: 2025-01-31
A9: aft.customisation.mandatory_tags.owner_key | B9: Owner | C9: Owner | D9: Owner | E9: Mandatory tag key for team ownership applied to all resources via AFT | F9: Yes | G9: String | H9: Non-empty string; valid AWS tag key | I9: Public | J9: Cloud CoE | L9: Value must be a valid team name or email from IAM Identity Center group directory | M9: 2025-01-31
A10: aft.customisation.mandatory_tags.cost_center_key | B10: CostCenter | C10: CostCenter | D10: CostCenter | E10: Mandatory tag key for cost allocation applied to all resources via AFT | F10: Yes | G10: String | H10: Non-empty string; valid AWS tag key | I10: Public | J10: Cloud CoE | L10: Finance cost centre code provided by client FinOps contact at kick-off | M10: 2025-01-31
A11: aft.customisation.mandatory_tags.project_key | B11: Project | C11: Project | D11: Project | E11: Mandatory tag key for project identification applied to all resources via AFT | F11: Yes | G11: String | H11: Non-empty string; valid AWS tag key | I11: Public | J11: Cloud CoE | M11: 2025-01-31
A12: aft.customisation.mandatory_tags.data_classification_key | B12: DataClassification | C12: DataClassification | D12: DataClassification | E12: Mandatory tag key for data sensitivity classification applied to all resources via AFT | F12: Yes | G12: String | H12: Non-empty string; valid AWS tag key | I12: Public | J12: Cloud CoE | L12: Valid values: public, internal, confidential, restricted | M12: 2025-01-31
A13: aft.customisation.budgets.alert_threshold_80 | B13: 80 | C13: 80 | D13: 80 | E13: AWS Budgets percentage threshold for the first spend alert sent to all account owners | F13: Yes | G13: Integer | H13: 1-100 | I13: Public | J13: Cloud CoE | L13: Applied to every vended account via AFT customisation; SOW go-live criterion | M13: 2025-01-31
A14: aft.customisation.budgets.alert_threshold_100 | B14: 100 | C14: 100 | D14: 100 | E14: AWS Budgets percentage threshold for the second (full) spend alert sent to all account owners | F14: Yes | G14: Integer | H14: 1-100 | I14: Public | J14: Cloud CoE | K14: aft.customisation.budgets.alert_threshold_80 | L14: Both 80% and 100% alerts mandatory per SOW; SNS topic routes to FinOps contact | M14: 2025-01-31
A15: cicd.pipeline.branch_protection_enabled | B15: true | C15: true | D15: true | E15: Enable branch protection rules on the IaC VCS repository requiring peer review before merge | F15: Yes | G15: Boolean | H15: true|false | I15: Public | J15: Cloud CoE | K15: aft.pipeline.account_request_repo | L15: SOW requires peer review + automated plan gate on all infrastructure changes | M15: 2025-01-31
A16: cicd.pipeline.terraform_plan_gate_enabled | B16: true | C16: true | D16: true | E16: Require a successful terraform plan validation as a CI/CD gate before any merge to main | F16: Yes | G16: Boolean | H16: true|false | I16: Public | J16: Cloud CoE | K16: cicd.pipeline.branch_protection_enabled | L16: Prevents broken or non-compliant Terraform from being applied to any environment | M16: 2025-01-31
A17: cicd.pipeline.scp_dual_approval_required | B17: true | C17: false | D17: true | E17: Require dual approval (Vendor Architect + Client Security Lead) for SCP changes | F17: Yes | G17: Boolean | H17: true|false | I17: Public | J17: Security Team | K17: cicd.pipeline.branch_protection_enabled | L17: SOW mandates dual-approval gate for all SCP policy changes in production | M17: 2025-01-31
A18: terraform_cloud.workspace_prefix | B18: ins | C18: ins | D18: ins | E18: Prefix for all Terraform Cloud workspace names following ins-{purpose}-{region-short} convention | F18: Yes | G18: String | H18: Lowercase alphanumeric; max 10 chars | I18: Public | J18: Cloud CoE | L18: Example workspace: ins-network-hub-use1; set before Phase 2 development begins | M18: 2025-01-31
A19: terraform_cloud.organisation_name | B19: [tf-cloud-org] | C19: [tf-cloud-org] | D19: [tf-cloud-org] | E19: HashiCorp Terraform Cloud organisation name for the client's Team tier account | F19: Yes | G19: String | H19: Valid Terraform Cloud org name | I19: Confidential | J19: Cloud CoE | L19: Client owns and registers the Terraform Cloud account per Assumption 12 in SOW | M19: 2025-01-31
A20: terraform_cloud.team_token | B20: [tf-cloud-team-token] | C20: [tf-cloud-team-token] | D20: [tf-cloud-team-token] | E20: Terraform Cloud Team API token injected into AFT CodePipeline at runtime | F20: Yes | G20: String | H20: Valid Terraform Cloud token format | I20: Secret | J20: Cloud CoE | K20: terraform_cloud.organisation_name | L20: Store in AWS Secrets Manager; injected at pipeline runtime; rotate every 90 days | M20: 2025-01-31

Sheet Monitoring
A1: Monitoring Parameters
A2: Parameter Name | B2: Production | C2: Test | D2: DR | E2: Description | F2: Required | G2: Data Type | H2: Validation Rules | I2: Security Level | J2: Owner Team | K2: Dependencies | L2: Notes | M2: Last Updated
A3: logging.cloudtrail.trail_name | B3: ins-org-trail-use1 | C3: ins-org-trail-use1 | D3: ins-org-trail-use2 | E3: Name of the CloudTrail organisation trail; naming follows ins-org-trail-{region-short} convention | F3: Yes | G3: String | H3: Alphanumeric and hyphens; max 128 chars | I3: Public | J3: Cloud CoE | L3: Single org trail captures all management events across both regions | M3: 2025-01-31
A4: logging.cloudtrail.log_bucket_name | B4: [log-archive-cloudtrail-bucket] | C4: [log-archive-cloudtrail-bucket] | D4: [log-archive-cloudtrail-bucket] | E4: S3 bucket name in the Log Archive account for CloudTrail log delivery | F4: Yes | G4: String | H4: Globally unique S3 bucket name; follows ins-log-archive-use1-{account-id} pattern | I4: Confidential | J4: Cloud CoE | K4: aws.account_id.log_archive | L4: Object Lock (compliance mode) and SSE-S3 enabled on this bucket | M4: 2025-01-31
A5: logging.cloudtrail.s3_retention_days_standard | B5: 90 | C5: 30 | D5: 90 | E5: Days to retain CloudTrail logs in S3 Standard storage before lifecycle transition to Glacier | F5: Yes | G5: Integer | H5: 1-3653 | I5: Public | J5: Cloud CoE | K5: logging.cloudtrail.log_bucket_name | L5: After this period logs move to S3 Glacier Instant Retrieval for cost-effective retention | M5: 2025-01-31
A6: logging.cloudtrail.lake_retention_years | B6: 7 | C6: 1 | D6: 7 | E6: Retention period in years for CloudTrail Lake event data store (queryable audit trail) | F6: Yes | G6: Integer | H6: 1-10 | I6: Public | J6: Cloud CoE | K6: aws.account_id.audit | L6: SOW specifies 7-year retention to satisfy SOC 2 / HIPAA / NIST 800-53 requirements | M6: 2025-01-31
A7: logging.cloudtrail.object_lock_retention_days | B7: 90 | C7: 30 | D7: 90 | E7: S3 Object Lock compliance-mode minimum retention period in days; prevents log deletion | F7: Yes | G7: Integer | H7: 1-3653 | I7: Public | J7: Security Team | K7: logging.cloudtrail.log_bucket_name | L7: Compliance mode means no user or role can delete locked objects within this period | M7: 2025-01-31
A8: logging.config.delivery_bucket_name | B8: [log-archive-config-bucket] | C8: [log-archive-config-bucket] | D8: [log-archive-config-bucket] | E8: S3 bucket name in Log Archive account for AWS Config snapshot and history delivery | F8: Yes | G8: String | H8: Globally unique S3 bucket name | I8: Confidential | J8: Cloud CoE | K8: aws.account_id.log_archive | L8: Separate prefix from CloudTrail logs within the same Log Archive account | M8: 2025-01-31
A9: logging.config.recording_enabled | B9: true | C9: true | D9: true | E9: Enable AWS Config recording in all accounts and both regions | F9: Yes | G9: Boolean | H9: true|false | I9: Public | J9: Cloud CoE | L9: Config recording active from Phase 1; SOW go-live criterion | M9: 2025-01-31
A10: logging.config.conformance_pack.fsbp | B10: true | C10: true | D10: true | E10: Enable the AWS Foundational Security Best Practices conformance pack in all accounts | F10: Yes | G10: Boolean | H10: true|false | I10: Public | J10: Security Team | K10: logging.config.recording_enabled | L10: Mandatory at go-live per SOW; provides 200+ FSBP control evaluations | M10: 2025-01-31
A11: logging.config.conformance_pack.nist | B11: true | C11: false | D11: true | E11: Enable the NIST 800-53 Rev 5 conformance pack if confirmed by Client Security Lead | F11: Yes | G11: Boolean | H11: true|false | I11: Public | J11: Security Team | K11: logging.config.recording_enabled | L11: Activation contingent on compliance framework confirmation (Dependency D3 / Week 2) | M11: 2025-01-31
A12: monitoring.securityhub.enabled | B12: true | C12: true | D12: true | E12: Enable AWS Security Hub in all accounts and both regions with FSBP standard | F12: Yes | G12: Boolean | H12: true|false | I12: Public | J12: Security Team | K12: aws.account_id.audit | L12: Aggregated to Audit account; SOW go-live success metric | M12: 2025-01-31
A13: monitoring.securityhub.fsbp_score_target | B13: 80 | C13: 80 | D13: 80 | E13: Minimum Security Hub FSBP compliance score percentage required at go-live | F13: Yes | G13: Integer | H13: 0-100 | I13: Public | J13: Security Team | K13: monitoring.securityhub.enabled | L13: Zero critical findings AND score >= 80% required for go-live sign-off per SOW | M13: 2025-01-31
A14: monitoring.securityhub.delegated_admin_account_id | B14: [audit-account-id] | C14: [audit-account-id] | D14: [audit-account-id] | E14: AWS account ID of the Security Hub delegated administrator (Audit account) | F14: Yes | G14: String | H14: 12-digit numeric; must match aws.account_id.audit | I14: Confidential | J14: Security Team | K14: aws.account_id.audit; monitoring.securityhub.enabled | L14: Aggregates all member account findings to the Audit account dashboard | M14: 2025-01-31
A15: monitoring.guardduty.enabled | B15: true | C15: true | D15: true | E15: Enable Amazon GuardDuty organisation-wide in both regions with delegated administrator | F15: Yes | G15: Boolean | H15: true|false | I15: Public | J15: Security Team | K15: aws.account_id.audit | L15: Analyses VPC Flow Logs; CloudTrail events; DNS logs for threat indicators | M15: 2025-01-31
A16: monitoring.guardduty.delegated_admin_account_id | B16: [audit-account-id] | C16: [audit-account-id] | D16: [audit-account-id] | E16: AWS account ID of the GuardDuty delegated administrator (Audit account) | F16: Yes | G16: String | H16: 12-digit numeric; must match aws.account_id.audit | I16: Confidential | J16: Security Team | K16: aws.account_id.audit; monitoring.guardduty.enabled | L16: Single pane for GuardDuty findings across all member accounts | M16: 2025-01-31
A17: monitoring.guardduty.alert_severity_threshold | B17: 7.0 | C17: 7.0 | D17: 7.0 | E17: GuardDuty finding severity threshold above which an SNS HIGH alert is triggered | F17: Yes | G17: Number | H17: 0.1-10.0 | I17: Public | J17: Security Team | K17: monitoring.guardduty.enabled; monitoring.sns.topic_arn_high | L17: EventBridge rule routes findings at or above this threshold to SNS HIGH topic | M17: 2025-01-31
A18: monitoring.cloudwatch.dashboard_name_ops | B18: ins-landing-zone-ops | C18: ins-landing-zone-ops | D18: ins-landing-zone-ops | E18: CloudWatch dashboard name for the Landing Zone Operations dashboard in Shared Services account | F18: Yes | G18: String | H18: Non-empty string; max 255 chars | I18: Public | J18: Operations | K18: aws.account_id.shared_services | L18: Shows CT compliance status; AFT pipeline health; account count; VPN status | M18: 2025-01-31
A19: monitoring.cloudwatch.dashboard_name_security | B19: ins-security-posture | C19: ins-security-posture | D19: ins-security-posture | E19: CloudWatch dashboard name for the Security Posture dashboard in Shared Services account | F19: Yes | G19: String | H19: Non-empty string; max 255 chars | I19: Public | J19: Security Team | K19: aws.account_id.shared_services | L19: Shows Security Hub FSBP score; GuardDuty finding volume; Config compliance score | M19: 2025-01-31
A20: monitoring.cloudwatch.dashboard_name_finops | B20: ins-finops | C20: ins-finops | D20: ins-finops | E20: CloudWatch dashboard name for the FinOps dashboard in Shared Services account | F20: Yes | G20: String | H20: Non-empty string; max 255 chars | I20: Public | J20: Operations | K20: aws.account_id.shared_services | L20: Shows org-wide cost trend; top 5 accounts by spend; Budget alert status | M20: 2025-01-31
A21: monitoring.cloudwatch.log_retention_days | B21: 90 | C21: 30 | D21: 90 | E21: Retention period in days for CloudWatch Log Groups created across the landing zone | F21: Yes | G21: Integer | H21: 1-3653 | I21: Public | J21: Operations | L21: Applies to all platform log groups; workload log groups inherit this default | M21: 2025-01-31
A22: monitoring.sns.topic_arn_critical | B22: [sns-topic-arn-critical] | C22: [sns-topic-arn-critical] | D22: [sns-topic-arn-critical] | E22: SNS topic ARN for CRITICAL (P1) alerts — CT drift and FSBP critical findings | F22: Yes | G22: String | H22: Valid SNS topic ARN | I22: Confidential | J22: Operations | K22: aws.account_id.shared_services | L22: 24x7 on-call routing; P1 response SLA 2 hours per SOW hypercare terms | M22: 2025-01-31
A23: monitoring.sns.topic_arn_high | B23: [sns-topic-arn-high] | C23: [sns-topic-arn-high] | D23: [sns-topic-arn-high] | E23: SNS topic ARN for HIGH (P2) alerts — AFT pipeline failures and GuardDuty threats | F23: Yes | G23: String | H23: Valid SNS topic ARN | I23: Confidential | J23: Operations | K23: aws.account_id.shared_services | L23: Business-hours routing; P2 response SLA 4 hours per SOW hypercare terms | M23: 2025-01-31
A24: monitoring.sns.topic_arn_medium | B24: [sns-topic-arn-medium] | C24: [sns-topic-arn-medium] | D24: [sns-topic-arn-medium] | E24: SNS topic ARN for MEDIUM (P3) alerts — Config drift and budget threshold notifications | F24: Yes | G24: String | H24: Valid SNS topic ARN | I24: Confidential | J24: Operations | K24: aws.account_id.shared_services | L24: 1 business-day response SLA; routed to operations email distribution list | M24: 2025-01-31
A25: monitoring.sns.alert_email_endpoint | B25: [ops-alert-email] | C25: [ops-alert-email] | D25: [ops-alert-email] | E25: Email address for SNS alert delivery; confirmed with client operations team at kick-off | F25: Yes | G25: String | H25: Valid email address | I25: Confidential | J25: Operations | K25: monitoring.sns.topic_arn_critical | L25: Subscription must be confirmed by the client before go-live readiness sign-off | M25: 2025-01-31

Sheet DR
A1: DR Parameters
