Workbook

Sheet Cover
B3: Configuration Parameters
B5: Generated: | C5: June 05, 2026
B6: Solution: | C6: Tmpnaegu_A5
B7: Customer: | C7: [Customer Name]
B8: Version: | C8: 1.0
B9: Status: | C9: Draft
C12: eoframework.org

Sheet All Parameters (Read Only)
A1: Total Parameters | B1: Categories | C1: Required | D1: Confidential/Secret
A2: 119 | B2: 11 | C2: 119 | D2: 28
A4: Parameter Name | B4: Category | C4: Production | D4: Test | E4: DR | F4: Description | G4: Required | H4: Data Type | I4: Validation Rules | J4: Security Level | K4: Owner Team | L4: Dependencies | M4: Notes | N4: Last Updated
A5: =IF('Project'!A3="","",'Project'!A3) | B5: Project | C5: =IF('Project'!B3="","",'Project'!B3) | D5: =IF('Project'!C3="","",'Project'!C3) | E5: =IF('Project'!D3="","",'Project'!D3) | F5: =IF('Project'!E3="","",'Project'!E3) | G5: =IF('Project'!F3="","",'Project'!F3) | H5: =IF('Project'!G3="","",'Project'!G3) | I5: =IF('Project'!H3="","",'Project'!H3) | J5: =IF('Project'!I3="","",'Project'!I3) | ... N5: =IF('Project'!M3="","",'Project'!M3)
A6: =IF('Project'!A4="","",'Project'!A4) | B6: Project | C6: =IF('Project'!B4="","",'Project'!B4) | D6: =IF('Project'!C4="","",'Project'!C4) | E6: =IF('Project'!D4="","",'Project'!D4) | F6: =IF('Project'!E4="","",'Project'!E4) | G6: =IF('Project'!F4="","",'Project'!F4) | H6: =IF('Project'!G4="","",'Project'!G4) | I6: =IF('Project'!H4="","",'Project'!H4) | J6: =IF('Project'!I4="","",'Project'!I4) | ... N6: =IF('Project'!M4="","",'Project'!M4)
A7: =IF('Project'!A5="","",'Project'!A5) | B7: Project | C7: =IF('Project'!B5="","",'Project'!B5) | D7: =IF('Project'!C5="","",'Project'!C5) | E7: =IF('Project'!D5="","",'Project'!D5) | F7: =IF('Project'!E5="","",'Project'!E5) | G7: =IF('Project'!F5="","",'Project'!F5) | H7: =IF('Project'!G5="","",'Project'!G5) | I7: =IF('Project'!H5="","",'Project'!H5) | J7: =IF('Project'!I5="","",'Project'!I5) | ... N7: =IF('Project'!M5="","",'Project'!M5)
A8: =IF('Project'!A6="","",'Project'!A6) | B8: Project | C8: =IF('Project'!B6="","",'Project'!B6) | D8: =IF('Project'!C6="","",'Project'!C6) | E8: =IF('Project'!D6="","",'Project'!D6) | F8: =IF('Project'!E6="","",'Project'!E6) | G8: =IF('Project'!F6="","",'Project'!F6) | H8: =IF('Project'!G6="","",'Project'!G6) | I8: =IF('Project'!H6="","",'Project'!H6) | J8: =IF('Project'!I6="","",'Project'!I6) | ... N8: =IF('Project'!M6="","",'Project'!M6)
A9: =IF('Project'!A7="","",'Project'!A7) | B9: Project | C9: =IF('Project'!B7="","",'Project'!B7) | D9: =IF('Project'!C7="","",'Project'!C7) | E9: =IF('Project'!D7="","",'Project'!D7) | F9: =IF('Project'!E7="","",'Project'!E7) | G9: =IF('Project'!F7="","",'Project'!F7) | H9: =IF('Project'!G7="","",'Project'!G7) | I9: =IF('Project'!H7="","",'Project'!H7) | J9: =IF('Project'!I7="","",'Project'!I7) | ... N9: =IF('Project'!M7="","",'Project'!M7)
A10: =IF('Project'!A8="","",'Project'!A8) | B10: Project | C10: =IF('Project'!B8="","",'Project'!B8) | D10: =IF('Project'!C8="","",'Project'!C8) | E10: =IF('Project'!D8="","",'Project'!D8) | F10: =IF('Project'!E8="","",'Project'!E8) | G10: =IF('Project'!F8="","",'Project'!F8) | H10: =IF('Project'!G8="","",'Project'!G8) | I10: =IF('Project'!H8="","",'Project'!H8) | J10: =IF('Project'!I8="","",'Project'!I8) | ... N10: =IF('Project'!M8="","",'Project'!M8)
A11: =IF('Project'!A9="","",'Project'!A9) | B11: Project | C11: =IF('Project'!B9="","",'Project'!B9) | D11: =IF('Project'!C9="","",'Project'!C9) | E11: =IF('Project'!D9="","",'Project'!D9) | F11: =IF('Project'!E9="","",'Project'!E9) | G11: =IF('Project'!F9="","",'Project'!F9) | H11: =IF('Project'!G9="","",'Project'!G9) | I11: =IF('Project'!H9="","",'Project'!H9) | J11: =IF('Project'!I9="","",'Project'!I9) | ... N11: =IF('Project'!M9="","",'Project'!M9)
A12: =IF('Networking'!A3="","",'Networking'!A3) | B12: Networking | C12: =IF('Networking'!B3="","",'Networking'!B3) | D12: =IF('Networking'!C3="","",'Networking'!C3) | E12: =IF('Networking'!D3="","",'Networking'!D3) | F12: =IF('Networking'!E3="","",'Networking'!E3) | G12: =IF('Networking'!F3="","",'Networking'!F3) | H12: =IF('Networking'!G3="","",'Networking'!G3) | I12: =IF('Networking'!H3="","",'Networking'!H3) | J12: =IF('Networking'!I3="","",'Networking'!I3) | ... N12: =IF('Networking'!M3="","",'Networking'!M3)
A13: =IF('Networking'!A4="","",'Networking'!A4) | B13: Networking | C13: =IF('Networking'!B4="","",'Networking'!B4) | D13: =IF('Networking'!C4="","",'Networking'!C4) | E13: =IF('Networking'!D4="","",'Networking'!D4) | F13: =IF('Networking'!E4="","",'Networking'!E4) | G13: =IF('Networking'!F4="","",'Networking'!F4) | H13: =IF('Networking'!G4="","",'Networking'!G4) | I13: =IF('Networking'!H4="","",'Networking'!H4) | J13: =IF('Networking'!I4="","",'Networking'!I4) | ... N13: =IF('Networking'!M4="","",'Networking'!M4)
A14: =IF('Networking'!A5="","",'Networking'!A5) | B14: Networking | C14: =IF('Networking'!B5="","",'Networking'!B5) | D14: =IF('Networking'!C5="","",'Networking'!C5) | E14: =IF('Networking'!D5="","",'Networking'!D5) | F14: =IF('Networking'!E5="","",'Networking'!E5) | G14: =IF('Networking'!F5="","",'Networking'!F5) | H14: =IF('Networking'!G5="","",'Networking'!G5) | I14: =IF('Networking'!H5="","",'Networking'!H5) | J14: =IF('Networking'!I5="","",'Networking'!I5) | ... N14: =IF('Networking'!M5="","",'Networking'!M5)
A15: =IF('Networking'!A6="","",'Networking'!A6) | B15: Networking | C15: =IF('Networking'!B6="","",'Networking'!B6) | D15: =IF('Networking'!C6="","",'Networking'!C6) | E15: =IF('Networking'!D6="","",'Networking'!D6) | F15: =IF('Networking'!E6="","",'Networking'!E6) | G15: =IF('Networking'!F6="","",'Networking'!F6) | H15: =IF('Networking'!G6="","",'Networking'!G6) | I15: =IF('Networking'!H6="","",'Networking'!H6) | J15: =IF('Networking'!I6="","",'Networking'!I6) | ... N15: =IF('Networking'!M6="","",'Networking'!M6)
A16: =IF('Networking'!A7="","",'Networking'!A7) | B16: Networking | C16: =IF('Networking'!B7="","",'Networking'!B7) | D16: =IF('Networking'!C7="","",'Networking'!C7) | E16: =IF('Networking'!D7="","",'Networking'!D7) | F16: =IF('Networking'!E7="","",'Networking'!E7) | G16: =IF('Networking'!F7="","",'Networking'!F7) | H16: =IF('Networking'!G7="","",'Networking'!G7) | I16: =IF('Networking'!H7="","",'Networking'!H7) | J16: =IF('Networking'!I7="","",'Networking'!I7) | ... N16: =IF('Networking'!M7="","",'Networking'!M7)
A17: =IF('Networking'!A8="","",'Networking'!A8) | B17: Networking | C17: =IF('Networking'!B8="","",'Networking'!B8) | D17: =IF('Networking'!C8="","",'Networking'!C8) | E17: =IF('Networking'!D8="","",'Networking'!D8) | F17: =IF('Networking'!E8="","",'Networking'!E8) | G17: =IF('Networking'!F8="","",'Networking'!F8) | H17: =IF('Networking'!G8="","",'Networking'!G8) | I17: =IF('Networking'!H8="","",'Networking'!H8) | J17: =IF('Networking'!I8="","",'Networking'!I8) | ... N17: =IF('Networking'!M8="","",'Networking'!M8)
A18: =IF('Networking'!A9="","",'Networking'!A9) | B18: Networking | C18: =IF('Networking'!B9="","",'Networking'!B9) | D18: =IF('Networking'!C9="","",'Networking'!C9) | E18: =IF('Networking'!D9="","",'Networking'!D9) | F18: =IF('Networking'!E9="","",'Networking'!E9) | G18: =IF('Networking'!F9="","",'Networking'!F9) | H18: =IF('Networking'!G9="","",'Networking'!G9) | I18: =IF('Networking'!H9="","",'Networking'!H9) | J18: =IF('Networking'!I9="","",'Networking'!I9) | ... N18: =IF('Networking'!M9="","",'Networking'!M9)
A19: =IF('Networking'!A10="","",'Networking'!A10) | B19: Networking | C19: =IF('Networking'!B10="","",'Networking'!B10) | D19: =IF('Networking'!C10="","",'Networking'!C10) | E19: =IF('Networking'!D10="","",'Networking'!D10) | F19: =IF('Networking'!E10="","",'Networking'!E10) | G19: =IF('Networking'!F10="","",'Networking'!F10) | H19: =IF('Networking'!G10="","",'Networking'!G10) | I19: =IF('Networking'!H10="","",'Networking'!H10) | J19: =IF('Networking'!I10="","",'Networking'!I10) | ... N19: =IF('Networking'!M10="","",'Networking'!M10)
A20: =IF('Networking'!A11="","",'Networking'!A11) | B20: Networking | C20: =IF('Networking'!B11="","",'Networking'!B11) | D20: =IF('Networking'!C11="","",'Networking'!C11) | E20: =IF('Networking'!D11="","",'Networking'!D11) | F20: =IF('Networking'!E11="","",'Networking'!E11) | G20: =IF('Networking'!F11="","",'Networking'!F11) | H20: =IF('Networking'!G11="","",'Networking'!G11) | I20: =IF('Networking'!H11="","",'Networking'!H11) | J20: =IF('Networking'!I11="","",'Networking'!I11) | ... N20: =IF('Networking'!M11="","",'Networking'!M11)
A21: =IF('Networking'!A12="","",'Networking'!A12) | B21: Networking | C21: =IF('Networking'!B12="","",'Networking'!B12) | D21: =IF('Networking'!C12="","",'Networking'!C12) | E21: =IF('Networking'!D12="","",'Networking'!D12) | F21: =IF('Networking'!E12="","",'Networking'!E12) | G21: =IF('Networking'!F12="","",'Networking'!F12) | H21: =IF('Networking'!G12="","",'Networking'!G12) | I21: =IF('Networking'!H12="","",'Networking'!H12) | J21: =IF('Networking'!I12="","",'Networking'!I12) | ... N21: =IF('Networking'!M12="","",'Networking'!M12)
A22: =IF('Networking'!A13="","",'Networking'!A13) | B22: Networking | C22: =IF('Networking'!B13="","",'Networking'!B13) | D22: =IF('Networking'!C13="","",'Networking'!C13) | E22: =IF('Networking'!D13="","",'Networking'!D13) | F22: =IF('Networking'!E13="","",'Networking'!E13) | G22: =IF('Networking'!F13="","",'Networking'!F13) | H22: =IF('Networking'!G13="","",'Networking'!G13) | I22: =IF('Networking'!H13="","",'Networking'!H13) | J22: =IF('Networking'!I13="","",'Networking'!I13) | ... N22: =IF('Networking'!M13="","",'Networking'!M13)
A23: =IF('Networking'!A14="","",'Networking'!A14) | B23: Networking | C23: =IF('Networking'!B14="","",'Networking'!B14) | D23: =IF('Networking'!C14="","",'Networking'!C14) | E23: =IF('Networking'!D14="","",'Networking'!D14) | F23: =IF('Networking'!E14="","",'Networking'!E14) | G23: =IF('Networking'!F14="","",'Networking'!F14) | H23: =IF('Networking'!G14="","",'Networking'!G14) | I23: =IF('Networking'!H14="","",'Networking'!H14) | J23: =IF('Networking'!I14="","",'Networking'!I14) | ... N23: =IF('Networking'!M14="","",'Networking'!M14)
... A25: =IF('Networking'!A16="","",'Networking'!A16) | B25: Networking | C25: =IF('Networking'!B16="","",'Networking'!B16) | D25: =IF('Networking'!C16="","",'Networking'!C16) | E25: =IF('Networking'!D16="","",'Networking'!D16) | F25: =IF('Networking'!E16="","",'Networking'!E16) | G25: =IF('Networking'!F16="","",'Networking'!F16) | H25: =IF('Networking'!G16="","",'Networking'!G16) | I25: =IF('Networking'!H16="","",'Networking'!H16) | J25: =IF('Networking'!I16="","",'Networking'!I16) | ... N25: =IF('Networking'!M16="","",'Networking'!M16)
A26: =IF('Security'!A3="","",'Security'!A3) | B26: Security | C26: =IF('Security'!B3="","",'Security'!B3) | D26: =IF('Security'!C3="","",'Security'!C3) | E26: =IF('Security'!D3="","",'Security'!D3) | F26: =IF('Security'!E3="","",'Security'!E3) | G26: =IF('Security'!F3="","",'Security'!F3) | H26: =IF('Security'!G3="","",'Security'!G3) | I26: =IF('Security'!H3="","",'Security'!H3) | J26: =IF('Security'!I3="","",'Security'!I3) | ... N26: =IF('Security'!M3="","",'Security'!M3)
A27: =IF('Security'!A4="","",'Security'!A4) | B27: Security | C27: =IF('Security'!B4="","",'Security'!B4) | D27: =IF('Security'!C4="","",'Security'!C4) | E27: =IF('Security'!D4="","",'Security'!D4) | F27: =IF('Security'!E4="","",'Security'!E4) | G27: =IF('Security'!F4="","",'Security'!F4) | H27: =IF('Security'!G4="","",'Security'!G4) | I27: =IF('Security'!H4="","",'Security'!H4) | J27: =IF('Security'!I4="","",'Security'!I4) | ... N27: =IF('Security'!M4="","",'Security'!M4)
A28: =IF('Security'!A5="","",'Security'!A5) | B28: Security | C28: =IF('Security'!B5="","",'Security'!B5) | D28: =IF('Security'!C5="","",'Security'!C5) | E28: =IF('Security'!D5="","",'Security'!D5) | F28: =IF('Security'!E5="","",'Security'!E5) | G28: =IF('Security'!F5="","",'Security'!F5) | H28: =IF('Security'!G5="","",'Security'!G5) | I28: =IF('Security'!H5="","",'Security'!H5) | J28: =IF('Security'!I5="","",'Security'!I5) | ... N28: =IF('Security'!M5="","",'Security'!M5)
A29: =IF('Security'!A6="","",'Security'!A6) | B29: Security | C29: =IF('Security'!B6="","",'Security'!B6) | D29: =IF('Security'!C6="","",'Security'!C6) | E29: =IF('Security'!D6="","",'Security'!D6) | F29: =IF('Security'!E6="","",'Security'!E6) | G29: =IF('Security'!F6="","",'Security'!F6) | H29: =IF('Security'!G6="","",'Security'!G6) | I29: =IF('Security'!H6="","",'Security'!H6) | J29: =IF('Security'!I6="","",'Security'!I6) | ... N29: =IF('Security'!M6="","",'Security'!M6)
A30: =IF('Security'!A7="","",'Security'!A7) | B30: Security | C30: =IF('Security'!B7="","",'Security'!B7) | D30: =IF('Security'!C7="","",'Security'!C7) | E30: =IF('Security'!D7="","",'Security'!D7) | F30: =IF('Security'!E7="","",'Security'!E7) | G30: =IF('Security'!F7="","",'Security'!F7) | H30: =IF('Security'!G7="","",'Security'!G7) | I30: =IF('Security'!H7="","",'Security'!H7) | J30: =IF('Security'!I7="","",'Security'!I7) | ... N30: =IF('Security'!M7="","",'Security'!M7)
A31: =IF('Security'!A8="","",'Security'!A8) | B31: Security | C31: =IF('Security'!B8="","",'Security'!B8) | D31: =IF('Security'!C8="","",'Security'!C8) | E31: =IF('Security'!D8="","",'Security'!D8) | F31: =IF('Security'!E8="","",'Security'!E8) | G31: =IF('Security'!F8="","",'Security'!F8) | H31: =IF('Security'!G8="","",'Security'!G8) | I31: =IF('Security'!H8="","",'Security'!H8) | J31: =IF('Security'!I8="","",'Security'!I8) | ... N31: =IF('Security'!M8="","",'Security'!M8)
A32: =IF('Security'!A9="","",'Security'!A9) | B32: Security | C32: =IF('Security'!B9="","",'Security'!B9) | D32: =IF('Security'!C9="","",'Security'!C9) | E32: =IF('Security'!D9="","",'Security'!D9) | F32: =IF('Security'!E9="","",'Security'!E9) | G32: =IF('Security'!F9="","",'Security'!F9) | H32: =IF('Security'!G9="","",'Security'!G9) | I32: =IF('Security'!H9="","",'Security'!H9) | J32: =IF('Security'!I9="","",'Security'!I9) | ... N32: =IF('Security'!M9="","",'Security'!M9)
A33: =IF('Security'!A10="","",'Security'!A10) | B33: Security | C33: =IF('Security'!B10="","",'Security'!B10) | D33: =IF('Security'!C10="","",'Security'!C10) | E33: =IF('Security'!D10="","",'Security'!D10) | F33: =IF('Security'!E10="","",'Security'!E10) | G33: =IF('Security'!F10="","",'Security'!F10) | H33: =IF('Security'!G10="","",'Security'!G10) | I33: =IF('Security'!H10="","",'Security'!H10) | J33: =IF('Security'!I10="","",'Security'!I10) | ... N33: =IF('Security'!M10="","",'Security'!M10)
A34: =IF('Security'!A11="","",'Security'!A11) | B34: Security | C34: =IF('Security'!B11="","",'Security'!B11) | D34: =IF('Security'!C11="","",'Security'!C11) | E34: =IF('Security'!D11="","",'Security'!D11) | F34: =IF('Security'!E11="","",'Security'!E11) | G34: =IF('Security'!F11="","",'Security'!F11) | H34: =IF('Security'!G11="","",'Security'!G11) | I34: =IF('Security'!H11="","",'Security'!H11) | J34: =IF('Security'!I11="","",'Security'!I11) | ... N34: =IF('Security'!M11="","",'Security'!M11)
A35: =IF('Security'!A12="","",'Security'!A12) | B35: Security | C35: =IF('Security'!B12="","",'Security'!B12) | D35: =IF('Security'!C12="","",'Security'!C12) | E35: =IF('Security'!D12="","",'Security'!D12) | F35: =IF('Security'!E12="","",'Security'!E12) | G35: =IF('Security'!F12="","",'Security'!F12) | H35: =IF('Security'!G12="","",'Security'!G12) | I35: =IF('Security'!H12="","",'Security'!H12) | J35: =IF('Security'!I12="","",'Security'!I12) | ... N35: =IF('Security'!M12="","",'Security'!M12)
A36: =IF('Security'!A13="","",'Security'!A13) | B36: Security | C36: =IF('Security'!B13="","",'Security'!B13) | D36: =IF('Security'!C13="","",'Security'!C13) | E36: =IF('Security'!D13="","",'Security'!D13) | F36: =IF('Security'!E13="","",'Security'!E13) | G36: =IF('Security'!F13="","",'Security'!F13) | H36: =IF('Security'!G13="","",'Security'!G13) | I36: =IF('Security'!H13="","",'Security'!H13) | J36: =IF('Security'!I13="","",'Security'!I13) | ... N36: =IF('Security'!M13="","",'Security'!M13)
A37: =IF('Security'!A14="","",'Security'!A14) | B37: Security | C37: =IF('Security'!B14="","",'Security'!B14) | D37: =IF('Security'!C14="","",'Security'!C14) | E37: =IF('Security'!D14="","",'Security'!D14) | F37: =IF('Security'!E14="","",'Security'!E14) | G37: =IF('Security'!F14="","",'Security'!F14) | H37: =IF('Security'!G14="","",'Security'!G14) | I37: =IF('Security'!H14="","",'Security'!H14) | J37: =IF('Security'!I14="","",'Security'!I14) | ... N37: =IF('Security'!M14="","",'Security'!M14)
... A41: =IF('Security'!A18="","",'Security'!A18) | B41: Security | C41: =IF('Security'!B18="","",'Security'!B18) | D41: =IF('Security'!C18="","",'Security'!C18) | E41: =IF('Security'!D18="","",'Security'!D18) | F41: =IF('Security'!E18="","",'Security'!E18) | G41: =IF('Security'!F18="","",'Security'!F18) | H41: =IF('Security'!G18="","",'Security'!G18) | I41: =IF('Security'!H18="","",'Security'!H18) | J41: =IF('Security'!I18="","",'Security'!I18) | ... N41: =IF('Security'!M18="","",'Security'!M18)
A42: =IF('Compute'!A3="","",'Compute'!A3) | B42: Compute | C42: =IF('Compute'!B3="","",'Compute'!B3) | D42: =IF('Compute'!C3="","",'Compute'!C3) | E42: =IF('Compute'!D3="","",'Compute'!D3) | F42: =IF('Compute'!E3="","",'Compute'!E3) | G42: =IF('Compute'!F3="","",'Compute'!F3) | H42: =IF('Compute'!G3="","",'Compute'!G3) | I42: =IF('Compute'!H3="","",'Compute'!H3) | J42: =IF('Compute'!I3="","",'Compute'!I3) | ... N42: =IF('Compute'!M3="","",'Compute'!M3)
A43: =IF('Compute'!A4="","",'Compute'!A4) | B43: Compute | C43: =IF('Compute'!B4="","",'Compute'!B4) | D43: =IF('Compute'!C4="","",'Compute'!C4) | E43: =IF('Compute'!D4="","",'Compute'!D4) | F43: =IF('Compute'!E4="","",'Compute'!E4) | G43: =IF('Compute'!F4="","",'Compute'!F4) | H43: =IF('Compute'!G4="","",'Compute'!G4) | I43: =IF('Compute'!H4="","",'Compute'!H4) | J43: =IF('Compute'!I4="","",'Compute'!I4) | ... N43: =IF('Compute'!M4="","",'Compute'!M4)
A44: =IF('Compute'!A5="","",'Compute'!A5) | B44: Compute | C44: =IF('Compute'!B5="","",'Compute'!B5) | D44: =IF('Compute'!C5="","",'Compute'!C5) | E44: =IF('Compute'!D5="","",'Compute'!D5) | F44: =IF('Compute'!E5="","",'Compute'!E5) | G44: =IF('Compute'!F5="","",'Compute'!F5) | H44: =IF('Compute'!G5="","",'Compute'!G5) | I44: =IF('Compute'!H5="","",'Compute'!H5) | J44: =IF('Compute'!I5="","",'Compute'!I5) | ... N44: =IF('Compute'!M5="","",'Compute'!M5)
A45: =IF('Compute'!A6="","",'Compute'!A6) | B45: Compute | C45: =IF('Compute'!B6="","",'Compute'!B6) | D45: =IF('Compute'!C6="","",'Compute'!C6) | E45: =IF('Compute'!D6="","",'Compute'!D6) | F45: =IF('Compute'!E6="","",'Compute'!E6) | G45: =IF('Compute'!F6="","",'Compute'!F6) | H45: =IF('Compute'!G6="","",'Compute'!G6) | I45: =IF('Compute'!H6="","",'Compute'!H6) | J45: =IF('Compute'!I6="","",'Compute'!I6) | ... N45: =IF('Compute'!M6="","",'Compute'!M6)
...

Sheet Project
A1: Project Parameters
A2: Parameter Name | B2: Production | C2: Test | D2: DR | E2: Description | F2: Required | G2: Data Type | H2: Validation Rules | I2: Security Level | J2: Owner Team | K2: Dependencies | L2: Notes | M2: Last Updated
A3: solution.name | B3: aws-agentic-presales | C3: aws-agentic-presales | D3: aws-agentic-presales | E3: Solution identifier used for resource naming and tagging across all environments | F3: Yes | G3: String | H3: lowercase alphanumeric hyphens only max 50 chars | I3: Public | J3: Cloud CoE | M3: 2025-06-01
A4: solution.region.primary | B4: us-west-2 | C4: us-west-2 | D4: us-west-2 | E4: Primary AWS deployment region; isolated from PREDICTif us-east-1 workloads per SOW | F4: Yes | G4: String | H4: Valid AWS region code | I4: Public | J4: Cloud CoE | L4: Single region per SOW scope; multi-region deferred to Phase 2 | M4: 2025-06-01
A5: solution.environment | B5: production | C5: dev | D5: production | E5: Deployment environment identifier used in resource naming pattern eofw-{env}-* | F5: Yes | G5: String | H5: production | dev | staging | I5: Public | J5: Cloud CoE | L5: DR mirrors production environment naming | M5: 2025-06-01
A6: solution.version | B6: 1.0.0 | C6: 1.0.0 | D6: 1.0.0 | E6: Current platform release version tracked in GitHub and used for CLI pip package versioning | F6: Yes | G6: String | H6: Semantic versioning X.Y.Z | I6: Public | J6: Cloud CoE | M6: 2025-06-01
A7: solution.account_id | B7: [aws-account-id] | C7: [aws-account-id] | D7: [aws-account-id] | E7: AWS account ID hosting the us-west-2 platform footprint | F7: Yes | G7: String | H7: 12-digit numeric | I7: Confidential | J7: Cloud CoE | L7: Dedicated account isolated from us-east-1 per SOW scope | M7: 2025-06-01
A8: solution.cost_center | B8: AMATRA-PRESALES-2026 | C8: AMATRA-PRESALES-2026 | D8: AMATRA-PRESALES-2026 | E8: Cost center tag applied to all AWS resources for billing attribution per SOC 2 CC9.1 | F8: Yes | G8: String | H8: Non-empty string | I8: Public | J8: Cloud CoE | L8: Required tag enforced by Terraform and AWS Config rules | M8: 2025-06-01
A9: solution.deadline | B9: 2026-04-30 | C9: 2026-04-30 | D9: 2026-04-30 | E9: Hard go-live deadline (end of April 2026) for executive demonstration to Sarah Lin (CRO) | F9: Yes | G9: String | H9: ISO 8601 date YYYY-MM-DD | I9: Public | J9: Cloud CoE | L9: Critical path gate; drives 12-week delivery schedule | M9: 2025-06-01

Sheet Networking
A1: Networking Parameters
A2: Parameter Name | B2: Production | C2: Test | D2: DR | E2: Description | F2: Required | G2: Data Type | H2: Validation Rules | I2: Security Level | J2: Owner Team | K2: Dependencies | L2: Notes | M2: Last Updated
A3: networking.vpc_cidr | B3: 10.0.0.0/16 | C3: 10.0.0.0/16 | D3: 10.0.0.0/16 | E3: VPC CIDR block for the us-west-2 platform footprint; isolated from us-east-1 | F3: Yes | G3: String | H3: Valid CIDR /16 or smaller | I3: Confidential | J3: Network Team | K3: solution.region.primary | M3: 2025-06-01
A4: networking.subnet_public_az1_cidr | B4: 10.0.1.0/24 | C4: 10.0.1.0/24 | D4: 10.0.1.0/24 | E4: Public subnet AZ1 (us-west-2a) for NAT Gateway only; no Lambda compute in public subnets | F4: Yes | G4: String | H4: Valid CIDR within VPC CIDR | I4: Confidential | J4: Network Team | K4: networking.vpc_cidr | M4: 2025-06-01
A5: networking.subnet_public_az2_cidr | B5: 10.0.2.0/24 | C5: 10.0.2.0/24 | D5: 10.0.2.0/24 | E5: Public subnet AZ2 (us-west-2b) for NAT Gateway only | F5: Yes | G5: String | H5: Valid CIDR within VPC CIDR | I5: Confidential | J5: Network Team | K5: networking.vpc_cidr | M5: 2025-06-01
A6: networking.subnet_private_az1_cidr | B6: 10.0.10.0/24 | C6: 10.0.10.0/24 | D6: 10.0.10.0/24 | E6: Private subnet AZ1 (us-west-2a) hosting all Lambda functions and agent orchestration | F6: Yes | G6: String | H6: Valid CIDR within VPC CIDR | I6: Confidential | J6: Network Team | K6: networking.vpc_cidr | M6: 2025-06-01
A7: networking.subnet_private_az2_cidr | B7: 10.0.11.0/24 | C7: 10.0.11.0/24 | D7: 10.0.11.0/24 | E7: Private subnet AZ2 (us-west-2b) hosting all Lambda functions and agent orchestration | F7: Yes | G7: String | H7: Valid CIDR within VPC CIDR | I7: Confidential | J7: Network Team | K7: networking.vpc_cidr | M7: 2025-06-01
A8: networking.subnet_db_az1_cidr | B8: 10.0.20.0/24 | C8: 10.0.20.0/24 | D8: 10.0.20.0/24 | E8: Database subnet AZ1 reserved for future RDS/ElastiCache; DynamoDB accessed via VPC Endpoint | F8: Yes | G8: String | H8: Valid CIDR within VPC CIDR | I8: Confidential | J8: Network Team | K8: networking.vpc_cidr | M8: 2025-06-01
A9: networking.subnet_db_az2_cidr | B9: 10.0.21.0/24 | C9: 10.0.21.0/24 | D9: 10.0.21.0/24 | E9: Database subnet AZ2 reserved for future RDS/ElastiCache | F9: Yes | G9: String | H9: Valid CIDR within VPC CIDR | I9: Confidential | J9: Network Team | K9: networking.vpc_cidr | M9: 2025-06-01
A10: networking.nat_gateway_count | B10: 1 | C10: 1 | D10: 1 | E10: NAT Gateways deployed in public subnets for Lambda outbound internet access | F10: Yes | G10: Integer | H10: 1-3 | I10: Public | J10: Network Team | K10: networking.vpc_cidr | L10: Single NAT in AZ1 for PoC; second AZ2 NAT recommended in Phase 2 for AZ resilience | M10: 2025-06-01
A11: networking.vpc_endpoint_s3 | B11: true | C11: true | D11: true | E11: Enable S3 Gateway VPC Endpoint to route Lambda-to-S3 traffic without public internet | F11: Yes | G11: Boolean | H11: true | false | I11: Public | J11: Network Team | K11: networking.vpc_cidr | L11: Required to keep artifact reads/writes off public internet | M11: 2025-06-01
A12: networking.vpc_endpoint_dynamodb | B12: true | C12: true | D12: true | E12: Enable DynamoDB Gateway VPC Endpoint to route Lambda-to-DynamoDB quota operations privately | F12: Yes | G12: Boolean | H12: true | false | I12: Public | J12: Network Team | K12: networking.vpc_cidr | L12: Required for quota enforcement latency target < 50ms P99 | M12: 2025-06-01
A13: networking.vpc_endpoint_secrets_manager | B13: true | C13: true | D13: true | E13: Enable Secrets Manager Interface VPC Endpoint for PAT retrieval without public internet traversal | F13: Yes | G13: Boolean | H13: true | false | I13: Public | J13: Network Team | K13: networking.vpc_cidr | L13: Required for secure runtime PAT retrieval by GitHub push Lambda | M13: 2025-06-01
A14: networking.vpc_endpoint_bedrock_runtime | B14: true | C14: true | D14: true | E14: Enable Bedrock Runtime Interface VPC Endpoint to route agent invocations privately | F14: Yes | G14: Boolean | H14: true | false | I14: Public | J14: Network Team | K14: networking.vpc_cidr | L14: Reduces latency and eliminates public internet exposure of model invocations | M14: 2025-06-01
A15: networking.apigw_endpoint | B15: https://[apigw-id].execute-api.us-west-2.amazonaws.com | C15: https://[apigw-id].execute-api.us-west-2.amazonaws.com | D15: https://[apigw-id].execute-api.us-west-2.amazonaws.com | E15: API Gateway HTTP API v2 regional endpoint base URL | F15: Yes | G15: String | H15: Valid HTTPS URL | I15: Confidential | J15: Network Team | K15: solution.region.primary | L15: HTTPS-only; HTTP rejected; 11 Lambda routes mounted under /api/v1/ | M15: 2025-06-01
A16: networking.apigw_throttle_rps_burst | B16: 1000 | C16: 100 | D16: 1000 | E16: API Gateway burst throttle limit in requests per second | F16: Yes | G16: Integer | H16: 1-10000 | I16: Public | J16: Network Team | K16: networking.apigw_endpoint | L16: Per-user quota enforced in DynamoDB in addition to API Gateway throttle | M16: 2025-06-01

Sheet Security
A1: Security Parameters
A2: Parameter Name | B2: Production | C2: Test | D2: DR | E2: Description | F2: Required | G2: Data Type | H2: Validation Rules | I2: Security Level | J2: Owner Team | K2: Dependencies | L2: Notes | M2: Last Updated
A3: security.cognito.user_pool_name | B3: eofw-prd-userpool | C3: eofw-dev-userpool | D3: eofw-prd-userpool | E3: Amazon Cognito User Pool name providing JWT authentication for all 11 API routes and CLI | F3: Yes | G3: String | H3: Non-empty string max 128 chars | I3: Confidential | J3: Security Team | K3: solution.region.primary | M3: 2025-06-01
A4: security.cognito.user_pool_id | B4: [cognito-user-pool-id] | C4: [cognito-user-pool-id] | D4: [cognito-user-pool-id] | E4: Cognito User Pool ID; referenced by API Gateway JWT authoriser and Lambda route handlers | F4: Yes | G4: String | H4: Format: {region}_{poolId} | I4: Secret | J4: Security Team | K4: security.cognito.user_pool_name | L4: Store in Secrets Manager; CTO sign-off required before provisioning in production | M4: 2025-06-01
A5: security.cognito.app_client_id | B5: [cognito-app-client-id] | C5: [cognito-app-client-id] | D5: [cognito-app-client-id] | E5: Cognito User Pool App Client ID used by the CLI for PKCE-based authorization code flow | F5: Yes | G5: String | H5: Alphanumeric | I5: Secret | J5: Security Team | K5: security.cognito.user_pool_id | L5: Store in Secrets Manager; never bake into CLI package or container image | M5: 2025-06-01
A6: security.cognito.access_token_expiry_seconds | B6: 3600 | C6: 3600 | D6: 3600 | E6: JWT access token expiry in seconds (1 hour); CLI auto-refreshes using stored refresh token | F6: Yes | G6: Integer | H6: 300-86400 | I6: Public | J6: Security Team | K6: security.cognito.user_pool_id | L6: SOC 2 CC6.1 control; short expiry limits blast radius of compromised token | M6: 2025-06-01
A7: security.cognito.refresh_token_expiry_days | B7: 30 | C7: 30 | D7: 30 | E7: Cognito refresh token validity in days per SOW Security & Compliance specification | F7: Yes | G7: Integer | H7: 1-3650 | I7: Public | J7: Security Team | K7: security.cognito.user_pool_id | L7: 30-day refresh token per SOW; CLI stores in ~/.eoframework/credentials | M7: 2025-06-01
A8: security.cognito.mfa_enabled | B8: true | C8: false | D8: true | E8: Require MFA for Admin role in production; standard Cognito MFA setting | F8: Yes | G8: Boolean | H8: true | false | I8: Public | J8: Security Team | K8: security.cognito.user_pool_id | L8: SOC 2 CC6.1 control; Admin role requires MFA; Consultant role exempt at PoC | M8: 2025-06-01
A9: security.cognito.cto_signoff_required | B9: true | C9: false | D9: true | E9: CTO approval gate required before provisioning production Cognito User Pool per SOW | F9: Yes | G9: Boolean | H9: true | false | I9: Public | J9: Security Team | K9: security.cognito.user_pool_id | L9: Critical path for Phase 1 milestone M3; must not slip beyond Week 3 | M9: 2025-06-01
A10: security.kms.s3_cmk_arn | B10: [kms-s3-cmk-arn] | C10: [kms-s3-cmk-arn] | D10: [kms-s3-cmk-arn] | E10: Customer-managed KMS key ARN for S3 artifact bucket SSE-KMS encryption at rest | F10: Yes | G10: String | H10: Valid KMS key ARN | I10: Secret | J10: Security Team | K10: storage.s3.artifact_bucket_name | L10: Stored in Secrets Manager; 90-day key rotation policy; key usage logged in CloudTrail | M10: 2025-06-01
A11: security.kms.rotation_days | B11: 90 | C11: 90 | D11: 90 | E11: KMS key rotation period in days applied to S3 CMK and Secrets Manager encryption keys | F11: Yes | G11: Integer | H11: 1-365 | I11: Public | J11: Security Team | K11: security.kms.s3_cmk_arn | M11: 2025-06-01
A12: security.iam.access_analyzer_enabled | B12: true | C12: true | D12: true | E12: Enable IAM Access Analyzer to continuously validate no overly permissive Lambda execution roles exist | F12: Yes | G12: Boolean | H12: true | false | I12: Public | J12: Security Team | L12: Required by SOW security design; no wildcard IAM actions permitted | M12: 2025-06-01
A13: security.guardduty_enabled | B13: true | C13: true | D13: true | E13: Enable AWS GuardDuty for threat detection in us-west-2 account; findings routed to Security Hub | F13: Yes | G13: Boolean | H13: true | false | I13: Public | J13: Security Team | K13: security.securityhub_enabled | M13: 2025-06-01
A14: security.securityhub_enabled | B14: true | C14: true | D14: true | E14: Enable AWS Security Hub aggregating GuardDuty / Config / Inspector findings for SOC 2 posture | F14: Yes | G14: Boolean | H14: true | false | I14: Public | J14: Security Team | K14: security.guardduty_enabled | L14: SOC 2 CC7.2 control; reviewed by Daniel Park quarterly | M14: 2025-06-01
A15: security.cloudtrail.management_events | B15: true | C15: true | D15: true | E15: Enable CloudTrail Management Events logging all AWS API calls in us-west-2 account | F15: Yes | G15: Boolean | H15: true | false | I15: Public | J15: Security Team | L15: SOC 2 CC8.1 control; logs stored in dedicated S3 bucket with Object Lock (WORM) | M15: 2025-06-01
A16: security.cloudtrail.s3_data_events | B16: true | C16: false | D16: true | E16: Enable CloudTrail S3 Data Events on artifact bucket for GetObject/PutObject audit trail | F16: Yes | G16: Boolean | H16: true | false | I16: Public | J16: Security Team | K16: storage.s3.artifact_bucket_name | L16: SOC 2 CC6.1 evidence; disabled in dev to reduce CloudTrail cost | M16: 2025-06-01
A17: security.cloudtrail.retention_days | B17: 365 | C17: 90 | D17: 365 | E17: CloudTrail log retention in days in dedicated S3 bucket with Object Lock | F17: Yes | G17: Integer | H17: 90-3650 | I17: Public | J17: Security Team | L17: 365 days required for SOC 2 evidence window | M17: 2025-06-01
A18: security.tls_minimum_version | B18: TLS1.2 | C18: TLS1.2 | D18: TLS1.2 | E18: Minimum TLS version enforced on API Gateway / Cognito / DynamoDB / S3 SDK endpoints | F18: Yes | G18: String | H18: TLS1.2 | TLS1.3 | I18: Public | J18: Security Team | L18: No HTTP endpoints; all requests rejected without TLS per SOW security design | M18: 2025-06-01

Sheet Compute
A1: Compute Parameters
A2: Parameter Name | B2: Production | C2: Test | D2: DR | E2: Description | F2: Required | G2: Data Type | H2: Validation Rules | I2: Security Level | J2: Owner Team | K2: Dependencies | L2: Notes | M2: Last Updated
A3: compute.lambda.api_handler.memory_mb | B3: 256 | C3: 256 | D3: 256 | E3: Memory allocation for non-generation API route handler Lambda functions (10 functions) | F3: Yes | G3: Integer | H3: 128-10240 | I3: Public | J3: Development | K3: solution.region.primary | M3: 2025-06-01
A4: compute.lambda.api_handler.timeout_seconds | B4: 30 | C4: 30 | D4: 30 | E4: Timeout for synchronous API route handlers; generation initiator uses separate config | F4: Yes | G4: Integer | H4: 1-900 | I4: Public | J4: Development | M4: 2025-06-01
A5: compute.lambda.generation_initiator.memory_mb | B5: 512 | C5: 512 | D5: 512 | E5: Memory for the Solution Generation Initiator Lambda that triggers the five-agent graph | F5: Yes | G5: Integer | H5: 128-10240 | I5: Public | J5: Development | K5: bedrock.agentcore.runtime_region | M5: 2025-06-01
A6: compute.lambda.generation_initiator.timeout_seconds | B6: 60 | C6: 60 | D6: 60 | E6: Timeout for the Solution Generation Initiator Lambda; returns 202 Accepted immediately | F6: Yes | G6: Integer | H6: 1-900 | I6: Public | J6: Development | K6: compute.lambda.generation_initiator.memory_mb | M6: 2025-06-01
A7: compute.lambda.agent_trigger.memory_mb | B7: 1024 | C7: 1024 | D7: 1024 | E7: Memory for the 5 agent orchestration trigger Lambdas running eof-tools container image | F7: Yes | G7: Integer | H7: 128-10240 | I7: Public | J7: Development | K7: compute.ecr.agent_image_uri | M7: 2025-06-01
A8: compute.lambda.agent_trigger.timeout_seconds | B8: 900 | C8: 900 | D8: 900 | E8: Maximum Lambda timeout applied to agent triggers to accommodate eof-tools conversion | F8: Yes | G8: Integer | H8: 1-900 | I8: Public | J8: Development | K8: compute.lambda.agent_trigger.memory_mb | L8: Must be ≤ Bedrock AgentCore Runtime invocation timeout | M8: 2025-06-01
A9: compute.lambda.cognito_trigger.memory_mb | B9: 256 | C9: 256 | D9: 256 | E9: Memory for the Cognito post-confirmation trigger Lambda that writes DynamoDB user profiles | F9: Yes | G9: Integer | H9: 128-10240 | I9: Public | J9: Development | K9: security.cognito.user_pool_id | M9: 2025-06-01
A10: compute.lambda.cognito_trigger.timeout_seconds | B10: 10 | C10: 10 | D10: 10 | E10: Timeout for the Cognito post-confirmation trigger; must complete before Cognito times out | F10: Yes | G10: Integer | H10: 1-900 | I10: Public | J10: Development | K10: compute.lambda.cognito_trigger.memory_mb | M10: 2025-06-01
A11: compute.lambda.github_push.memory_mb | B11: 256 | C11: 256 | D11: 256 | E11: Memory for the GitHub push Lambda that commits artifacts to the configured repository | F11: Yes | G11: Integer | H11: 128-10240 | I11: Public | J11: Development | K11: integration.github.secret_arn | M11: 2025-06-01
A12: compute.lambda.github_push.timeout_seconds | B12: 60 | C12: 60 | D12: 60 | E12: Timeout for GitHub push Lambda; accounts for Secrets Manager retrieval and GitHub API call | F12: Yes | G12: Integer | H12: 1-900 | I12: Public | J12: Development | K12: compute.lambda.github_push.memory_mb | M12: 2025-06-01
A13: compute.lambda.runtime | B13: python3.12 | C13: python3.12 | D13: python3.12 | E13: Python runtime version for all 17 Lambda functions | F13: Yes | G13: String | H13: Valid AWS Lambda runtime identifier | I13: Public | J13: Development | M13: 2025-06-01
A14: compute.lambda.architecture | B14: arm64 | C14: arm64 | D14: arm64 | E14: Lambda function CPU architecture; arm64 provides better price-performance for Python workloads | F14: Yes | G14: String | H14: x86_64 | arm64 | I14: Public | J14: Development | M14: 2025-06-01
A15: compute.lambda.total_function_count | B15: 17 | C15: 17 | D15: 17 | E15: Total Lambda functions: 11 API routes + 5 agent triggers + 1 Cognito post-confirmation | F15: Yes | G15: Integer | H15: 17 | I15: Public | J15: Development | M15: 2025-06-01
A16: compute.lambda.provisioned_concurrency_agent_triggers | B16: 0 | C16: 0 | D16: 0 | E16: Provisioned concurrency for agent triggers; set to 0 at launch; evaluate after Phase 3 load test | F16: Yes | G16: Integer | H16: 0-100 | I16: Public | J16: Development | K16: compute.lambda.agent_trigger.memory_mb | L16: Increase if P99 cold-start timeout observed in Phase 3 load test per risk register | M16: 2025-06-01
A17: compute.ecr.repository_name | B17: eofw-prd-ecr-agent-image | C17: eofw-dev-ecr-agent-image | D17: eofw-prd-ecr-agent-image | E17: ECR repository name for the eof-tools agent container image | F17: Yes | G17: String | H17: Valid ECR repo name | I17: Confidential | J17: DevOps | K17: solution.region.primary | M17: 2025-06-01
A18: compute.ecr.agent_image_uri | B18: [ecr-agent-image-uri] | C18: [ecr-agent-image-uri] | D18: [ecr-agent-image-uri] | E18: Full ECR URI including tag for the eof-tools Docker image baked with ~30 Python converter modules | F18: Yes | G18: String | H18: Valid ECR URI format: {account}.dkr.ecr.{region}.amazonaws.com/{repo}:{tag} | I18: Confidential | J18: DevOps | K18: compute.ecr.repository_name | L18: Image tag must be immutable; updated each sprint via CI/CD pipeline | M18: 2025-06-01
A19: compute.lambda.xray_tracing | B19: Active | C19: Active | D19: Active | E19: AWS X-Ray tracing mode for all 17 Lambda functions; enables distributed service maps | F19: Yes | G19: String | H19: Active | PassThrough | I19: Public | J19: Operations | M19: 2025-06-01

Sheet Storage
A1: Storage Parameters
A2: Parameter Name | B2: Production | C2: Test | D2: DR | E2: Description | F2: Required | G2: Data Type | H2: Validation Rules | I2: Security Level | J2: Owner Team | K2: Dependencies | L2: Notes | M2: Last Updated
A3: storage.s3.artifact_bucket_name | B3: [s3-artifact-bucket-name] | C3: [s3-artifact-bucket-name] | D3: [s3-artifact-bucket-name] | E3: S3 bucket for all generated artifacts: raw MD/CSV + converted DOCX/PPTX/XLSX + Terraform bundles | F3: Yes | G3: String | H3: Globally unique bucket name lowercase alphanumeric hyphens | I3: Confidential | J3: Operations | K3: solution.region.primary | L3: Versioning enabled; SSE-KMS encryption; public access block enabled | M3: 2025-06-01
A4: storage.s3.artifact_bucket_versioning | B4: Enabled | C4: Enabled | D4: Enabled | E4: S3 versioning on artifact bucket; retains previous object versions for 90 days | F4: Yes | G4: String | H4: Enabled | Suspended | I4: Public | J4: Operations | K4: storage.s3.artifact_bucket_name | L4: S3 versioning covers artifact history for RPO of 1 hour | M4: 2025-06-01
A5: storage.s3.artifact_standard_retention_days | B5: 365 | C5: 90 | D5: 365 | E5: S3 Standard storage retention in days before lifecycle transition to S3 Glacier | F5: Yes | G5: Integer | H5: 1-3650 | I5: Public | J5: Operations | K5: storage.s3.artifact_bucket_name | L5: Managed via S3 Lifecycle rules; transition to Glacier after 12 months in production | M5: 2025-06-01
A6: storage.s3.artifact_glacier_retention_days | B6: 730 | C6: 0 | D6: 730 | E6: S3 Glacier retention in days before expiry after transition from Standard storage | F6: Yes | G6: Integer | H6: 0-3650 | I6: Public | J6: Operations | K6: storage.s3.artifact_standard_retention_days | L6: 730 days = 24 months Glacier per SOW Data Architecture section | M6: 2025-06-01
A7: storage.s3.artifact_path_raw_presales | B7: {solution_id}/raw/pre-sales/ | C7: {solution_id}/raw/pre-sales/ | D7: {solution_id}/raw/pre-sales/ | E7: S3 key prefix for raw MD/CSV presales artifacts per structured path hierarchy | F7: Yes | G7: String | H7: Must include {solution_id} token | I7: Public | J7: Development | K7: storage.s3.artifact_bucket_name | M7: 2025-06-01
A8: storage.s3.artifact_path_raw_delivery | B8: {solution_id}/raw/delivery/ | C8: {solution_id}/raw/delivery/ | D8: {solution_id}/raw/delivery/ | E8: S3 key prefix for raw MD delivery artifacts per structured path hierarchy | F8: Yes | G8: String | H8: Must include {solution_id} token | I8: Public | J8: Development | K8: storage.s3.artifact_bucket_name | M8: 2025-06-01
A9: storage.s3.artifact_path_automation | B9: {solution_id}/automation/ | C9: {solution_id}/automation/ | D9: {solution_id}/automation/ | E9: S3 key prefix for the Terraform IaC automation bundle (12th artifact type) | F9: Yes | G9: String | H9: Must include {solution_id} token | I9: Public | J9: Development | K9: storage.s3.artifact_bucket_name | M9: 2025-06-01
A10: storage.s3.cloudtrail_bucket_name | B10: [s3-cloudtrail-bucket-name] | C10: [s3-cloudtrail-bucket-name] | D10: [s3-cloudtrail-bucket-name] | E10: Dedicated S3 bucket for CloudTrail logs; Object Lock (WORM) enabled to prevent tampering | F10: Yes | G10: String | H10: Globally unique bucket name lowercase alphanumeric hyphens | I10: Confidential | J10: Security Team | K10: security.cloudtrail.management_events | L10: Separate from artifact bucket; Object Lock enforces immutability per SOC 2 CC8.1 | M10: 2025-06-01
A11: storage.s3.guidance_bucket_name | B11: [s3-guidance-bucket-name] | C11: [s3-guidance-bucket-name] | D11: [s3-guidance-bucket-name] | E11: S3 bucket hosting EO Framework guidance files used by generation agents for artifact prompting | F11: Yes | G11: String | H11: Globally unique bucket name lowercase alphanumeric hyphens | I11: Confidential | J11: Operations | K11: solution.region.primary | L11: Vendor team requires read access from Week 1 per SOW assumption A13 | M11: 2025-06-01

Sheet Database
A1: Database Parameters
A2: Parameter Name | B2: Production | C2: Test | D2: DR | E2: Description | F2: Required | G2: Data Type | H2: Validation Rules | I2: Security Level | J2: Owner Team | K2: Dependencies | L2: Notes | M2: Last Updated
A3: database.users_table_name | B3: eofw-prd-tbl-users | C3: eofw-dev-tbl-users | D3: eofw-prd-tbl-users | E3: DynamoDB table storing Cognito user profiles written by post-confirmation trigger Lambda | F3: Yes | G3: String | H3: Alphanumeric hyphens max 255 chars | I3: Confidential | J3: Database Team | K3: solution.region.primary | M3: 2025-06-01
A4: database.solutions_table_name | B4: eofw-prd-tbl-solutions | C4: eofw-dev-tbl-solutions | D4: eofw-prd-tbl-solutions | E4: DynamoDB table storing solution state / artifact statuses / per-phase token usage (PK: solution_id) | F4: Yes | G4: String | H4: Alphanumeric hyphens max 255 chars | I4: Confidential | J4: Database Team | K4: solution.region.primary | M4: 2025-06-01
A5: database.quotas_table_name | B5: eofw-prd-tbl-quotas | C5: eofw-dev-tbl-quotas | D5: eofw-prd-tbl-quotas | E5: DynamoDB table for per-user and global atomic quota counters (PK: user_id or GLOBAL) | F5: Yes | G5: String | H5: Alphanumeric hyphens max 255 chars | I5: Confidential | J5: Database Team | K5: solution.region.primary | L5: Atomic conditional writes prevent quota bypass; validated in Phase 3 security testing | M5: 2025-06-01
A6: database.audit_events_table_name | B6: eofw-prd-tbl-audit-events | C6: eofw-dev-tbl-audit-events | D6: eofw-prd-tbl-audit-events | E6: DynamoDB immutable audit log table capturing all API calls per SOC 2 CC7 requirements | F6: Yes | G6: String | H6: Alphanumeric hyphens max 255 chars | I6: Confidential | J6: Database Team | K6: solution.region.primary | M6: 2025-06-01
A7: database.billing_mode | B7: PAY_PER_REQUEST | C7: PAY_PER_REQUEST | D7: PAY_PER_REQUEST | E7: DynamoDB billing mode for all four tables; On-Demand auto-scales to any throughput | F7: Yes | G7: String | H7: PROVISIONED | PAY_PER_REQUEST | I7: Public | J7: Database Team | L7: Review reserved capacity at scale post-PoC per cost model | M7: 2025-06-01
A8: database.pitr_enabled | B8: true | C8: false | D8: true | E8: Enable DynamoDB Point-In-Time Recovery on all four tables; required for 4-hour RTO target | F8: Yes | G8: Boolean | H8: true | false | I8: Public | J8: Database Team | L8: PITR restore test executed in Phase 3 to validate RTO; 35-day recovery window | M8: 2025-06-01
A9: database.audit_events_ttl_days | B9: 90 | C9: 30 | D9: 90 | E9: TTL-based retention for audit_events records; expires items automatically without manual deletion | F9: Yes | G9: Integer | H9: 1-3653 | I9: Public | J9: Database Team | K9: database.audit_events_table_name | L9: SOC 2 CC7.2 evidence; set shorter in dev to control costs | M9: 2025-06-01
A10: database.quota_per_user_monthly | B10: 10 | C10: 10 | D10: 10 | E10: Maximum solutions per Amatra consultant per calendar month per SOW scope parameter | F10: Yes | G10: Integer | H10: 1-1000 | I10: Public | J10: Operations | K10: database.quotas_table_name | L10: Enforced via atomic DynamoDB conditional write; admin override available via API | M10: 2025-06-01
A11: database.quota_global_monthly | B11: 1000 | C11: 100 | D11: 1000 | E11: Maximum total solutions across all users per calendar month per SOW scope parameter | F11: Yes | G11: Integer | H11: 1-100000 | I11: Public | J11: Operations | K11: database.quotas_table_name | L11: CloudWatch alarm fires at 90% of this threshold (900 solutions) | M11: 2025-06-01
A12: database.inactive_user_suspension_days | B12: 90 | C12: 90 | D12: 90 | E12: Days of API inactivity before the scheduled Lambda suspends the Cognito account per SOC 2 CC6.2 | F12: Yes | G12: Integer | H12: 1-365 | I12: Public | J12: Security Team | K12: database.users_table_name | L12: Quarterly access reviews conducted by Daniel Park | M12: 2025-06-01

Sheet Application
A1: Application Parameters
A2: Parameter Name | B2: Production | C2: Test | D2: DR | E2: Description | F2: Required | G2: Data Type | H2: Validation Rules | I2: Security Level | J2: Owner Team | K2: Dependencies | L2: Notes | M2: Last Updated
A3: application.name | B3: eoframework | C3: eoframework | D3: eoframework | E3: Application identifier used in CloudWatch log groups and X-Ray service maps | F3: Yes | G3: String | H3: lowercase alphanumeric hyphens only max 50 chars | I3: Public | J3: Development | K3: solution.name | M3: 2025-06-01
A4: application.log_level | B4: info | C4: debug | D4: info | E4: Logging verbosity for all 17 Lambda functions; debug enabled in dev for agent tracing | F4: Yes | G4: String | H4: debug | info | warn | error | I4: Public | J4: Operations | M4: 2025-06-01
A5: application.port | B5: 443 | C5: 443 | D5: 443 | E5: HTTPS port enforced on API Gateway HTTP API v2; HTTP requests rejected | F5: Yes | G5: Integer | H5: 443 only | I5: Public | J5: Development | K5: networking.apigw_endpoint | M5: 2025-06-01
A6: application.timeout_seconds | B6: 30 | C6: 30 | D6: 30 | E6: Synchronous API route Lambda timeout in seconds; async generation routes use separate config | F6: Yes | G6: Integer | H6: 1-900 | I6: Public | J6: Development | K6: compute.lambda.api_handler.timeout_seconds | M6: 2025-06-01
A7: application.cli_package_name | B7: eoframework-cli | C7: eoframework-cli | D7: eoframework-cli | E7: Pip-installable Python package name for the 14-subcommand consultant-facing CLI | F7: Yes | G7: String | H7: Valid Python package name | I7: Public | J7: Development | M7: 2025-06-01
A8: application.cli_subcommand_count | B8: 14 | C8: 14 | D8: 14 | E8: Total CLI subcommands including auth / generate / status / admin per SOW specification | F8: Yes | G8: Integer | H8: 14 | I8: Public | J8: Development | K8: application.cli_package_name | L8: Must match SOW deliverable D11 exactly | M8: 2025-06-01
A9: application.api_route_count | B9: 11 | C9: 11 | D9: 11 | E9: Total HTTP API v2 Lambda routes per SOW specification | F9: Yes | G9: Integer | H9: 11 | I9: Public | J9: Development | K9: networking.apigw_endpoint | L9: Must match SOW deliverable D4 exactly | M9: 2025-06-01
A10: application.artifact_types_count | B10: 12 | C10: 12 | D10: 12 | E10: Total EO Framework artifact types: 5 presales + 6 delivery + 1 Terraform automation bundle | F10: Yes | G10: Integer | H10: 12 | I10: Public | J10: Development | M10: 2025-06-01
A11: application.agent_count | B11: 5 | C11: 5 | D11: 5 | E11: Total Strands agents registered in Bedrock AgentCore Runtime per SOW scope | F11: Yes | G11: Integer | H11: 5 | I11: Public | J11: Development | K11: bedrock.agentcore.runtime_region | M11: 2025-06-01
A12: application.max_retries_per_artifact | B12: 3 | C12: 3 | D12: 3 | E12: Maximum automatic retries per artifact in the EO Validator validation loop | F12: Yes | G12: Integer | H12: 1-10 | I12: Public | J12: Development | K12: bedrock.validator_model_id | L12: Graded delivery policy surfaces passing artifacts while retrying failures | M12: 2025-06-01
A13: application.generation_timeout_minutes | B13: 60 | C13: 60 | D13: 60 | E13: End-to-end 12-artifact solution bundle generation time limit; SLA target from SOW | F13: Yes | G13: Integer | H13: 1-480 | I13: Public | J13: Operations | M13: 2025-06-01

Sheet Monitoring
A1: Monitoring Parameters
A2: Parameter Name | B2: Production | C2: Test | D2: DR | E2: Description | F2: Required | G2: Data Type | H2: Validation Rules | I2: Security Level | J2: Owner Team | K2: Dependencies | L2: Notes | M2: Last Updated
A3: monitoring.cloudwatch_dashboard_name | B3: eofw-prd-health | C3: eofw-dev-health | D3: eofw-prd-health | E3: CloudWatch dashboard name for real-time Lambda / DynamoDB / Bedrock operational visibility | F3: Yes | G3: String | H3: Non-empty string max 255 chars | I3: Public | J3: Operations | K3: solution.region.primary | M3: 2025-06-01
A4: monitoring.log_retention_lambda_days | B4: 90 | C4: 30 | D4: 90 | E4: CloudWatch Log Group retention in days for the 17 Lambda function log groups | F4: Yes | G4: Integer | H4: 1-3653 | I4: Public | J4: Operations | L4: Production uses 90 days per SOW data architecture; shorter in dev to control cost | M4: 2025-06-01
A5: monitoring.log_retention_cloudtrail_days | B5: 365 | C5: 90 | D5: 365 | E5: CloudWatch Logs retention for CloudTrail delivery to CloudWatch Logs group | F5: Yes | G5: Integer | H5: 1-3653 | I5: Public | J5: Security Team | K5: security.cloudtrail.management_events | L5: 365 days required for SOC 2 evidence window | M5: 2025-06-01
A6: monitoring.xray_sampling_rate | B6: 0.05 | C6: 1.0 | D6: 0.05 | E6: X-Ray trace sampling rate; 5% in production / 100% in dev for full distributed tracing | F6: Yes | G6: Number | H6: 0.0-1.0 | I6: Public | J6: Operations | K6: compute.lambda.xray_tracing | L6: Configurable post-launch; increase to 0.10 during Phase 3 load test investigation | M6: 2025-06-01
A7: monitoring.alert_sns_topic_arn | B7: [sns-ops-alerts-arn] | C7: [sns-ops-alerts-arn] | D7: [sns-ops-alerts-arn] | E7: SNS topic ARN for all CloudWatch Alarms; email subscriptions for Daniel Park and ops on-call | F7: Yes | G7: String | H7: Valid SNS ARN | I7: Confidential | J7: Operations | K7: solution.region.primary | L7: Routes Lambda error rate / Bedrock throttle / DLQ / quota threshold alarms | M7: 2025-06-01
A8: monitoring.alarm_lambda_error_rate_pct | B8: 1 | C8: 5 | D8: 1 | E8: Lambda error rate alarm threshold as a percentage; triggers P2 alert to ops team | F8: Yes | G8: Number | H8: 0.1-100.0 | I8: Public | J8: Operations | K8: monitoring.alert_sns_topic_arn | L8: Escalate to P1 if sustained > 15 minutes per alert definitions in detailed design | M8: 2025-06-01
A9: monitoring.alarm_bedrock_throttle_count | B9: 5 | C9: 20 | D9: 5 | E9: Bedrock ThrottlingException count per 5-minute window before alarm fires | F9: Yes | G9: Integer | H9: 1-1000 | I9: Public | J9: Operations | K9: monitoring.alert_sns_topic_arn | L9: Triggers SNS notification; investigate token throughput and request quota increase if sustained | M9: 2025-06-01
A10: monitoring.alarm_global_quota_threshold_pct | B10: 90 | C10: 90 | D10: 90 | E10: Percentage of global monthly quota (1000 solutions) that triggers P3 warning alarm | F10: Yes | G10: Integer | H10: 1-100 | I10: Public | J10: Operations | K10: monitoring.alert_sns_topic_arn, database.quota_global_monthly | L10: Fires at 900/1000 solutions; notify Admin to evaluate quota increase | M10: 2025-06-01
A11: monitoring.canary_health_check_interval_minutes | B11: 5 | C11: 5 | D11: 5 | E11: CloudWatch Synthetics canary polling interval in minutes for /api/v1/health route | F11: Yes | G11: Integer | H11: 1-60 | I11: Public | J11: Operations | K11: networking.apigw_endpoint | L11: P1 alarm fires on 2 consecutive canary failures; immediate escalation required | M11: 2025-06-01
A12: monitoring.api_gateway_p99_latency_ms | B12: 3000 | C12: 3000 | D12: 3000 | E12: API Gateway P99 latency SLA target in milliseconds for synchronous routes per SOW | F12: Yes | G12: Integer | H12: 100-30000 | I12: Public | J12: Operations | K12: networking.apigw_endpoint | L12: CloudWatch metric alarm configured against this threshold | M12: 2025-06-01
A13: monitoring.bedrock_cost_per_solution_alert_usd | B13: 5.00 | C13: 5.00 | D13: 5.00 | E13: Alert threshold for estimated per-solution Bedrock cost in USD; matches SOW success metric | F13: Yes | G13: Number | H13: 0.01-100.00 | I13: Public | J13: Operations | K13: monitoring.alert_sns_topic_arn, bedrock.cost_per_solution_target_usd | M13: 2025-06-01

Sheet Bedrock
A1: Bedrock Parameters
A2: Parameter Name | B2: Production | C2: Test | D2: DR | E2: Description | F2: Required | G2: Data Type | H2: Validation Rules | I2: Security Level | J2: Owner Team | K2: Dependencies | L2: Notes | M2: Last Updated
A3: bedrock.primary_model_id | B3: anthropic.claude-sonnet-4-5 | C3: anthropic.claude-sonnet-4-5 | D3: anthropic.claude-sonnet-4-5 | E3: Claude Sonnet 4.6 model ID used by Pre-Sales / Delivery / Code Generator agents for artifact generation | F3: Yes | G3: String | H3: Valid Bedrock model ID | I3: Confidential | J3: Development | K3: bedrock.agentcore.runtime_region | L3: Primary generation model; targets < $5 per solution at 200 solutions/month | M3: 2025-06-01
A4: bedrock.validator_model_id | B4: anthropic.claude-haiku-4-5 | C4: anthropic.claude-haiku-4-5 | D4: anthropic.claude-haiku-4-5 | E4: Claude Haiku 4.5 model ID used by EO Validator agent for cost-efficient quality scoring | F4: Yes | G4: String | H4: Valid Bedrock model ID | I4: Confidential | J4: Development | K4: bedrock.agentcore.runtime_region | L4: Haiku chosen to reduce validation cost vs Sonnet per infrastructure cost model | M4: 2025-06-01
A5: bedrock.agentcore.runtime_region | B5: us-west-2 | C5: us-west-2 | D5: us-west-2 | E5: AWS region where Bedrock AgentCore Runtime hosts the five Strands agents | F5: Yes | G5: String | H5: Valid AWS region code | I5: Public | J5: Development | K5: solution.region.primary | L5: Must be GA in us-west-2 before Phase 2 start per SOW assumption A8; validate in Week 1 spike | M5: 2025-06-01
A6: bedrock.input_tokens_monthly_sonnet | B6: 3000000 | C6: 500000 | D6: 3000000 | E6: Target Bedrock Sonnet 4.6 input token volume per month at PoC steady state (~50 solutions/month) | F6: Yes | G6: Integer | H6: 1-1000000000 | I6: Public | J6: Operations | K6: bedrock.primary_model_id | L6: Sourced from SOW Scope Parameters; quota pre-approval via AWS Solutions Architect required | M6: 2025-06-01
A7: bedrock.output_tokens_monthly_sonnet | B7: 1000000 | C7: 100000 | D7: 1000000 | E7: Target Bedrock Sonnet 4.6 output token volume per month at PoC steady state | F7: Yes | G7: Integer | H7: 1-1000000000 | I7: Public | J7: Operations | K7: bedrock.primary_model_id | L7: Monitor in CloudWatch; alert if trending above cost model projection | M7: 2025-06-01
A8: bedrock.cost_per_solution_target_usd | B8: 5.00 | C8: 5.00 | D8: 5.00 | E8: Maximum acceptable Bedrock model spend per 12-artifact solution bundle per SOW success metric | F8: Yes | G8: Number | H8: 0.01-100.00 | I8: Public | J8: Operations | K8: bedrock.primary_model_id | L8: Validated in Phase 3 load test at 200 solutions/month | M8: 2025-06-01

Sheet Integration
A1: Integration Parameters
A2: Parameter Name | B2: Production | C2: Test | D2: DR | E2: Description | F2: Required | G2: Data Type | H2: Validation Rules | I2: Security Level | J2: Owner Team | K2: Dependencies | L2: Notes | M2: Last Updated
A3: integration.github.repository_url | B3: [github-repo-url] | C3: [github-repo-url] | D3: [github-repo-url] | E3: GitHub repository URL for automated PAT-based artifact commit pipeline per SOW deliverable D13 | F3: Yes | G3: String | H3: Valid HTTPS GitHub URL | I3: Confidential | J3: Integration Team | K3: integration.github.secret_arn | L3: Provisioned by Marcus Patel before Week 5 per SOW dependency table | M3: 2025-06-01
A4: integration.github.secret_arn | B4: [secrets-manager-arn-github-pat] | C4: [secrets-manager-arn-github-pat] | D4: [secrets-manager-arn-github-pat] | E4: Secrets Manager ARN storing the GitHub PAT with repo-write scope | F4: Yes | G4: String | H4: Valid Secrets Manager ARN | I4: Secret | J4: Security Team | K4: integration.github.repository_url | L4: 90-day automatic rotation; PAT retrieved at runtime; never logged or baked into image | M4: 2025-06-01
A5: integration.github.pat_rotation_days | B5: 90 | C5: 90 | D5: 90 | E5: GitHub PAT rotation period in days matching Secrets Manager automatic rotation schedule | F5: Yes | G5: Integer | H5: 1-365 | I5: Public | J5: Security Team | K5: integration.github.secret_arn | L5: PAT expiry alarm configured in CloudWatch; DLQ for failed commits | M5: 2025-06-01
A6: integration.github.push_retry_count | B6: 3 | C6: 3 | D6: 3 | E6: Maximum GitHub API push retry attempts before writing to SQS DLQ for failed commits | F6: Yes | G6: Integer | H6: 1-10 | I6: Public | J6: Integration Team | K6: integration.github.secret_arn | L6: CloudWatch alarm fires on DLQ depth > 0; SNS notification to Daniel Park | M6: 2025-06-01
A7: integration.github.commit_message_format | B7: {solution_id}/{artifact_type}: generated by EO Validator — {status} | C7: {solution_id}/{artifact_type}: generated by EO Validator — {status} | D7: {solution_id}/{artifact_type}: generated by EO Validator — {status} | E7: Structured commit message format creating immutable delivery audit trail in GitHub history | F7: Yes | G7: String | H7: Must include solution_id and artifact_type tokens | I7: Public | J7: Integration Team | K7: integration.github.repository_url | M7: 2025-06-01
A8: integration.github.dlq_name | B8: eofw-prd-sqs-github-dlq | C8: eofw-dev-sqs-github-dlq | D8: eofw-prd-sqs-github-dlq | E8: SQS FIFO DLQ name for failed GitHub push messages after retry exhaustion | F8: Yes | G8: String | H8: Valid SQS queue name ending in .fifo | I8: Confidential | J8: Integration Team | K8: integration.github.push_retry_count | M8: 2025-06-01

Sheet Operations
A1: Operations Parameters
A2: Parameter Name | B2: Production | C2: Test | D2: DR | E2: Description | F2: Required | G2: Data Type | H2: Validation Rules | I2: Security Level | J2: Owner Team | K2: Dependencies | L2: Notes | M2: Last Updated
A3: operations.backup_enabled | B3: true | C3: true | D3: true | E3: Enable automated DynamoDB PITR and S3 versioning backups across all environments | F3: Yes | G3: Boolean | H3: true | false | I3: Public | J3: Operations | K3: database.pitr_enabled | M3: 2025-06-01
A4: operations.rto_hours | B4: 4 | C4: 4 | D4: 4 | E4: Recovery Time Objective in hours; validated by DynamoDB PITR restore test in Phase 3 | F4: Yes | G4: Integer | H4: 1-72 | I4: Public | J4: Operations | K4: database.pitr_enabled | L4: PITR restore test performed in staging during Phase 3 to validate this target | M4: 2025-06-01
