Workbook

Sheet Cover
B3: Discovery Questionnaire
B5: Generated: | C5: June 29, 2026
B6: Solution: | C6: Tmp2Vuewb8H
B7: Customer: | C7: [Customer Name]
B8: Version: | C8: 1.0
B9: Status: | C9: Draft
C12: eoframework.org

Sheet All Categories (Read Only)
A1: Total Questions | B1: Answered | C1: Remaining | D1: % Complete
A2: 62 | B2: =SUMPRODUCT(--(LEN(F5:F66)>0)) | C2: =A2-B2 | D2: =B2/A2
A4: Question ID | B4: Category | C4: Sub-Category | D4: Question | E4: Guidance | F4: Customer Response | G4: Notes
A5: =IF('Business Requirements'!A2="","",'Business Requirements'!A2) | B5: =IF('Business Requirements'!B2="","",'Business Requirements'!B2) | C5: =IF('Business Requirements'!C2="","",'Business Requirements'!C2) | D5: =IF('Business Requirements'!D2="","",'Business Requirements'!D2) | E5: =IF('Business Requirements'!E2="","",'Business Requirements'!E2) | F5: =IF('Business Requirements'!F2="","",'Business Requirements'!F2) | G5: =IF('Business Requirements'!G2="","",'Business Requirements'!G2)
A6: =IF('Business Requirements'!A3="","",'Business Requirements'!A3) | B6: =IF('Business Requirements'!B3="","",'Business Requirements'!B3) | C6: =IF('Business Requirements'!C3="","",'Business Requirements'!C3) | D6: =IF('Business Requirements'!D3="","",'Business Requirements'!D3) | E6: =IF('Business Requirements'!E3="","",'Business Requirements'!E3) | F6: =IF('Business Requirements'!F3="","",'Business Requirements'!F3) | G6: =IF('Business Requirements'!G3="","",'Business Requirements'!G3)
A7: =IF('Business Requirements'!A4="","",'Business Requirements'!A4) | B7: =IF('Business Requirements'!B4="","",'Business Requirements'!B4) | C7: =IF('Business Requirements'!C4="","",'Business Requirements'!C4) | D7: =IF('Business Requirements'!D4="","",'Business Requirements'!D4) | E7: =IF('Business Requirements'!E4="","",'Business Requirements'!E4) | F7: =IF('Business Requirements'!F4="","",'Business Requirements'!F4) | G7: =IF('Business Requirements'!G4="","",'Business Requirements'!G4)
A8: =IF('Business Requirements'!A5="","",'Business Requirements'!A5) | B8: =IF('Business Requirements'!B5="","",'Business Requirements'!B5) | C8: =IF('Business Requirements'!C5="","",'Business Requirements'!C5) | D8: =IF('Business Requirements'!D5="","",'Business Requirements'!D5) | E8: =IF('Business Requirements'!E5="","",'Business Requirements'!E5) | F8: =IF('Business Requirements'!F5="","",'Business Requirements'!F5) | G8: =IF('Business Requirements'!G5="","",'Business Requirements'!G5)
A9: =IF('Business Requirements'!A6="","",'Business Requirements'!A6) | B9: =IF('Business Requirements'!B6="","",'Business Requirements'!B6) | C9: =IF('Business Requirements'!C6="","",'Business Requirements'!C6) | D9: =IF('Business Requirements'!D6="","",'Business Requirements'!D6) | E9: =IF('Business Requirements'!E6="","",'Business Requirements'!E6) | F9: =IF('Business Requirements'!F6="","",'Business Requirements'!F6) | G9: =IF('Business Requirements'!G6="","",'Business Requirements'!G6)
A10: =IF('Business Requirements'!A7="","",'Business Requirements'!A7) | B10: =IF('Business Requirements'!B7="","",'Business Requirements'!B7) | C10: =IF('Business Requirements'!C7="","",'Business Requirements'!C7) | D10: =IF('Business Requirements'!D7="","",'Business Requirements'!D7) | E10: =IF('Business Requirements'!E7="","",'Business Requirements'!E7) | F10: =IF('Business Requirements'!F7="","",'Business Requirements'!F7) | G10: =IF('Business Requirements'!G7="","",'Business Requirements'!G7)
A11: =IF('Business Requirements'!A8="","",'Business Requirements'!A8) | B11: =IF('Business Requirements'!B8="","",'Business Requirements'!B8) | C11: =IF('Business Requirements'!C8="","",'Business Requirements'!C8) | D11: =IF('Business Requirements'!D8="","",'Business Requirements'!D8) | E11: =IF('Business Requirements'!E8="","",'Business Requirements'!E8) | F11: =IF('Business Requirements'!F8="","",'Business Requirements'!F8) | G11: =IF('Business Requirements'!G8="","",'Business Requirements'!G8)
A12: =IF('Business Requirements'!A9="","",'Business Requirements'!A9) | B12: =IF('Business Requirements'!B9="","",'Business Requirements'!B9) | C12: =IF('Business Requirements'!C9="","",'Business Requirements'!C9) | D12: =IF('Business Requirements'!D9="","",'Business Requirements'!D9) | E12: =IF('Business Requirements'!E9="","",'Business Requirements'!E9) | F12: =IF('Business Requirements'!F9="","",'Business Requirements'!F9) | G12: =IF('Business Requirements'!G9="","",'Business Requirements'!G9)
A13: =IF('Business Requirements'!A10="","",'Business Requirements'!A10) | B13: =IF('Business Requirements'!B10="","",'Business Requirements'!B10) | C13: =IF('Business Requirements'!C10="","",'Business Requirements'!C10) | D13: =IF('Business Requirements'!D10="","",'Business Requirements'!D10) | E13: =IF('Business Requirements'!E10="","",'Business Requirements'!E10) | F13: =IF('Business Requirements'!F10="","",'Business Requirements'!F10) | G13: =IF('Business Requirements'!G10="","",'Business Requirements'!G10)
A14: =IF('Business Requirements'!A11="","",'Business Requirements'!A11) | B14: =IF('Business Requirements'!B11="","",'Business Requirements'!B11) | C14: =IF('Business Requirements'!C11="","",'Business Requirements'!C11) | D14: =IF('Business Requirements'!D11="","",'Business Requirements'!D11) | E14: =IF('Business Requirements'!E11="","",'Business Requirements'!E11) | F14: =IF('Business Requirements'!F11="","",'Business Requirements'!F11) | G14: =IF('Business Requirements'!G11="","",'Business Requirements'!G11)
A15: =IF('Technical Requirements'!A2="","",'Technical Requirements'!A2) | B15: =IF('Technical Requirements'!B2="","",'Technical Requirements'!B2) | C15: =IF('Technical Requirements'!C2="","",'Technical Requirements'!C2) | D15: =IF('Technical Requirements'!D2="","",'Technical Requirements'!D2) | E15: =IF('Technical Requirements'!E2="","",'Technical Requirements'!E2) | F15: =IF('Technical Requirements'!F2="","",'Technical Requirements'!F2) | G15: =IF('Technical Requirements'!G2="","",'Technical Requirements'!G2)
A16: =IF('Technical Requirements'!A3="","",'Technical Requirements'!A3) | B16: =IF('Technical Requirements'!B3="","",'Technical Requirements'!B3) | C16: =IF('Technical Requirements'!C3="","",'Technical Requirements'!C3) | D16: =IF('Technical Requirements'!D3="","",'Technical Requirements'!D3) | E16: =IF('Technical Requirements'!E3="","",'Technical Requirements'!E3) | F16: =IF('Technical Requirements'!F3="","",'Technical Requirements'!F3) | G16: =IF('Technical Requirements'!G3="","",'Technical Requirements'!G3)
A17: =IF('Technical Requirements'!A4="","",'Technical Requirements'!A4) | B17: =IF('Technical Requirements'!B4="","",'Technical Requirements'!B4) | C17: =IF('Technical Requirements'!C4="","",'Technical Requirements'!C4) | D17: =IF('Technical Requirements'!D4="","",'Technical Requirements'!D4) | E17: =IF('Technical Requirements'!E4="","",'Technical Requirements'!E4) | F17: =IF('Technical Requirements'!F4="","",'Technical Requirements'!F4) | G17: =IF('Technical Requirements'!G4="","",'Technical Requirements'!G4)
A18: =IF('Technical Requirements'!A5="","",'Technical Requirements'!A5) | B18: =IF('Technical Requirements'!B5="","",'Technical Requirements'!B5) | C18: =IF('Technical Requirements'!C5="","",'Technical Requirements'!C5) | D18: =IF('Technical Requirements'!D5="","",'Technical Requirements'!D5) | E18: =IF('Technical Requirements'!E5="","",'Technical Requirements'!E5) | F18: =IF('Technical Requirements'!F5="","",'Technical Requirements'!F5) | G18: =IF('Technical Requirements'!G5="","",'Technical Requirements'!G5)
A19: =IF('Technical Requirements'!A6="","",'Technical Requirements'!A6) | B19: =IF('Technical Requirements'!B6="","",'Technical Requirements'!B6) | C19: =IF('Technical Requirements'!C6="","",'Technical Requirements'!C6) | D19: =IF('Technical Requirements'!D6="","",'Technical Requirements'!D6) | E19: =IF('Technical Requirements'!E6="","",'Technical Requirements'!E6) | F19: =IF('Technical Requirements'!F6="","",'Technical Requirements'!F6) | G19: =IF('Technical Requirements'!G6="","",'Technical Requirements'!G6)
A20: =IF('Technical Requirements'!A7="","",'Technical Requirements'!A7) | B20: =IF('Technical Requirements'!B7="","",'Technical Requirements'!B7) | C20: =IF('Technical Requirements'!C7="","",'Technical Requirements'!C7) | D20: =IF('Technical Requirements'!D7="","",'Technical Requirements'!D7) | E20: =IF('Technical Requirements'!E7="","",'Technical Requirements'!E7) | F20: =IF('Technical Requirements'!F7="","",'Technical Requirements'!F7) | G20: =IF('Technical Requirements'!G7="","",'Technical Requirements'!G7)
A21: =IF('Technical Requirements'!A8="","",'Technical Requirements'!A8) | B21: =IF('Technical Requirements'!B8="","",'Technical Requirements'!B8) | C21: =IF('Technical Requirements'!C8="","",'Technical Requirements'!C8) | D21: =IF('Technical Requirements'!D8="","",'Technical Requirements'!D8) | E21: =IF('Technical Requirements'!E8="","",'Technical Requirements'!E8) | F21: =IF('Technical Requirements'!F8="","",'Technical Requirements'!F8) | G21: =IF('Technical Requirements'!G8="","",'Technical Requirements'!G8)
A22: =IF('Technical Requirements'!A9="","",'Technical Requirements'!A9) | B22: =IF('Technical Requirements'!B9="","",'Technical Requirements'!B9) | C22: =IF('Technical Requirements'!C9="","",'Technical Requirements'!C9) | D22: =IF('Technical Requirements'!D9="","",'Technical Requirements'!D9) | E22: =IF('Technical Requirements'!E9="","",'Technical Requirements'!E9) | F22: =IF('Technical Requirements'!F9="","",'Technical Requirements'!F9) | G22: =IF('Technical Requirements'!G9="","",'Technical Requirements'!G9)
A23: =IF('Technical Requirements'!A10="","",'Technical Requirements'!A10) | B23: =IF('Technical Requirements'!B10="","",'Technical Requirements'!B10) | C23: =IF('Technical Requirements'!C10="","",'Technical Requirements'!C10) | D23: =IF('Technical Requirements'!D10="","",'Technical Requirements'!D10) | E23: =IF('Technical Requirements'!E10="","",'Technical Requirements'!E10) | F23: =IF('Technical Requirements'!F10="","",'Technical Requirements'!F10) | G23: =IF('Technical Requirements'!G10="","",'Technical Requirements'!G10)
A24: =IF('Technical Requirements'!A11="","",'Technical Requirements'!A11) | B24: =IF('Technical Requirements'!B11="","",'Technical Requirements'!B11) | C24: =IF('Technical Requirements'!C11="","",'Technical Requirements'!C11) | D24: =IF('Technical Requirements'!D11="","",'Technical Requirements'!D11) | E24: =IF('Technical Requirements'!E11="","",'Technical Requirements'!E11) | F24: =IF('Technical Requirements'!F11="","",'Technical Requirements'!F11) | G24: =IF('Technical Requirements'!G11="","",'Technical Requirements'!G11)
A25: =IF('Technical Requirements'!A12="","",'Technical Requirements'!A12) | B25: =IF('Technical Requirements'!B12="","",'Technical Requirements'!B12) | C25: =IF('Technical Requirements'!C12="","",'Technical Requirements'!C12) | D25: =IF('Technical Requirements'!D12="","",'Technical Requirements'!D12) | E25: =IF('Technical Requirements'!E12="","",'Technical Requirements'!E12) | F25: =IF('Technical Requirements'!F12="","",'Technical Requirements'!F12) | G25: =IF('Technical Requirements'!G12="","",'Technical Requirements'!G12)
A26: =IF('Technical Requirements'!A13="","",'Technical Requirements'!A13) | B26: =IF('Technical Requirements'!B13="","",'Technical Requirements'!B13) | C26: =IF('Technical Requirements'!C13="","",'Technical Requirements'!C13) | D26: =IF('Technical Requirements'!D13="","",'Technical Requirements'!D13) | E26: =IF('Technical Requirements'!E13="","",'Technical Requirements'!E13) | F26: =IF('Technical Requirements'!F13="","",'Technical Requirements'!F13) | G26: =IF('Technical Requirements'!G13="","",'Technical Requirements'!G13)
... A34: =IF('Technical Requirements'!A21="","",'Technical Requirements'!A21) | B34: =IF('Technical Requirements'!B21="","",'Technical Requirements'!B21) | C34: =IF('Technical Requirements'!C21="","",'Technical Requirements'!C21) | D34: =IF('Technical Requirements'!D21="","",'Technical Requirements'!D21) | E34: =IF('Technical Requirements'!E21="","",'Technical Requirements'!E21) | F34: =IF('Technical Requirements'!F21="","",'Technical Requirements'!F21) | G34: =IF('Technical Requirements'!G21="","",'Technical Requirements'!G21)
A35: =IF('Security & Compliance'!A2="","",'Security & Compliance'!A2) | B35: =IF('Security & Compliance'!B2="","",'Security & Compliance'!B2) | C35: =IF('Security & Compliance'!C2="","",'Security & Compliance'!C2) | D35: =IF('Security & Compliance'!D2="","",'Security & Compliance'!D2) | E35: =IF('Security & Compliance'!E2="","",'Security & Compliance'!E2) | F35: =IF('Security & Compliance'!F2="","",'Security & Compliance'!F2) | G35: =IF('Security & Compliance'!G2="","",'Security & Compliance'!G2)
A36: =IF('Security & Compliance'!A3="","",'Security & Compliance'!A3) | B36: =IF('Security & Compliance'!B3="","",'Security & Compliance'!B3) | C36: =IF('Security & Compliance'!C3="","",'Security & Compliance'!C3) | D36: =IF('Security & Compliance'!D3="","",'Security & Compliance'!D3) | E36: =IF('Security & Compliance'!E3="","",'Security & Compliance'!E3) | F36: =IF('Security & Compliance'!F3="","",'Security & Compliance'!F3) | G36: =IF('Security & Compliance'!G3="","",'Security & Compliance'!G3)
A37: =IF('Security & Compliance'!A4="","",'Security & Compliance'!A4) | B37: =IF('Security & Compliance'!B4="","",'Security & Compliance'!B4) | C37: =IF('Security & Compliance'!C4="","",'Security & Compliance'!C4) | D37: =IF('Security & Compliance'!D4="","",'Security & Compliance'!D4) | E37: =IF('Security & Compliance'!E4="","",'Security & Compliance'!E4) | F37: =IF('Security & Compliance'!F4="","",'Security & Compliance'!F4) | G37: =IF('Security & Compliance'!G4="","",'Security & Compliance'!G4)
A38: =IF('Security & Compliance'!A5="","",'Security & Compliance'!A5) | B38: =IF('Security & Compliance'!B5="","",'Security & Compliance'!B5) | C38: =IF('Security & Compliance'!C5="","",'Security & Compliance'!C5) | D38: =IF('Security & Compliance'!D5="","",'Security & Compliance'!D5) | E38: =IF('Security & Compliance'!E5="","",'Security & Compliance'!E5) | F38: =IF('Security & Compliance'!F5="","",'Security & Compliance'!F5) | G38: =IF('Security & Compliance'!G5="","",'Security & Compliance'!G5)
A39: =IF('Security & Compliance'!A6="","",'Security & Compliance'!A6) | B39: =IF('Security & Compliance'!B6="","",'Security & Compliance'!B6) | C39: =IF('Security & Compliance'!C6="","",'Security & Compliance'!C6) | D39: =IF('Security & Compliance'!D6="","",'Security & Compliance'!D6) | E39: =IF('Security & Compliance'!E6="","",'Security & Compliance'!E6) | F39: =IF('Security & Compliance'!F6="","",'Security & Compliance'!F6) | G39: =IF('Security & Compliance'!G6="","",'Security & Compliance'!G6)
A40: =IF('Security & Compliance'!A7="","",'Security & Compliance'!A7) | B40: =IF('Security & Compliance'!B7="","",'Security & Compliance'!B7) | C40: =IF('Security & Compliance'!C7="","",'Security & Compliance'!C7) | D40: =IF('Security & Compliance'!D7="","",'Security & Compliance'!D7) | E40: =IF('Security & Compliance'!E7="","",'Security & Compliance'!E7) | F40: =IF('Security & Compliance'!F7="","",'Security & Compliance'!F7) | G40: =IF('Security & Compliance'!G7="","",'Security & Compliance'!G7)
A41: =IF('Security & Compliance'!A8="","",'Security & Compliance'!A8) | B41: =IF('Security & Compliance'!B8="","",'Security & Compliance'!B8) | C41: =IF('Security & Compliance'!C8="","",'Security & Compliance'!C8) | D41: =IF('Security & Compliance'!D8="","",'Security & Compliance'!D8) | E41: =IF('Security & Compliance'!E8="","",'Security & Compliance'!E8) | F41: =IF('Security & Compliance'!F8="","",'Security & Compliance'!F8) | G41: =IF('Security & Compliance'!G8="","",'Security & Compliance'!G8)
A42: =IF('Security & Compliance'!A9="","",'Security & Compliance'!A9) | B42: =IF('Security & Compliance'!B9="","",'Security & Compliance'!B9) | C42: =IF('Security & Compliance'!C9="","",'Security & Compliance'!C9) | D42: =IF('Security & Compliance'!D9="","",'Security & Compliance'!D9) | E42: =IF('Security & Compliance'!E9="","",'Security & Compliance'!E9) | F42: =IF('Security & Compliance'!F9="","",'Security & Compliance'!F9) | G42: =IF('Security & Compliance'!G9="","",'Security & Compliance'!G9)
A43: =IF('Security & Compliance'!A10="","",'Security & Compliance'!A10) | B43: =IF('Security & Compliance'!B10="","",'Security & Compliance'!B10) | C43: =IF('Security & Compliance'!C10="","",'Security & Compliance'!C10) | D43: =IF('Security & Compliance'!D10="","",'Security & Compliance'!D10) | E43: =IF('Security & Compliance'!E10="","",'Security & Compliance'!E10) | F43: =IF('Security & Compliance'!F10="","",'Security & Compliance'!F10) | G43: =IF('Security & Compliance'!G10="","",'Security & Compliance'!G10)
A44: =IF('Security & Compliance'!A11="","",'Security & Compliance'!A11) | B44: =IF('Security & Compliance'!B11="","",'Security & Compliance'!B11) | C44: =IF('Security & Compliance'!C11="","",'Security & Compliance'!C11) | D44: =IF('Security & Compliance'!D11="","",'Security & Compliance'!D11) | E44: =IF('Security & Compliance'!E11="","",'Security & Compliance'!E11) | F44: =IF('Security & Compliance'!F11="","",'Security & Compliance'!F11) | G44: =IF('Security & Compliance'!G11="","",'Security & Compliance'!G11)
A45: =IF('Security & Compliance'!A12="","",'Security & Compliance'!A12) | B45: =IF('Security & Compliance'!B12="","",'Security & Compliance'!B12) | C45: =IF('Security & Compliance'!C12="","",'Security & Compliance'!C12) | D45: =IF('Security & Compliance'!D12="","",'Security & Compliance'!D12) | E45: =IF('Security & Compliance'!E12="","",'Security & Compliance'!E12) | F45: =IF('Security & Compliance'!F12="","",'Security & Compliance'!F12) | G45: =IF('Security & Compliance'!G12="","",'Security & Compliance'!G12)
A46: =IF('Implementation Planning'!A2="","",'Implementation Planning'!A2) | B46: =IF('Implementation Planning'!B2="","",'Implementation Planning'!B2) | C46: =IF('Implementation Planning'!C2="","",'Implementation Planning'!C2) | D46: =IF('Implementation Planning'!D2="","",'Implementation Planning'!D2) | E46: =IF('Implementation Planning'!E2="","",'Implementation Planning'!E2) | F46: =IF('Implementation Planning'!F2="","",'Implementation Planning'!F2) | G46: =IF('Implementation Planning'!G2="","",'Implementation Planning'!G2)
A47: =IF('Implementation Planning'!A3="","",'Implementation Planning'!A3) | B47: =IF('Implementation Planning'!B3="","",'Implementation Planning'!B3) | C47: =IF('Implementation Planning'!C3="","",'Implementation Planning'!C3) | D47: =IF('Implementation Planning'!D3="","",'Implementation Planning'!D3) | E47: =IF('Implementation Planning'!E3="","",'Implementation Planning'!E3) | F47: =IF('Implementation Planning'!F3="","",'Implementation Planning'!F3) | G47: =IF('Implementation Planning'!G3="","",'Implementation Planning'!G3)
A48: =IF('Implementation Planning'!A4="","",'Implementation Planning'!A4) | B48: =IF('Implementation Planning'!B4="","",'Implementation Planning'!B4) | C48: =IF('Implementation Planning'!C4="","",'Implementation Planning'!C4) | D48: =IF('Implementation Planning'!D4="","",'Implementation Planning'!D4) | E48: =IF('Implementation Planning'!E4="","",'Implementation Planning'!E4) | F48: =IF('Implementation Planning'!F4="","",'Implementation Planning'!F4) | G48: =IF('Implementation Planning'!G4="","",'Implementation Planning'!G4)
...

Sheet Business Requirements
A1: Question ID | B1: Category | C1: Sub-Category | D1: Question | E1: Guidance | F1: Customer Response | G1: Notes
A2: BUS-001 | B2: Business Requirements | C2: Business Drivers | D2: What are the top 3–5 clinical and operational pain points driving the CDS platform initiative? | E2: Describe current gaps in sepsis detection, readmission prevention, and alert fatigue in detail | G2: Aligns technical solution with clinical and operational outcomes; drives feature prioritization
A3: BUS-002 | B3: Business Requirements | C3: Success Criteria | D3: How will you measure the success of the CDS platform across sepsis mortality, readmission rates, and alert fatigue? | E3: Quantify targets: e.g. 15% sepsis mortality reduction, 20% readmission reduction, 40% false-positive decrease | G3: Defines measurable KPIs required for project sign-off and ongoing model performance reviews
A4: BUS-003 | B4: Business Requirements | C4: Success Criteria | D4: What clinical staff adoption rate is acceptable within 90 days of go-live at each facility? | E4: Target is ≥75%; how will adoption be measured (logins, alert acknowledgements, workflow integration)? | G4: Adoption metrics drive change management plan and training scope
A5: BUS-004 | B5: Business Requirements | C5: Stakeholders | D5: Who are the key clinical and IT decision-makers and what are their sign-off authorities at each project phase? | E5: Identify CMO, CIO, Clinical Informatics Lead, CISO, EHR Integration Lead, and their approval roles | G5: Governance map needed to structure steering committee and escalation paths
A6: BUS-005 | B6: Business Requirements | C6: Business Drivers | D6: What specific clinical workflows (nursing, physician, rapid-response team) will be most affected by AI-generated alerts? | E6: Describe current alert consumption workflows across acute care, ICU, and ambulatory settings | G6: Workflow impact analysis drives UX design and alert routing architecture
A7: BUS-006 | B7: Business Requirements | C7: Timeline | D7: Is the Phase 1 (sepsis MVP) delivery date of 2026-10-31 a firm deadline, and what are the consequences if it slips past the Joint Commission review in November 2026? | E7: Confirm hard deadline and describe fallback plan if delivery is delayed | G7: Joint Commission review is a regulatory constraint; any timeline risk must be flagged immediately
A8: BUS-007 | B8: Business Requirements | C8: Budget | D8: Please confirm the approved budget range ($1.2M–$1.6M) and the breakdown between implementation services, AWS run costs, and licensing. | E8: Clarify CapEx vs. OpEx split, internal resource allocation, and contingency reserve | G8: Budget envelope drives design decisions on managed vs. self-managed services and model complexity
A9: BUS-008 | B9: Business Requirements | C9: Budget | D9: What is the approved monthly AWS steady-state budget range ($18K–$24K/month), and who holds approval authority for overages? | E9: Confirm budget owner and approval threshold for unexpected cost spikes | G9: Cost governance drives right-sizing decisions for SageMaker, Kinesis, HealthLake, and Bedrock
A10: BUS-009 | B10: Business Requirements | C10: Regulatory Drivers | D10: Beyond HIPAA and HITECH, are there any state-level healthcare data privacy regulations (e.g. Tennessee data breach law) or Joint Commission standards that must be addressed? | E10: List all regulatory frameworks that apply to PHI handling and clinical AI decision support | G10: Regulatory scope determines audit log design, PHI de-identification requirements, and model governance
A11: BUS-010 | B11: Business Requirements | C11: Stakeholders | D11: Has MedCore engaged its clinical ethics committee or patient safety board regarding AI-driven clinical alerts? | E11: Describe any internal governance reviews required before deploying AI risk scores at the bedside | G11: Clinical AI governance sign-off may add lead time; needs to be factored into Phase 1 timeline

Sheet Technical Requirements
A1: Question ID | B1: Category | C1: Sub-Category | D1: Question | E1: Guidance | F1: Customer Response | G1: Notes
A2: TECH-001 | B2: Technical Requirements | C2: Current Infrastructure | D2: Describe your current Epic EHR deployment — version, hosting model (Epic-hosted vs. on-premise), and which FHIR R4 API resources are currently enabled. | E2: Include Epic version, Interconnect configuration, and list of exposed FHIR R4 resource types (Observation, Patient, Encounter, MedicationRequest, etc.) | G2: Epic API capability directly determines which clinical data elements are available for model features
A3: TECH-002 | B3: Technical Requirements | C3: Current Infrastructure | D3: Describe your Mirth Connect integration engine deployment — version, current message volume (HL7 v2.3 messages/day), and existing outbound channel configurations. | E3: Include Mirth Connect version, server specs, and daily HL7 v2.3 message throughput from Philips and GE monitors | G3: Mirth Connect throughput and version determine the event-driven ingestion architecture into AWS
A4: TECH-003 | B4: Technical Requirements | C4: Data Sources | D4: What structured patient data elements are currently captured and available for model features (vitals, labs, medications, EHR events)? | E4: Provide a data dictionary or list: heart rate, blood pressure, temperature, WBC, creatinine, lactate, medication administration records, etc. | G4: Feature availability drives model architecture; missing data elements may require additional integration work
A5: TECH-004 | B5: Technical Requirements | C5: Data Sources | D5: How frequently are lab results, vitals, and medication administration records updated in Epic and bedside monitors? | E5: Specify update frequency per data type: e.g. vitals every 15 minutes, labs within 30 minutes of resulted, MAR on administration | G5: Data refresh cadence determines pipeline latency design and Kinesis stream partitioning
A6: TECH-005 | B6: Technical Requirements | C6: Data Volume | D6: What is the current and projected patient census across all 18 hospitals and 60+ clinics? | E6: Provide average daily census (ADC) per facility and total; include peak census periods (flu season, etc.) | G6: Patient census drives Kinesis shard count, SageMaker endpoint scaling, and HealthLake storage sizing
A7: TECH-006 | B7: Technical Requirements | C7: Data Volume | D7: Estimate the total daily volume of HL7 messages (v2.3 and FHIR R4) expected from all facilities once fully live. | E7: Include both real-time monitor streams and EHR event notifications; provide messages/hour at peak | G7: Message throughput determines Kinesis Data Streams capacity and Lambda concurrency limits
A8: TECH-007 | B8: Technical Requirements | C8: AI/ML Requirements | D8: What predictive models are in scope: sepsis risk, 30-day readmission, rapid response events — any others? | E8: Confirm the full model portfolio; specify whether models are binary classifiers, risk scores (0–100), or probability estimates | G8: Model portfolio determines SageMaker training jobs, endpoint count, and MLflow/model registry scope
A9: TECH-008 | B9: Technical Requirements | C9: AI/ML Requirements | D9: Does MedCore have existing ML models, clinical scoring algorithms (e.g. NEWS2, qSOFA), or training datasets that can seed the initial models? | E9: Describe any existing models, labeled datasets, or clinical scoring logic to be incorporated or replaced | G9: Existing assets can accelerate Phase 1 model development; absence requires full de-novo training pipeline
A10: TECH-009 | B10: Technical Requirements | C10: AI/ML Requirements | D10: What model explainability format is required for clinical staff — SHAP values, feature contribution lists, natural-language explanations, or all three? | E10: Describe how clinicians expect to see the explanation: bedside dashboard, EHR alert note, mobile push? | G10: Explainability output format drives Bedrock prompt design and SageMaker Clarify integration
A11: TECH-010 | B11: Technical Requirements | C11: AI/ML Requirements | D11: What minimum acceptable model accuracy/AUC is required before a model can be deployed to production? | E11: Specify AUC, sensitivity, specificity, PPV, NPV thresholds by model type (sepsis, readmission, rapid response) | G11: Model acceptance thresholds gate production deployment and define clinical validation process
A12: TECH-011 | B12: Technical Requirements | C12: LLM/Summarization | D12: Which AWS Bedrock foundation models are preferred or approved for generating clinical narrative summaries? | E12: e.g. Anthropic Claude 3, Amazon Titan — any model restrictions based on vendor security review? | G12: Bedrock model selection impacts token cost, latency, and summarization quality; vendor approval may be needed
A13: TECH-012 | B13: Technical Requirements | C13: EHR Integration | D13: What Epic integration method is preferred for writing alert notifications back into Epic — Smart-on-FHIR app, FHIR R4 write-back, HL7 v2.x ADT/ORU message, or Epic Secure Chat? | E13: Confirm with EHR Integration Lead; describe current Epic Interconnect capabilities for inbound messages | G13: Alert write-back method determines Phase 3 integration architecture and Epic configuration scope
... A21: TECH-020 | B21: Technical Requirements | C21: Identity & Access | D21: Confirm the Azure Active Directory tenant configuration for SAML 2.0 federation to Amazon Cognito — is AD FS or Azure AD Enterprise Application the preferred federation method? | E21: Specify Azure AD tenant ID, supported SAML claims (UPN, role, facility), and MFA enforcement policy | G21: SSO federation design determines Cognito User Pool configuration and RBAC attribute mapping

Sheet Security & Compliance
A1: Question ID | B1: Category | C1: Sub-Category | D1: Question | E1: Guidance | F1: Customer Response | G1: Notes
A2: SEC-001 | B2: Security & Compliance | C2: Compliance Frameworks | D2: Confirm which compliance frameworks formally apply to the CDS platform: HIPAA, HITECH, SOC 2 Type II — any others (HITRUST, NIST CSF, CMS)? | E2: List all frameworks requiring formal attestation or audit evidence; confirm SOC 2 Type II audit scope | G2: Framework scope determines control implementation effort and audit timeline; drives AWS Config rules and GuardDuty policies
A3: SEC-002 | B3: Security & Compliance | C3: PHI Data Handling | D3: What PHI data elements will be stored and processed by the CDS platform, and what is the required data retention period? | E3: List PHI fields: patient ID, name, DOB, MRN, vitals, labs, diagnoses, medications; specify retention (e.g. 7 years per HIPAA) | G3: PHI inventory is required for BAA scope, data classification, and HealthLake/S3 encryption key policy design
A4: SEC-003 | B4: Security & Compliance | C4: PHI Data Handling | D4: Is there a requirement to de-identify or pseudonymize PHI for model training datasets, or can identifiable PHI be used under BAA? | E4: Describe data de-identification policy: HIPAA Safe Harbor vs. Expert Determination method | G4: De-identification requirement impacts model training pipeline design and SageMaker training data preparation
A5: SEC-004 | B5: Security & Compliance | C5: Data Residency | D5: Confirm that all PHI must remain within US AWS regions at all times — are there any specific state-level data residency restrictions beyond federal HIPAA requirements? | E5: Specify allowed AWS regions; confirm no cross-border data transfer is permitted | G5: Data residency constraint enforces region-pinned S3 bucket policies and HealthLake configuration
A6: SEC-005 | B6: Security & Compliance | C6: Encryption | D6: What encryption standard is required for PHI at rest and in transit — AES-256, TLS 1.2+, and who manages the KMS keys (AWS-managed vs. customer-managed CMKs)? | E6: Specify KMS key management preference, key rotation policy, and who holds key administrator role | G6: KMS CMK design impacts operational complexity and compliance audit evidence for HIPAA encryption controls
A7: SEC-006 | B7: Security & Compliance | C7: Audit Logging | D7: What is the required format, retention period, and access control for the HIPAA-compliant PHI access audit log? | E7: Describe required log fields (who, what, when, from where), retention (minimum 6 years under HIPAA), and SIEM integration | G7: Audit log design drives CloudTrail, CloudWatch Logs, and optional SIEM (Splunk/Sentinel) integration scope
A8: SEC-007 | B8: Security & Compliance | C8: Authentication | D8: What MFA method is mandated for clinical staff accessing the CDS platform — TOTP, hardware token, or Azure AD Conditional Access MFA? | E8: Confirm MFA enforcement point: Azure AD Conditional Access before SAML assertion, or Cognito-level MFA | G8: MFA architecture determines Cognito configuration and Azure AD Conditional Access policy requirements
A9: SEC-008 | B9: Security & Compliance | C9: Authorization | D9: Define the required role-based access control model — what permissions does each role (nurse, physician, administrator, data scientist) have? | E9: Map roles to actions: view alerts, acknowledge alerts, view risk scores, access model performance dashboards, manage users | G9: RBAC model drives Cognito group policy, IAM role design, and API Gateway authorization layer
A10: SEC-009 | B10: Security & Compliance | C10: Network Security | D10: What network segmentation and perimeter controls are required between the AWS CDS platform and MedCore's on-premises Epic/Mirth Connect environment? | E10: Describe VPN or Direct Connect preference, firewall rules, and whether a WAF is required for internet-facing endpoints | G10: Network security controls determine AWS Transit Gateway, Site-to-Site VPN, and WAF configuration
A11: SEC-010 | B11: Security & Compliance | C11: Vulnerability Management | D11: What is MedCore's policy for patching and vulnerability scanning of AWS infrastructure — who owns this for the CDS platform? | E11: Clarify responsibility: Amatra manages during build; post-handover to MedCore IT or co-managed? | G11: Vulnerability management scope impacts project cost and determines whether Amazon Inspector is in scope
A12: SEC-011 | B12: Security & Compliance | C12: BAA Governance | D12: Has MedCore executed or is prepared to execute a BAA with AWS for the CDS platform account? | E12: Confirm BAA status with AWS; identify any additional vendor BAAs required (e.g. Bedrock third-party model providers) | G12: BAA must be in place before any PHI enters the AWS environment; blocks Phase 1 start if not resolved

Sheet Implementation Planning
A1: Question ID | B1: Category | C1: Sub-Category | D1: Question | E1: Guidance | F1: Customer Response | G1: Notes
A2: IMPL-001 | B2: Implementation Planning | C2: Migration Approach | D2: What is the preferred deployment approach for Phase 1 — greenfield build in the new dedicated AWS account, and what sign-off is needed from the IT landing zone team? | E2: Confirm greenfield deployment; identify AWS Organization account vending process and lead time | G2: Account provisioning lead time can affect Phase 1 schedule; must be initiated 4–6 weeks before build start
A3: IMPL-002 | B3: Implementation Planning | C3: Phased Rollout | D3: How many hospitals and clinics will be onboarded in each phase, and what is the criteria for graduating a facility from pilot to full production? | E3: Define facility selection criteria for Phase 1 pilot (e.g. 2 flagship hospitals), and graduation checklist | G3: Phased facility rollout determines integration effort per site and resource allocation across all three phases
A4: IMPL-003 | B4: Implementation Planning | C4: Downtime Tolerance | D4: What is the maximum acceptable downtime for EHR integration cutovers, and what maintenance windows are available? | E4: Specify allowed maintenance windows by facility type (acute care vs. ambulatory); confirm 99.95% availability target | G4: Downtime tolerance drives multi-AZ vs. multi-region active-active architecture and cutover runbook design
A5: IMPL-004 | B5: Implementation Planning | C5: Data Migration | D5: Does MedCore need to backfill historical patient data (vitals, labs, EHR events) into the platform for initial model training, and if so, what is the historical data volume and format? | E5: Estimate years of history required, data format (HL7, CSV, SQL export), and Epic data extract capability | G5: Historical backfill scope is a major implementation effort; impacts Phase 1 timeline and SageMaker training pipeline design
A6: IMPL-005 | B6: Implementation Planning | C6: Resource Availability | D6: Which MedCore internal teams (IT, Clinical Informatics, Epic Integration, CISO office) are available to support the build, and what is their estimated weekly time commitment? | E6: Identify named resources per team and their availability (FTE percentage, conflicting projects) | G6: Internal resource availability is a key project risk; under-resourced client teams frequently cause schedule slippage
A7: IMPL-006 | B7: Implementation Planning | C7: Training Needs | D7: What training is required for clinical staff, nursing managers, administrators, and IT operations personnel? | E7: Specify training modality preferences: in-person, virtual, train-the-trainer, LMS e-learning; estimate learner count per role | G7: Training scope and timeline are deliverables in Phase 3; must be designed 6–8 weeks before facility go-live
A8: IMPL-007 | B8: Implementation Planning | C8: UAT | D8: Who owns User Acceptance Testing for the CDS platform, and what is the minimum UAT duration before production go-live at each facility? | E8: Identify UAT lead (Clinical Informatics or Quality & Patient Safety), test case owners, and pass/fail criteria | G8: UAT process must be budgeted into Phase 2 and Phase 3 timelines; inadequate UAT is a top-3 go-live risk
A9: IMPL-008 | B9: Implementation Planning | C9: Change Management | D9: What change management and clinical communication plan exists for introducing AI-generated alerts to nursing and physician workflows? | E9: Describe existing change management resources (Organizational Change Management team, CMO communications) | G9: Clinical adoption (≥75% target) depends heavily on structured change management; absence is a project risk
A10: IMPL-009 | B10: Implementation Planning | C10: Go-Live Readiness | D10: What are the go-live readiness criteria for Phase 1 (sepsis model only) in advance of the November 2026 Joint Commission review? | E10: Define checklist: data pipeline validated, model AUC threshold met, alert workflow tested, audit logging verified, BAA confirmed | G10: Joint Commission readiness criteria must be documented and signed off by CISO and CMO before go-live

Sheet Operations & Support
A1: Question ID | B1: Category | C1: Sub-Category | D1: Question | E1: Guidance | F1: Customer Response | G1: Notes
A2: OPS-001 | B2: Operations & Support | C2: RTO | D2: What is the Recovery Time Objective (RTO) for the CDS platform in the event of a regional AWS outage? | E2: Specify RTO per component: ingestion pipeline, inference endpoints, clinical dashboard, alert delivery | G2: RTO drives multi-region active-active vs. active-passive design and Route 53 health-check failover configuration
A3: OPS-002 | B3: Operations & Support | C3: RPO | D3: What is the Recovery Point Objective (RPO) for patient risk score data and audit logs in the event of data loss? | E3: Maximum acceptable data loss in minutes; distinguish between real-time scores (low RPO) and historical analytics (higher RPO) | G3: RPO drives Kinesis Data Firehose backup frequency, HealthLake cross-region replication, and S3 versioning policy
A4: OPS-003 | B4: Operations & Support | C4: Monitoring | D4: What monitoring and alerting is required for the CDS platform — infrastructure, ML model performance, pipeline latency, and clinical alert delivery? | E4: Specify monitoring tools: Amazon CloudWatch, Grafana, Datadog, or MedCore's existing monitoring platform | G4: Monitoring scope determines CloudWatch dashboard design, SageMaker Model Monitor schedules, and PagerDuty integration
A5: OPS-004 | B5: Operations & Support | C5: Support Coverage | D5: What support coverage is required for the CDS platform post go-live — 24x7 for clinical alert delivery, business hours for model management? | E5: Specify SLA tiers by component: critical (alert pipeline) = 24x7; non-critical (analytics) = business hours | G5: Support coverage tiers drive Amatra managed services scope and escalation runbook design
A6: OPS-005 | B6: Operations & Support | C6: Capacity Planning | D6: How will capacity scaling be governed — AWS auto-scaling policies managed by MedCore IT, or delegated to Amatra under a managed services agreement? | E6: Describe internal AWS operations maturity; identify AWS-certified resources on MedCore's IT team | G6: Capacity governance model determines whether SageMaker endpoint auto-scaling and Kinesis scaling are self-managed or co-managed
A7: OPS-006 | B7: Operations & Support | C7: Backup & Recovery | D7: What is the backup policy for HealthLake patient data, SageMaker model artifacts, and the clinical audit log — frequency, retention, and tested restore cadence? | E7: Specify backup frequency per data type and required restore test schedule (e.g. quarterly DR drill) | G7: Backup policy drives AWS Backup configuration and compliance evidence for HIPAA contingency plan control
A8: OPS-007 | B8: Operations & Support | C8: Model Operations | D8: What process is required for ongoing model retraining, version management, and promotion from staging to production? | E8: Describe MLOps maturity: does MedCore have a data science team to own model retraining, or does Amatra manage post go-live? | G8: MLOps ownership model determines whether SageMaker Pipelines and MLflow are handed over or remain Amatra-managed
A9: OPS-008 | B9: Operations & Support | C9: Maintenance Windows | D9: What maintenance windows are available for infrastructure patching, model deployments, and Epic integration updates? | E9: Specify days and times; confirm whether 99.95% availability SLA excludes planned maintenance | G9: Maintenance windows must be formalized in the Operations Runbook and communicated to clinical leadership

Sheet Risk & Constraints
A1: Question ID | B1: Category | C1: Sub-Category | D1: Question | E1: Guidance | F1: Customer Response | G1: Notes
A2: RISK-001 | B2: Risk & Constraints | C2: Project Risks | D2: What is the risk if the Epic FHIR R4 API does not expose all required clinical data elements (e.g. lactate, culture results) in time for Phase 1? | E2: Describe Epic upgrade timeline and any pending API enablement requests with Epic support | G2: Missing EHR data elements are the highest technical risk to Phase 1 model accuracy; mitigation plan required
A3: RISK-002 | B3: Risk & Constraints | C3: Dependencies | D3: What third-party or vendor dependencies could delay the project — Epic configuration changes, Philips/GE monitor firmware updates, AWS service availability? | E3: List all vendor dependencies with lead times; identify single points of failure in the integration chain | G3: Vendor dependency mapping is required for Phase 1 risk register and Joint Commission deadline contingency plan
A4: RISK-003 | B4: Risk & Constraints | C4: Constraints | D4: Are there any AWS Service Control Policy restrictions in the existing Organization landing zone that could block required services (SageMaker, HealthLake, Bedrock, Kinesis)? | E4: Request a review of the Clinical Applications OU SCPs from the IT landing zone team before architecture finalization | G4: SCP conflicts must be resolved in the first two weeks of the project; late discovery is a schedule risk
A5: RISK-004 | B5: Risk & Constraints | C5: Assumptions | D5: Does MedCore assume that Amatra will manage all AWS infrastructure and MLOps tooling through general availability, or will a knowledge-transfer handover occur at Phase 3 completion? | E5: Clarify operating model post-GA: fully managed, co-managed, or full handover to MedCore IT | G5: Operating model assumption drives project budget, staffing, and managed services contract scope
