Workbook

Sheet Cover
B3: Configuration Parameters
B5: Generated: | C5: June 05, 2026
B6: Solution: | C6: Tmphvehf53R
B7: Customer: | C7: [Customer Name]
B8: Version: | C8: 1.0
B9: Status: | C9: Draft
C12: eoframework.org

Sheet All Parameters (Read Only)
A1: Total Parameters | B1: Categories | C1: Required | D1: Confidential/Secret
A2: 93 | B2: 10 | C2: 93 | D2: 31
A4: Parameter Name | B4: Category | C4: Production | D4: Test | E4: DR | F4: Description | G4: Required | H4: Data Type | I4: Validation Rules | J4: Security Level | K4: Owner Team | L4: Dependencies | M4: Notes | N4: Last Updated
A5: =IF('Project'!A3="","",'Project'!A3) | B5: Project | C5: =IF('Project'!B3="","",'Project'!B3) | D5: =IF('Project'!C3="","",'Project'!C3) | E5: =IF('Project'!D3="","",'Project'!D3) | F5: =IF('Project'!E3="","",'Project'!E3) | G5: =IF('Project'!F3="","",'Project'!F3) | H5: =IF('Project'!G3="","",'Project'!G3) | I5: =IF('Project'!H3="","",'Project'!H3) | J5: =IF('Project'!I3="","",'Project'!I3) | ... N5: =IF('Project'!M3="","",'Project'!M3)
A6: =IF('Project'!A4="","",'Project'!A4) | B6: Project | C6: =IF('Project'!B4="","",'Project'!B4) | D6: =IF('Project'!C4="","",'Project'!C4) | E6: =IF('Project'!D4="","",'Project'!D4) | F6: =IF('Project'!E4="","",'Project'!E4) | G6: =IF('Project'!F4="","",'Project'!F4) | H6: =IF('Project'!G4="","",'Project'!G4) | I6: =IF('Project'!H4="","",'Project'!H4) | J6: =IF('Project'!I4="","",'Project'!I4) | ... N6: =IF('Project'!M4="","",'Project'!M4)
A7: =IF('Project'!A5="","",'Project'!A5) | B7: Project | C7: =IF('Project'!B5="","",'Project'!B5) | D7: =IF('Project'!C5="","",'Project'!C5) | E7: =IF('Project'!D5="","",'Project'!D5) | F7: =IF('Project'!E5="","",'Project'!E5) | G7: =IF('Project'!F5="","",'Project'!F5) | H7: =IF('Project'!G5="","",'Project'!G5) | I7: =IF('Project'!H5="","",'Project'!H5) | J7: =IF('Project'!I5="","",'Project'!I5) | ... N7: =IF('Project'!M5="","",'Project'!M5)
A8: =IF('Project'!A6="","",'Project'!A6) | B8: Project | C8: =IF('Project'!B6="","",'Project'!B6) | D8: =IF('Project'!C6="","",'Project'!C6) | E8: =IF('Project'!D6="","",'Project'!D6) | F8: =IF('Project'!E6="","",'Project'!E6) | G8: =IF('Project'!F6="","",'Project'!F6) | H8: =IF('Project'!G6="","",'Project'!G6) | I8: =IF('Project'!H6="","",'Project'!H6) | J8: =IF('Project'!I6="","",'Project'!I6) | ... N8: =IF('Project'!M6="","",'Project'!M6)
A9: =IF('Project'!A7="","",'Project'!A7) | B9: Project | C9: =IF('Project'!B7="","",'Project'!B7) | D9: =IF('Project'!C7="","",'Project'!C7) | E9: =IF('Project'!D7="","",'Project'!D7) | F9: =IF('Project'!E7="","",'Project'!E7) | G9: =IF('Project'!F7="","",'Project'!F7) | H9: =IF('Project'!G7="","",'Project'!G7) | I9: =IF('Project'!H7="","",'Project'!H7) | J9: =IF('Project'!I7="","",'Project'!I7) | ... N9: =IF('Project'!M7="","",'Project'!M7)
A10: =IF('Project'!A8="","",'Project'!A8) | B10: Project | C10: =IF('Project'!B8="","",'Project'!B8) | D10: =IF('Project'!C8="","",'Project'!C8) | E10: =IF('Project'!D8="","",'Project'!D8) | F10: =IF('Project'!E8="","",'Project'!E8) | G10: =IF('Project'!F8="","",'Project'!F8) | H10: =IF('Project'!G8="","",'Project'!G8) | I10: =IF('Project'!H8="","",'Project'!H8) | J10: =IF('Project'!I8="","",'Project'!I8) | ... N10: =IF('Project'!M8="","",'Project'!M8)
A11: =IF('Project'!A9="","",'Project'!A9) | B11: Project | C11: =IF('Project'!B9="","",'Project'!B9) | D11: =IF('Project'!C9="","",'Project'!C9) | E11: =IF('Project'!D9="","",'Project'!D9) | F11: =IF('Project'!E9="","",'Project'!E9) | G11: =IF('Project'!F9="","",'Project'!F9) | H11: =IF('Project'!G9="","",'Project'!G9) | I11: =IF('Project'!H9="","",'Project'!H9) | J11: =IF('Project'!I9="","",'Project'!I9) | ... N11: =IF('Project'!M9="","",'Project'!M9)
A12: =IF('Project'!A10="","",'Project'!A10) | B12: Project | C12: =IF('Project'!B10="","",'Project'!B10) | D12: =IF('Project'!C10="","",'Project'!C10) | E12: =IF('Project'!D10="","",'Project'!D10) | F12: =IF('Project'!E10="","",'Project'!E10) | G12: =IF('Project'!F10="","",'Project'!F10) | H12: =IF('Project'!G10="","",'Project'!G10) | I12: =IF('Project'!H10="","",'Project'!H10) | J12: =IF('Project'!I10="","",'Project'!I10) | ... N12: =IF('Project'!M10="","",'Project'!M10)
A13: =IF('Networking'!A3="","",'Networking'!A3) | B13: Networking | C13: =IF('Networking'!B3="","",'Networking'!B3) | D13: =IF('Networking'!C3="","",'Networking'!C3) | E13: =IF('Networking'!D3="","",'Networking'!D3) | F13: =IF('Networking'!E3="","",'Networking'!E3) | G13: =IF('Networking'!F3="","",'Networking'!F3) | H13: =IF('Networking'!G3="","",'Networking'!G3) | I13: =IF('Networking'!H3="","",'Networking'!H3) | J13: =IF('Networking'!I3="","",'Networking'!I3) | ... N13: =IF('Networking'!M3="","",'Networking'!M3)
A14: =IF('Networking'!A4="","",'Networking'!A4) | B14: Networking | C14: =IF('Networking'!B4="","",'Networking'!B4) | D14: =IF('Networking'!C4="","",'Networking'!C4) | E14: =IF('Networking'!D4="","",'Networking'!D4) | F14: =IF('Networking'!E4="","",'Networking'!E4) | G14: =IF('Networking'!F4="","",'Networking'!F4) | H14: =IF('Networking'!G4="","",'Networking'!G4) | I14: =IF('Networking'!H4="","",'Networking'!H4) | J14: =IF('Networking'!I4="","",'Networking'!I4) | ... N14: =IF('Networking'!M4="","",'Networking'!M4)
A15: =IF('Networking'!A5="","",'Networking'!A5) | B15: Networking | C15: =IF('Networking'!B5="","",'Networking'!B5) | D15: =IF('Networking'!C5="","",'Networking'!C5) | E15: =IF('Networking'!D5="","",'Networking'!D5) | F15: =IF('Networking'!E5="","",'Networking'!E5) | G15: =IF('Networking'!F5="","",'Networking'!F5) | H15: =IF('Networking'!G5="","",'Networking'!G5) | I15: =IF('Networking'!H5="","",'Networking'!H5) | J15: =IF('Networking'!I5="","",'Networking'!I5) | ... N15: =IF('Networking'!M5="","",'Networking'!M5)
A16: =IF('Networking'!A6="","",'Networking'!A6) | B16: Networking | C16: =IF('Networking'!B6="","",'Networking'!B6) | D16: =IF('Networking'!C6="","",'Networking'!C6) | E16: =IF('Networking'!D6="","",'Networking'!D6) | F16: =IF('Networking'!E6="","",'Networking'!E6) | G16: =IF('Networking'!F6="","",'Networking'!F6) | H16: =IF('Networking'!G6="","",'Networking'!G6) | I16: =IF('Networking'!H6="","",'Networking'!H6) | J16: =IF('Networking'!I6="","",'Networking'!I6) | ... N16: =IF('Networking'!M6="","",'Networking'!M6)
A17: =IF('Networking'!A7="","",'Networking'!A7) | B17: Networking | C17: =IF('Networking'!B7="","",'Networking'!B7) | D17: =IF('Networking'!C7="","",'Networking'!C7) | E17: =IF('Networking'!D7="","",'Networking'!D7) | F17: =IF('Networking'!E7="","",'Networking'!E7) | G17: =IF('Networking'!F7="","",'Networking'!F7) | H17: =IF('Networking'!G7="","",'Networking'!G7) | I17: =IF('Networking'!H7="","",'Networking'!H7) | J17: =IF('Networking'!I7="","",'Networking'!I7) | ... N17: =IF('Networking'!M7="","",'Networking'!M7)
A18: =IF('Networking'!A8="","",'Networking'!A8) | B18: Networking | C18: =IF('Networking'!B8="","",'Networking'!B8) | D18: =IF('Networking'!C8="","",'Networking'!C8) | E18: =IF('Networking'!D8="","",'Networking'!D8) | F18: =IF('Networking'!E8="","",'Networking'!E8) | G18: =IF('Networking'!F8="","",'Networking'!F8) | H18: =IF('Networking'!G8="","",'Networking'!G8) | I18: =IF('Networking'!H8="","",'Networking'!H8) | J18: =IF('Networking'!I8="","",'Networking'!I8) | ... N18: =IF('Networking'!M8="","",'Networking'!M8)
A19: =IF('Networking'!A9="","",'Networking'!A9) | B19: Networking | C19: =IF('Networking'!B9="","",'Networking'!B9) | D19: =IF('Networking'!C9="","",'Networking'!C9) | E19: =IF('Networking'!D9="","",'Networking'!D9) | F19: =IF('Networking'!E9="","",'Networking'!E9) | G19: =IF('Networking'!F9="","",'Networking'!F9) | H19: =IF('Networking'!G9="","",'Networking'!G9) | I19: =IF('Networking'!H9="","",'Networking'!H9) | J19: =IF('Networking'!I9="","",'Networking'!I9) | ... N19: =IF('Networking'!M9="","",'Networking'!M9)
A20: =IF('Security'!A3="","",'Security'!A3) | B20: Security | C20: =IF('Security'!B3="","",'Security'!B3) | D20: =IF('Security'!C3="","",'Security'!C3) | E20: =IF('Security'!D3="","",'Security'!D3) | F20: =IF('Security'!E3="","",'Security'!E3) | G20: =IF('Security'!F3="","",'Security'!F3) | H20: =IF('Security'!G3="","",'Security'!G3) | I20: =IF('Security'!H3="","",'Security'!H3) | J20: =IF('Security'!I3="","",'Security'!I3) | ... N20: =IF('Security'!M3="","",'Security'!M3)
A21: =IF('Security'!A4="","",'Security'!A4) | B21: Security | C21: =IF('Security'!B4="","",'Security'!B4) | D21: =IF('Security'!C4="","",'Security'!C4) | E21: =IF('Security'!D4="","",'Security'!D4) | F21: =IF('Security'!E4="","",'Security'!E4) | G21: =IF('Security'!F4="","",'Security'!F4) | H21: =IF('Security'!G4="","",'Security'!G4) | I21: =IF('Security'!H4="","",'Security'!H4) | J21: =IF('Security'!I4="","",'Security'!I4) | ... N21: =IF('Security'!M4="","",'Security'!M4)
A22: =IF('Security'!A5="","",'Security'!A5) | B22: Security | C22: =IF('Security'!B5="","",'Security'!B5) | D22: =IF('Security'!C5="","",'Security'!C5) | E22: =IF('Security'!D5="","",'Security'!D5) | F22: =IF('Security'!E5="","",'Security'!E5) | G22: =IF('Security'!F5="","",'Security'!F5) | H22: =IF('Security'!G5="","",'Security'!G5) | I22: =IF('Security'!H5="","",'Security'!H5) | J22: =IF('Security'!I5="","",'Security'!I5) | ... N22: =IF('Security'!M5="","",'Security'!M5)
A23: =IF('Security'!A6="","",'Security'!A6) | B23: Security | C23: =IF('Security'!B6="","",'Security'!B6) | D23: =IF('Security'!C6="","",'Security'!C6) | E23: =IF('Security'!D6="","",'Security'!D6) | F23: =IF('Security'!E6="","",'Security'!E6) | G23: =IF('Security'!F6="","",'Security'!F6) | H23: =IF('Security'!G6="","",'Security'!G6) | I23: =IF('Security'!H6="","",'Security'!H6) | J23: =IF('Security'!I6="","",'Security'!I6) | ... N23: =IF('Security'!M6="","",'Security'!M6)
A24: =IF('Security'!A7="","",'Security'!A7) | B24: Security | C24: =IF('Security'!B7="","",'Security'!B7) | D24: =IF('Security'!C7="","",'Security'!C7) | E24: =IF('Security'!D7="","",'Security'!D7) | F24: =IF('Security'!E7="","",'Security'!E7) | G24: =IF('Security'!F7="","",'Security'!F7) | H24: =IF('Security'!G7="","",'Security'!G7) | I24: =IF('Security'!H7="","",'Security'!H7) | J24: =IF('Security'!I7="","",'Security'!I7) | ... N24: =IF('Security'!M7="","",'Security'!M7)
A25: =IF('Security'!A8="","",'Security'!A8) | B25: Security | C25: =IF('Security'!B8="","",'Security'!B8) | D25: =IF('Security'!C8="","",'Security'!C8) | E25: =IF('Security'!D8="","",'Security'!D8) | F25: =IF('Security'!E8="","",'Security'!E8) | G25: =IF('Security'!F8="","",'Security'!F8) | H25: =IF('Security'!G8="","",'Security'!G8) | I25: =IF('Security'!H8="","",'Security'!H8) | J25: =IF('Security'!I8="","",'Security'!I8) | ... N25: =IF('Security'!M8="","",'Security'!M8)
A26: =IF('Security'!A9="","",'Security'!A9) | B26: Security | C26: =IF('Security'!B9="","",'Security'!B9) | D26: =IF('Security'!C9="","",'Security'!C9) | E26: =IF('Security'!D9="","",'Security'!D9) | F26: =IF('Security'!E9="","",'Security'!E9) | G26: =IF('Security'!F9="","",'Security'!F9) | H26: =IF('Security'!G9="","",'Security'!G9) | I26: =IF('Security'!H9="","",'Security'!H9) | J26: =IF('Security'!I9="","",'Security'!I9) | ... N26: =IF('Security'!M9="","",'Security'!M9)
A27: =IF('Security'!A10="","",'Security'!A10) | B27: Security | C27: =IF('Security'!B10="","",'Security'!B10) | D27: =IF('Security'!C10="","",'Security'!C10) | E27: =IF('Security'!D10="","",'Security'!D10) | F27: =IF('Security'!E10="","",'Security'!E10) | G27: =IF('Security'!F10="","",'Security'!F10) | H27: =IF('Security'!G10="","",'Security'!G10) | I27: =IF('Security'!H10="","",'Security'!H10) | J27: =IF('Security'!I10="","",'Security'!I10) | ... N27: =IF('Security'!M10="","",'Security'!M10)
A28: =IF('Security'!A11="","",'Security'!A11) | B28: Security | C28: =IF('Security'!B11="","",'Security'!B11) | D28: =IF('Security'!C11="","",'Security'!C11) | E28: =IF('Security'!D11="","",'Security'!D11) | F28: =IF('Security'!E11="","",'Security'!E11) | G28: =IF('Security'!F11="","",'Security'!F11) | H28: =IF('Security'!G11="","",'Security'!G11) | I28: =IF('Security'!H11="","",'Security'!H11) | J28: =IF('Security'!I11="","",'Security'!I11) | ... N28: =IF('Security'!M11="","",'Security'!M11)
A29: =IF('Security'!A12="","",'Security'!A12) | B29: Security | C29: =IF('Security'!B12="","",'Security'!B12) | D29: =IF('Security'!C12="","",'Security'!C12) | E29: =IF('Security'!D12="","",'Security'!D12) | F29: =IF('Security'!E12="","",'Security'!E12) | G29: =IF('Security'!F12="","",'Security'!F12) | H29: =IF('Security'!G12="","",'Security'!G12) | I29: =IF('Security'!H12="","",'Security'!H12) | J29: =IF('Security'!I12="","",'Security'!I12) | ... N29: =IF('Security'!M12="","",'Security'!M12)
A30: =IF('Security'!A13="","",'Security'!A13) | B30: Security | C30: =IF('Security'!B13="","",'Security'!B13) | D30: =IF('Security'!C13="","",'Security'!C13) | E30: =IF('Security'!D13="","",'Security'!D13) | F30: =IF('Security'!E13="","",'Security'!E13) | G30: =IF('Security'!F13="","",'Security'!F13) | H30: =IF('Security'!G13="","",'Security'!G13) | I30: =IF('Security'!H13="","",'Security'!H13) | J30: =IF('Security'!I13="","",'Security'!I13) | ... N30: =IF('Security'!M13="","",'Security'!M13)
A31: =IF('Security'!A14="","",'Security'!A14) | B31: Security | C31: =IF('Security'!B14="","",'Security'!B14) | D31: =IF('Security'!C14="","",'Security'!C14) | E31: =IF('Security'!D14="","",'Security'!D14) | F31: =IF('Security'!E14="","",'Security'!E14) | G31: =IF('Security'!F14="","",'Security'!F14) | H31: =IF('Security'!G14="","",'Security'!G14) | I31: =IF('Security'!H14="","",'Security'!H14) | J31: =IF('Security'!I14="","",'Security'!I14) | ... N31: =IF('Security'!M14="","",'Security'!M14)
... A35: =IF('Security'!A18="","",'Security'!A18) | B35: Security | C35: =IF('Security'!B18="","",'Security'!B18) | D35: =IF('Security'!C18="","",'Security'!C18) | E35: =IF('Security'!D18="","",'Security'!D18) | F35: =IF('Security'!E18="","",'Security'!E18) | G35: =IF('Security'!F18="","",'Security'!F18) | H35: =IF('Security'!G18="","",'Security'!G18) | I35: =IF('Security'!H18="","",'Security'!H18) | J35: =IF('Security'!I18="","",'Security'!I18) | ... N35: =IF('Security'!M18="","",'Security'!M18)
A36: =IF('Compute'!A3="","",'Compute'!A3) | B36: Compute | C36: =IF('Compute'!B3="","",'Compute'!B3) | D36: =IF('Compute'!C3="","",'Compute'!C3) | E36: =IF('Compute'!D3="","",'Compute'!D3) | F36: =IF('Compute'!E3="","",'Compute'!E3) | G36: =IF('Compute'!F3="","",'Compute'!F3) | H36: =IF('Compute'!G3="","",'Compute'!G3) | I36: =IF('Compute'!H3="","",'Compute'!H3) | J36: =IF('Compute'!I3="","",'Compute'!I3) | ... N36: =IF('Compute'!M3="","",'Compute'!M3)
A37: =IF('Compute'!A4="","",'Compute'!A4) | B37: Compute | C37: =IF('Compute'!B4="","",'Compute'!B4) | D37: =IF('Compute'!C4="","",'Compute'!C4) | E37: =IF('Compute'!D4="","",'Compute'!D4) | F37: =IF('Compute'!E4="","",'Compute'!E4) | G37: =IF('Compute'!F4="","",'Compute'!F4) | H37: =IF('Compute'!G4="","",'Compute'!G4) | I37: =IF('Compute'!H4="","",'Compute'!H4) | J37: =IF('Compute'!I4="","",'Compute'!I4) | ... N37: =IF('Compute'!M4="","",'Compute'!M4)
A38: =IF('Compute'!A5="","",'Compute'!A5) | B38: Compute | C38: =IF('Compute'!B5="","",'Compute'!B5) | D38: =IF('Compute'!C5="","",'Compute'!C5) | E38: =IF('Compute'!D5="","",'Compute'!D5) | F38: =IF('Compute'!E5="","",'Compute'!E5) | G38: =IF('Compute'!F5="","",'Compute'!F5) | H38: =IF('Compute'!G5="","",'Compute'!G5) | I38: =IF('Compute'!H5="","",'Compute'!H5) | J38: =IF('Compute'!I5="","",'Compute'!I5) | ... N38: =IF('Compute'!M5="","",'Compute'!M5)
A39: =IF('Compute'!A6="","",'Compute'!A6) | B39: Compute | C39: =IF('Compute'!B6="","",'Compute'!B6) | D39: =IF('Compute'!C6="","",'Compute'!C6) | E39: =IF('Compute'!D6="","",'Compute'!D6) | F39: =IF('Compute'!E6="","",'Compute'!E6) | G39: =IF('Compute'!F6="","",'Compute'!F6) | H39: =IF('Compute'!G6="","",'Compute'!G6) | I39: =IF('Compute'!H6="","",'Compute'!H6) | J39: =IF('Compute'!I6="","",'Compute'!I6) | ... N39: =IF('Compute'!M6="","",'Compute'!M6)
A40: =IF('Compute'!A7="","",'Compute'!A7) | B40: Compute | C40: =IF('Compute'!B7="","",'Compute'!B7) | D40: =IF('Compute'!C7="","",'Compute'!C7) | E40: =IF('Compute'!D7="","",'Compute'!D7) | F40: =IF('Compute'!E7="","",'Compute'!E7) | G40: =IF('Compute'!F7="","",'Compute'!F7) | H40: =IF('Compute'!G7="","",'Compute'!G7) | I40: =IF('Compute'!H7="","",'Compute'!H7) | J40: =IF('Compute'!I7="","",'Compute'!I7) | ... N40: =IF('Compute'!M7="","",'Compute'!M7)
A41: =IF('Compute'!A8="","",'Compute'!A8) | B41: Compute | C41: =IF('Compute'!B8="","",'Compute'!B8) | D41: =IF('Compute'!C8="","",'Compute'!C8) | E41: =IF('Compute'!D8="","",'Compute'!D8) | F41: =IF('Compute'!E8="","",'Compute'!E8) | G41: =IF('Compute'!F8="","",'Compute'!F8) | H41: =IF('Compute'!G8="","",'Compute'!G8) | I41: =IF('Compute'!H8="","",'Compute'!H8) | J41: =IF('Compute'!I8="","",'Compute'!I8) | ... N41: =IF('Compute'!M8="","",'Compute'!M8)
A42: =IF('Storage'!A3="","",'Storage'!A3) | B42: Storage | C42: =IF('Storage'!B3="","",'Storage'!B3) | D42: =IF('Storage'!C3="","",'Storage'!C3) | E42: =IF('Storage'!D3="","",'Storage'!D3) | F42: =IF('Storage'!E3="","",'Storage'!E3) | G42: =IF('Storage'!F3="","",'Storage'!F3) | H42: =IF('Storage'!G3="","",'Storage'!G3) | I42: =IF('Storage'!H3="","",'Storage'!H3) | J42: =IF('Storage'!I3="","",'Storage'!I3) | ... N42: =IF('Storage'!M3="","",'Storage'!M3)
A43: =IF('Storage'!A4="","",'Storage'!A4) | B43: Storage | C43: =IF('Storage'!B4="","",'Storage'!B4) | D43: =IF('Storage'!C4="","",'Storage'!C4) | E43: =IF('Storage'!D4="","",'Storage'!D4) | F43: =IF('Storage'!E4="","",'Storage'!E4) | G43: =IF('Storage'!F4="","",'Storage'!F4) | H43: =IF('Storage'!G4="","",'Storage'!G4) | I43: =IF('Storage'!H4="","",'Storage'!H4) | J43: =IF('Storage'!I4="","",'Storage'!I4) | ... N43: =IF('Storage'!M4="","",'Storage'!M4)
A44: =IF('Storage'!A5="","",'Storage'!A5) | B44: Storage | C44: =IF('Storage'!B5="","",'Storage'!B5) | D44: =IF('Storage'!C5="","",'Storage'!C5) | E44: =IF('Storage'!D5="","",'Storage'!D5) | F44: =IF('Storage'!E5="","",'Storage'!E5) | G44: =IF('Storage'!F5="","",'Storage'!F5) | H44: =IF('Storage'!G5="","",'Storage'!G5) | I44: =IF('Storage'!H5="","",'Storage'!H5) | J44: =IF('Storage'!I5="","",'Storage'!I5) | ... N44: =IF('Storage'!M5="","",'Storage'!M5)
...

Sheet Project
A1: Project Parameters
A2: Parameter Name | B2: Production | C2: Test | D2: DR | E2: Description | F2: Required | G2: Data Type | H2: Validation Rules | I2: Security Level | J2: Owner Team | K2: Dependencies | L2: Notes | M2: Last Updated
A3: solution.name | B3: amatra-presales-platform | C3: amatra-presales-platform | D3: amatra-presales-platform | E3: Solution identifier used for resource naming and tagging | F3: Yes | G3: String | H3: lowercase alphanumeric hyphens only max 50 chars | I3: Public | J3: Cloud CoE | M3: 2026-06-05
A4: solution.region.primary | B4: us-west-2 | C4: us-west-2 | D4: us-west-2 | E4: Primary AWS region for all solution resources per SOW | F4: Yes | G4: String | H4: Valid AWS region code | I4: Public | J4: Cloud CoE | L4: Single region per SOW scope; multi-region is out of scope | M4: 2026-06-05
A5: solution.environment | B5: prod | C5: dev | D5: prod | E5: Deployment environment identifier | F5: Yes | G5: String | H5: prod|dev|staging | I5: Public | J5: Cloud CoE | L5: DR mirrors production environment configuration | M5: 2026-06-05
A6: solution.opportunity_id | B6: OPP-2026-001 | C6: OPP-2026-001 | D6: OPP-2026-001 | E6: Opportunity identifier for cost allocation tagging | F6: Yes | G6: String | H6: OPP-YYYY-NNN format | I6: Public | J6: Cloud CoE | L6: Used in all resource cost allocation tags | M6: 2026-06-05
A7: aws.account_id | B7: [aws-account-id] | C7: [aws-account-id] | D7: [aws-account-id] | E7: AWS account identifier for the fresh us-west-2 footprint | F7: Yes | G7: String | H7: 12-digit numeric | I7: Confidential | J7: Cloud CoE | K7: solution.region.primary | L7: New isolated account per SOW; not the legacy us-east-1 account | M7: 2026-06-05
A8: solution.artifact_retention_days | B8: 365 | C8: 30 | D8: 365 | E8: S3 artifact retention period before lifecycle expiry | F8: Yes | G8: Integer | H8: 1-3653 | I8: Public | J8: Cloud CoE | K8: storage.s3.bucket_name | L8: Matches SOW data retention commitment; 365 days for prod | M8: 2026-06-05
A9: solution.monthly_quota.global | B9: 1000 | C9: 50 | D9: 1000 | E9: Global hard cap on solutions generated per calendar month | F9: Yes | G9: Integer | H9: 1-10000 | I9: Public | J9: Cloud CoE | K9: dynamodb.table.quota_global | L9: Enforced atomically via DynamoDB conditional writes per SOW | M9: 2026-06-05
A10: solution.monthly_quota.per_user | B10: 10 | C10: 5 | D10: 10 | E10: Per-user hard cap on solutions generated per calendar month | F10: Yes | G10: Integer | H10: 1-1000 | I10: Public | J10: Cloud CoE | K10: dynamodb.table.user_profiles | L10: Atomic enforcement; quota reset by scheduled Lambda each month | M10: 2026-06-05

Sheet Networking
A1: Networking Parameters
A2: Parameter Name | B2: Production | C2: Test | D2: DR | E2: Description | F2: Required | G2: Data Type | H2: Validation Rules | I2: Security Level | J2: Owner Team | K2: Dependencies | L2: Notes | M2: Last Updated
A3: networking.vpc_cidr | B3: 10.0.0.0/16 | C3: 10.1.0.0/16 | D3: 10.0.0.0/16 | E3: VPC CIDR block for the platform in us-west-2 | F3: Yes | G3: String | H3: Valid CIDR /16 or smaller | I3: Confidential | J3: Network Team | K3: solution.region.primary | L3: Purpose-built VPC per SOW; three availability zones | M3: 2026-06-05
A4: networking.subnet_private_az1_cidr | B4: 10.0.0.0/24 | C4: 10.1.0.0/24 | D4: 10.0.0.0/24 | E4: Private subnet CIDR in AZ1 hosting Lambda and AgentCore | F4: Yes | G4: String | H4: Valid CIDR within VPC CIDR | I4: Confidential | J4: Network Team | K4: networking.vpc_cidr | L4: All Lambda and AgentCore containers run in private subnets per SOW | M4: 2026-06-05
A5: networking.subnet_private_az2_cidr | B5: 10.0.1.0/24 | C5: 10.1.1.0/24 | D5: 10.0.1.0/24 | E5: Private subnet CIDR in AZ2 hosting Lambda and AgentCore | F5: Yes | G5: String | H5: Valid CIDR within VPC CIDR | I5: Confidential | J5: Network Team | K5: networking.vpc_cidr | L5: Multi-AZ redundancy for serverless components per SOW reliability | M5: 2026-06-05
A6: networking.subnet_private_az3_cidr | B6: 10.0.2.0/24 | C6: 10.1.2.0/24 | D6: 10.0.2.0/24 | E6: Private subnet CIDR in AZ3 hosting Lambda and AgentCore | F6: Yes | G6: String | H6: Valid CIDR within VPC CIDR | I6: Confidential | J6: Network Team | K6: networking.vpc_cidr | L6: Three AZs per SOW network design | M6: 2026-06-05
A7: networking.subnet_public_cidr | B7: 10.0.100.0/24 | C7: 10.1.100.0/24 | D7: 10.0.100.0/24 | E7: Public subnet CIDR hosting NAT Gateway | F7: Yes | G7: String | H7: Valid CIDR within VPC CIDR | I7: Confidential | J7: Network Team | K7: networking.vpc_cidr | L7: NAT Gateway handles GitHub API and CLI traffic only per SOW | M7: 2026-06-05
A8: networking.nat_gateway_count | B8: 1 | C8: 1 | D8: 1 | E8: Number of NAT Gateway instances for internet egress | F8: Yes | G8: Integer | H8: 1-3 | I8: Public | J8: Network Team | K8: networking.subnet_public_cidr | L8: 1 NAT GW per SOW scope; single region PoC does not require HA NAT | M8: 2026-06-05
A9: networking.vpc_endpoints_enabled | B9: true | C9: true | D9: true | E9: Provision VPC interface endpoints for AWS internal services | F9: Yes | G9: Boolean | H9: true|false | I9: Public | J9: Network Team | K9: networking.vpc_cidr | L9: Endpoints for Bedrock, DynamoDB, S3, Secrets Manager, ECR, CloudWatch Logs | M9: 2026-06-05

Sheet Security
A1: Security Parameters
A2: Parameter Name | B2: Production | C2: Test | D2: DR | E2: Description | F2: Required | G2: Data Type | H2: Validation Rules | I2: Security Level | J2: Owner Team | K2: Dependencies | L2: Notes | M2: Last Updated
A3: cognito.user_pool_name | B3: amatra-prod-user-pool | C3: amatra-dev-user-pool | D3: amatra-prod-user-pool | E3: Cognito User Pool name for platform authentication | F3: Yes | G3: String | H3: Non-empty string max 128 chars | I3: Confidential | J3: Security Team | L3: CTO sign-off required before production pool activation per SOW | M3: 2026-06-05
A4: cognito.user_pool_id | B4: [cognito-user-pool-id] | C4: [cognito-user-pool-id] | D4: [cognito-user-pool-id] | E4: Cognito User Pool ID used by JWT authoriser | F4: Yes | G4: String | H4: Valid Cognito pool ID format | I4: Confidential | J4: Security Team | K4: cognito.user_pool_name | L4: Populated post-provisioning; referenced by API Gateway JWT authoriser | M4: 2026-06-05
A5: cognito.app_client_id | B5: [cognito-app-client-id] | C5: [cognito-app-client-id] | D5: [cognito-app-client-id] | E5: Cognito App Client ID for CLI and API authentication flows | F5: Yes | G5: String | H5: Alphanumeric max 128 chars | I5: Confidential | J5: Security Team | K5: cognito.user_pool_id | L5: Used by pip CLI for token acquisition and refresh | M5: 2026-06-05
A6: cognito.app_client_secret | B6: [cognito-app-client-secret] | C6: [cognito-app-client-secret] | D6: [cognito-app-client-secret] | E6: Cognito App Client secret for server-side auth flows | F6: Yes | G6: String | H6: Non-empty string | I6: Secret | J6: Security Team | K6: cognito.app_client_id | L6: Stored in Secrets Manager; rotated every 365 days; never in code | M6: 2026-06-05
A7: cognito.token_refresh_ttl_days | B7: 30 | C7: 30 | D7: 30 | E7: JWT refresh token TTL in days per SOW authentication spec | F7: Yes | G7: Integer | H7: 1-3650 | I7: Public | J7: Security Team | K7: cognito.user_pool_id | L7: Matches SOW 30-day refresh token commitment | M7: 2026-06-05
A8: cognito.access_token_ttl_hours | B8: 1 | C8: 1 | D8: 1 | E8: JWT access token expiry in hours | F8: Yes | G8: Integer | H8: 1-24 | I8: Public | J8: Security Team | K8: cognito.user_pool_id | L8: Short-lived access tokens per least-privilege IAM design | M8: 2026-06-05
A9: cognito.mfa_enabled | B9: false | C9: false | D9: false | E9: MFA enforcement in Cognito User Pool | F9: Yes | G9: Boolean | H9: true|false | I9: Public | J9: Security Team | K9: cognito.user_pool_id | L9: MFA eligibility enabled; enforcement optional per SOW; revisit at Phase 2 | M9: 2026-06-05
A10: security.kms_key_id | B10: [kms-key-id] | C10: [kms-key-id] | D10: [kms-key-id] | E10: Customer-managed KMS key ID for SSE-KMS on S3 and CloudWatch Logs | F10: Yes | G10: String | H10: Valid KMS key ID or ARN | I10: Secret | J10: Security Team | K10: solution.region.primary | L10: CMK per SOW encryption-at-rest requirement; stored in Secrets Manager | M10: 2026-06-05
A11: security.enable_encryption_at_rest | B11: true | C11: true | D11: true | E11: Enable SSE-KMS encryption at rest for all data stores | F11: Yes | G11: Boolean | H11: true|false | I11: Public | J11: Security Team | K11: security.kms_key_id | L11: Applies to S3 and CloudWatch Logs; DynamoDB uses AWS-managed key | M11: 2026-06-05
A12: security.tls_minimum_version | B12: TLS1.2 | C12: TLS1.2 | D12: TLS1.2 | E12: Minimum TLS version for all data in transit | F12: Yes | G12: String | H12: TLS1.2|TLS1.3 | I12: Public | J12: Security Team | L12: Enforced via S3 bucket policy aws:SecureTransport condition | M12: 2026-06-05
A13: security.guardduty_enabled | B13: true | C13: true | D13: true | E13: Enable AWS GuardDuty threat detection in the account | F13: Yes | G13: Boolean | H13: true|false | I13: Public | J13: Security Team | K13: aws.account_id | L13: Required for SOC 2 Type II baseline controls per SOW | M13: 2026-06-05
A14: security.cloudtrail_enabled | B14: true | C14: true | D14: true | E14: Enable CloudTrail data events for S3 and DynamoDB | F14: Yes | G14: Boolean | H14: true|false | I14: Public | J14: Security Team | K14: storage.s3.cloudtrail_bucket | L14: Required for SOW audit trail commitment; WORM retention 365 days | M14: 2026-06-05
A15: security.cloudtrail_retention_days | B15: 365 | C15: 30 | D15: 365 | E15: CloudTrail log retention in dedicated S3 bucket with Object Lock | F15: Yes | G15: Integer | H15: 1-3653 | I15: Public | J15: Security Team | K15: security.cloudtrail_enabled | L15: 365 days matches SOW tamper-proof audit evidence requirement | M15: 2026-06-05
A16: security.iam_permission_boundary_arn | B16: [iam-permission-boundary-arn] | C16: [iam-permission-boundary-arn] | D16: [iam-permission-boundary-arn] | E16: IAM permission boundary ARN applied to developer and CI/CD roles | F16: Yes | G16: String | H16: Valid IAM ARN format | I16: Confidential | J16: Security Team | K16: aws.account_id | L16: Prevents privilege escalation per SOW IAM least-privilege design | M16: 2026-06-05
A17: secrets.manager.github_pat_secret_name | B17: amatra/prod/github-pat | C17: amatra/dev/github-pat | D17: amatra/prod/github-pat | E17: Secrets Manager secret name holding the GitHub PAT | F17: Yes | G17: String | H17: Valid Secrets Manager secret name path | I17: Confidential | J17: Security Team | K17: solution.region.primary | L17: Automatic rotation every 90 days via Lambda rotation function per SOW | M17: 2026-06-05
A18: secrets.manager.cognito_secret_name | B18: amatra/prod/cognito-app-client-secret | C18: amatra/dev/cognito-app-client-secret | D18: amatra/prod/cognito-app-client-secret | E18: Secrets Manager secret name holding the Cognito App Client secret | F18: Yes | G18: String | H18: Valid Secrets Manager secret name path | I18: Confidential | J18: Security Team | K18: cognito.app_client_id | L18: Rotated every 365 days; no plaintext credentials in Lambda env vars | M18: 2026-06-05

Sheet Compute
A1: Compute Parameters
A2: Parameter Name | B2: Production | C2: Test | D2: DR | E2: Description | F2: Required | G2: Data Type | H2: Validation Rules | I2: Security Level | J2: Owner Team | K2: Dependencies | L2: Notes | M2: Last Updated
A3: compute.lambda.memory_mb | B3: 1024 | C3: 512 | D3: 1024 | E3: Default Lambda function memory allocation in MB | F3: Yes | G3: Integer | H3: 128-10240 | I3: Public | J3: Development | L3: Tuned for agent handler performance; adjust per function in IaC | M3: 2026-06-05
A4: compute.lambda.timeout_seconds | B4: 900 | C4: 900 | D4: 900 | E4: Default Lambda function timeout in seconds | F4: Yes | G4: Integer | H4: 1-900 | I4: Public | J4: Development | K4: application.generation_timeout_minutes | L4: Set to Lambda maximum; Step Functions manages overall pipeline timeout | M4: 2026-06-05
A5: compute.lambda.reserved_concurrency | B5: 50 | C5: 10 | D5: 50 | E5: Reserved Lambda concurrency units for platform functions | F5: Yes | G5: Integer | H5: 0-1000 | I5: Public | J5: Development | K5: compute.lambda.memory_mb | L5: Sized for 200 solutions/month steady-state with headroom | M5: 2026-06-05
A6: compute.stepfunctions.execution_timeout_seconds | B6: 3600 | C6: 3600 | D6: 3600 | E6: Step Functions state machine execution timeout in seconds | F6: Yes | G6: Integer | H6: 1-31536000 | I6: Public | J6: Development | K6: application.generation_timeout_minutes | L6: 3600s = 60 min; maps directly to P95 end-to-end SLA per SOW | M6: 2026-06-05
A7: compute.ecr.repository_name | B7: amatra-agentcore | C7: amatra-agentcore | D7: amatra-agentcore | E7: ECR repository name for AgentCore agent Docker images | F7: Yes | G7: String | H7: Lowercase alphanumeric hyphens and slashes | I7: Confidential | J7: DevOps Team | K7: solution.region.primary | L7: Single repo; images tagged by agent name and version | M7: 2026-06-05
A8: compute.ecr.image_retention_count | B8: 3 | C8: 3 | D8: 3 | E8: Number of most-recent tagged ECR image versions retained | F8: Yes | G8: Integer | H8: 1-100 | I8: Public | J8: DevOps Team | K8: compute.ecr.repository_name | L8: Lifecycle policy retains last 3 tagged versions per SOW design | M8: 2026-06-05

Sheet Storage
A1: Storage Parameters
A2: Parameter Name | B2: Production | C2: Test | D2: DR | E2: Description | F2: Required | G2: Data Type | H2: Validation Rules | I2: Security Level | J2: Owner Team | K2: Dependencies | L2: Notes | M2: Last Updated
A3: storage.s3.bucket_name | B3: [s3-artifact-bucket-name] | C3: [s3-artifact-bucket-name] | D3: [s3-artifact-bucket-name] | E3: S3 bucket name for raw and converted artifact storage | F3: Yes | G3: String | H3: Globally unique DNS-compliant bucket name | I3: Confidential | J3: Operations | K3: solution.region.primary | L3: Hosts raw markdown/CSV and converted DOCX/PPTX/XLSX per SOW | M3: 2026-06-05
A4: storage.s3.versioning_enabled | B4: true | C4: true | D4: true | E4: Enable S3 object versioning on the artifact bucket | F4: Yes | G4: Boolean | H4: true|false | I4: Public | J4: Operations | K4: storage.s3.bucket_name | L4: Required for rollback and RPO=0 for artifact tier per SOW DR design | M4: 2026-06-05
A5: storage.s3.glacier_transition_days | B5: 30 | C5: 0 | D5: 30 | E5: Days after which non-current S3 object versions move to Glacier | F5: Yes | G5: Integer | H5: 0-3650 | I5: Public | J5: Operations | K5: storage.s3.versioning_enabled | L5: 0 in dev disables Glacier transition; 30 days in prod per SOW lifecycle | M5: 2026-06-05
A6: storage.s3.cloudtrail_bucket | B6: [s3-cloudtrail-bucket-name] | C6: [s3-cloudtrail-bucket-name] | D6: [s3-cloudtrail-bucket-name] | E6: S3 bucket name for CloudTrail logs with Object Lock (WORM) | F6: Yes | G6: String | H6: Globally unique DNS-compliant bucket name | I6: Confidential | J6: Security Team | K6: security.cloudtrail_enabled | L6: Separate bucket from artifact store; WORM enabled for 365-day retention | M6: 2026-06-05
A7: storage.s3.enforce_ssl | B7: true | C7: true | D7: true | E7: Enforce HTTPS-only access via S3 bucket policy | F7: Yes | G7: Boolean | H7: true|false | I7: Public | J7: Security Team | K7: storage.s3.bucket_name | L7: Enforced via aws:SecureTransport condition per SOW TLS requirement | M7: 2026-06-05

Sheet Database
A1: Database Parameters
A2: Parameter Name | B2: Production | C2: Test | D2: DR | E2: Description | F2: Required | G2: Data Type | H2: Validation Rules | I2: Security Level | J2: Owner Team | K2: Dependencies | L2: Notes | M2: Last Updated
A3: dynamodb.table.user_profiles | B3: amatra-prod-user-profiles | C3: amatra-dev-user-profiles | D3: amatra-prod-user-profiles | E3: DynamoDB table name for user profiles and per-user quota counters | F3: Yes | G3: String | H3: Alphanumeric hyphens max 255 chars | I3: Confidential | J3: Database Team | K3: solution.region.primary | M3: 2026-06-05
A4: dynamodb.table.solution_state | B4: amatra-prod-solution-state | C4: amatra-dev-solution-state | D4: amatra-prod-solution-state | E4: DynamoDB table name for per-solution execution state and artifact status | F4: Yes | G4: String | H4: Alphanumeric hyphens max 255 chars | I4: Confidential | J4: Database Team | K4: solution.region.primary | M4: 2026-06-05
A5: dynamodb.table.quota_global | B5: amatra-prod-quota-global | C5: amatra-dev-quota-global | D5: amatra-prod-quota-global | E5: DynamoDB table name for global 1000/month quota pool counter | F5: Yes | G5: String | H5: Alphanumeric hyphens max 255 chars | I5: Confidential | J5: Database Team | K5: solution.region.primary | L5: Conditional writes enforce atomic global quota cap per SOW | M5: 2026-06-05
A6: dynamodb.billing_mode | B6: PAY_PER_REQUEST | C6: PAY_PER_REQUEST | D6: PAY_PER_REQUEST | E6: DynamoDB billing mode for all platform tables | F6: Yes | G6: String | H6: PROVISIONED|PAY_PER_REQUEST | I6: Public | J6: Database Team | K6: dynamodb.table.user_profiles | L6: On-demand chosen to handle bursty quota-write workloads without throttle | M6: 2026-06-05
A7: dynamodb.pitr_enabled | B7: true | C7: false | D7: true | E7: Enable DynamoDB Point-in-Time Recovery on all tables | F7: Yes | G7: Boolean | H7: true|false | I7: Public | J7: Database Team | K7: dynamodb.table.user_profiles | L7: PITR provides 35-day recovery window per SOW data architecture | M7: 2026-06-05
A8: dynamodb.solution_state_ttl_days | B8: 90 | C8: 30 | D8: 90 | E8: DynamoDB TTL for solution state records in days | F8: Yes | G8: Integer | H8: 1-3653 | I8: Public | J8: Database Team | K8: dynamodb.table.solution_state | L8: Records archived after 90 days via DynamoDB TTL per SOW data architecture | M8: 2026-06-05

Sheet Application
A1: Application Parameters
A2: Parameter Name | B2: Production | C2: Test | D2: DR | E2: Description | F2: Required | G2: Data Type | H2: Validation Rules | I2: Security Level | J2: Owner Team | K2: Dependencies | L2: Notes | M2: Last Updated
A3: application.name | B3: amatra-presales-platform | C3: amatra-presales-platform | D3: amatra-presales-platform | E3: Application identifier used in logging and monitoring | F3: Yes | G3: String | H3: Alphanumeric and hyphens max 50 chars | I3: Public | J3: Development | K3: solution.name | M3: 2026-06-05
A4: application.version | B4: 1.0.0 | C4: 1.0.0 | D4: 1.0.0 | E4: Current application semantic version | F4: Yes | G4: String | H4: Semantic versioning X.Y.Z | I4: Public | J4: Development | L4: Increment on each production deployment | M4: 2026-06-05
A5: application.log_level | B5: info | C5: debug | D5: info | E5: Logging verbosity level for all Lambda functions and agents | F5: Yes | G5: String | H5: debug|info|warn|error | I5: Public | J5: Operations | L5: debug only in dev; info in prod to reduce CloudWatch cost | M5: 2026-06-05
A6: application.max_artifacts_per_solution | B6: 12 | C6: 12 | D6: 12 | E6: Total artifact types produced per solution run per SOW scope | F6: Yes | G6: Integer | H6: 1-50 | I6: Public | J6: Development | L6: 5 presales + 6 delivery + 1 Terraform IaC bundle | M6: 2026-06-05
A7: application.validation_retry_limit | B7: 3 | C7: 3 | D7: 3 | E7: Maximum per-artifact validation retry attempts before P1 escalation | F7: Yes | G7: Integer | H7: 1-10 | I7: Public | J7: Development | L7: Matches SOW format-check + LLM quality-check retry contract | M7: 2026-06-05
A8: application.generation_timeout_minutes | B8: 60 | C8: 60 | D8: 60 | E8: P95 end-to-end solution generation SLA in minutes | F8: Yes | G8: Integer | H8: 1-480 | I8: Public | J8: Development | K8: compute.stepfunctions.execution_timeout_seconds | L8: Hard SLA per SOW; breach triggers CloudWatch alarm | M8: 2026-06-05
A9: api.gateway_id | B9: [api-gateway-id] | C9: [api-gateway-id] | D9: [api-gateway-id] | E9: API Gateway HTTP API v2 identifier | F9: Yes | G9: String | H9: Non-empty alphanumeric | I9: Confidential | J9: Development | K9: cognito.user_pool_id | L9: Populated post-provisioning; 11 Lambda routes behind JWT authoriser | M9: 2026-06-05
A10: api.route_count | B10: 11 | C10: 11 | D10: 11 | E10: Total number of JWT-protected Lambda routes per SOW scope | F10: Yes | G10: Integer | H10: 1-100 | I10: Public | J10: Development | K10: api.gateway_id | L10: Fixed at 11 per SOW; additional routes require change control | M10: 2026-06-05
A11: api.throttle_rate_limit | B11: 100 | C11: 20 | D11: 100 | E11: API Gateway route-level throttle rate limit (requests/second) | F11: Yes | G11: Integer | H11: 1-10000 | I11: Public | J11: Development | K11: api.gateway_id | L11: Prevents any single user from saturating Lambda concurrency pool | M11: 2026-06-05
A12: api.throttle_burst_limit | B12: 200 | C12: 50 | D12: 200 | E12: API Gateway route-level throttle burst limit (requests) | F12: Yes | G12: Integer | H12: 1-10000 | I12: Public | J12: Development | K12: api.throttle_rate_limit | L12: Set higher than rate limit to absorb short traffic spikes | M12: 2026-06-05
A13: bedrock.generation_model_id | B13: us.anthropic.claude-sonnet-4-5 | C13: us.anthropic.claude-sonnet-4-5 | D13: us.anthropic.claude-sonnet-4-5 | E13: Bedrock model ID for primary artifact generation (Claude Sonnet 4.6) | F13: Yes | G13: String | H13: Valid Bedrock model ID | I13: Public | J13: ML/AI Team | K13: solution.region.primary | L13: Claude Sonnet 4.6 per SOW; confirm model availability in us-west-2 at Phase 2 | M13: 2026-06-05
A14: bedrock.validation_model_id | B14: us.anthropic.claude-haiku-4-5 | C14: us.anthropic.claude-haiku-4-5 | D14: us.anthropic.claude-haiku-4-5 | E14: Bedrock model ID for cost-efficient validation (Claude Haiku 4.5) | F14: Yes | G14: String | H14: Valid Bedrock model ID | I14: Public | J14: ML/AI Team | K14: solution.region.primary | L14: Haiku 4.5 chosen for 5x cost advantage over Sonnet at validation tasks | M14: 2026-06-05
A15: bedrock.max_tokens_per_call | B15: 4096 | C15: 4096 | D15: 4096 | E15: Maximum output token limit per Bedrock inference call | F15: Yes | G15: Integer | H15: 1-32768 | I15: Public | J15: ML/AI Team | K15: bedrock.generation_model_id | L15: Tune per artifact type; caps runaway token spend per SOW $5/solution target | M15: 2026-06-05
A16: bedrock.monthly_token_budget_millions | B16: 25 | C16: 5 | D16: 25 | E16: Monthly Bedrock token budget ceiling in millions (combined models) | F16: Yes | G16: Integer | H16: 1-10000 | I16: Public | J16: ML/AI Team | K16: bedrock.generation_model_id | L16: 5M–25M tokens/month per SOW scope; alarm at 110% of budget | M16: 2026-06-05
A17: cli.package_name | B17: amatra-cli | C17: amatra-cli | D17: amatra-cli | E17: PyPI package name for the pip-installable CLI distribution | F17: Yes | G17: String | H17: Valid PyPI package name | I17: Public | J17: Development | L17: pip install amatra-cli; distributed to 120 consultants per SOW | M17: 2026-06-05
A18: cli.subcommand_count | B18: 14 | C18: 14 | D18: 14 | E18: Total number of CLI subcommands per SOW scope | F18: Yes | G18: Integer | H18: 1-100 | I18: Public | J18: Development | K18: cli.package_name | L18: Fixed at 14 per SOW; additional subcommands require change control | M18: 2026-06-05
A19: cli.credential_storage_path | B19: ~/.amatra/credentials | C19: ~/.amatra/credentials | D19: ~/.amatra/credentials | E19: Local file path for JWT credential storage on consultant laptops | F19: Yes | G19: String | H19: Valid filesystem path | I19: Confidential | J19: Development | K19: cognito.user_pool_id | L19: Stores access and refresh tokens post-login; chmod 600 recommended | M19: 2026-06-05
A20: agentcore.agent_count | B20: 5 | C20: 5 | D20: 5 | E20: Number of Strands agents registered in Bedrock AgentCore Runtime | F20: Yes | G20: Integer | H20: 1-20 | I20: Public | J20: ML/AI Team | K20: solution.region.primary | L20: Input Validator, Pre-Sales Generator, Delivery Generator, Code Generator, EO Validator | M20: 2026-06-05
A21: agentcore.input_validator_agent_id | B21: [agentcore-input-validator-id] | C21: [agentcore-input-validator-id] | D21: [agentcore-input-validator-id] | E21: AgentCore Runtime resource ID for the Input Validator agent | F21: Yes | G21: String | H21: Valid AgentCore agent ID | I21: Confidential | J21: ML/AI Team | K21: compute.ecr.repository_name | L21: Validates brief.txt format; first agent in Step Functions graph | M21: 2026-06-05
A22: agentcore.presales_generator_agent_id | B22: [agentcore-presales-gen-id] | C22: [agentcore-presales-gen-id] | D22: [agentcore-presales-gen-id] | E22: AgentCore Runtime resource ID for the Pre-Sales Generator agent | F22: Yes | G22: String | H22: Valid AgentCore agent ID | I22: Confidential | J22: ML/AI Team | K22: agentcore.input_validator_agent_id | L22: Produces 5 presales artifacts using Claude Sonnet 4.6 | M22: 2026-06-05
A23: agentcore.delivery_generator_agent_id | B23: [agentcore-delivery-gen-id] | C23: [agentcore-delivery-gen-id] | D23: [agentcore-delivery-gen-id] | E23: AgentCore Runtime resource ID for the Delivery Generator agent | F23: Yes | G23: String | H23: Valid AgentCore agent ID | I23: Confidential | J23: ML/AI Team | K23: agentcore.input_validator_agent_id | L23: Produces 6 delivery artifacts using Claude Sonnet 4.6 | M23: 2026-06-05
A24: agentcore.code_generator_agent_id | B24: [agentcore-code-gen-id] | C24: [agentcore-code-gen-id] | D24: [agentcore-code-gen-id] | E24: AgentCore Runtime resource ID for the Code Generator agent | F24: Yes | G24: String | H24: Valid AgentCore agent ID | I24: Confidential | J24: ML/AI Team | K24: agentcore.input_validator_agent_id | L24: Produces Terraform IaC bundle; triggers GitHub commit via Secrets Manager PAT | M24: 2026-06-05
A25: agentcore.eo_validator_agent_id | B25: [agentcore-eo-validator-id] | C25: [agentcore-eo-validator-id] | D25: [agentcore-eo-validator-id] | E25: AgentCore Runtime resource ID for the EO Validator agent | F25: Yes | G25: String | H25: Valid AgentCore agent ID | I25: Confidential | J25: ML/AI Team | K25: agentcore.code_generator_agent_id | L25: Runs format-check + Haiku 4.5 quality-check with up to 3 retries per artifact | M25: 2026-06-05

Sheet Monitoring
A1: Monitoring Parameters
A2: Parameter Name | B2: Production | C2: Test | D2: DR | E2: Description | F2: Required | G2: Data Type | H2: Validation Rules | I2: Security Level | J2: Owner Team | K2: Dependencies | L2: Notes | M2: Last Updated
A3: monitoring.cloudwatch_dashboard_name | B3: amatra-prod-health | C3: amatra-dev-health | D3: amatra-prod-health | E3: CloudWatch dashboard name for platform operational metrics | F3: Yes | G3: String | H3: Non-empty alphanumeric hyphens | I3: Public | J3: Operations | K3: solution.region.primary | L3: Accessible via amatra status CLI subcommand per SOW observability design | M3: 2026-06-05
A4: monitoring.log_retention_days | B4: 90 | C4: 30 | D4: 90 | E4: CloudWatch Logs retention period in days for all log groups | F4: Yes | G4: Integer | H4: 1-3653 | I4: Public | J4: Operations | L4: 90-day minimum per SOW Security & Compliance section | M4: 2026-06-05
A5: monitoring.metrics_namespace | B5: AmatraPlatform | C5: AmatraPlatform | D5: AmatraPlatform | E5: CloudWatch custom metrics namespace for token usage and latency | F5: Yes | G5: String | H5: Non-empty string no spaces | I5: Public | J5: Operations | L5: Per-phase token usage emitted here per SOW observability design | M5: 2026-06-05
A6: monitoring.alarm_sns_topic_arn | B6: [sns-alarm-topic-arn] | C6: [sns-alarm-topic-arn] | D6: [sns-alarm-topic-arn] | E6: SNS topic ARN for operational and security CloudWatch alarms | F6: Yes | G6: String | H6: Valid SNS ARN | I6: Confidential | J6: Operations | K6: solution.region.primary | L6: Routes to Amatra security contact and PREDICTif nominated contact | M6: 2026-06-05
A7: monitoring.lambda_error_rate_alarm_threshold | B7: 1 | C7: 5 | D7: 1 | E7: Lambda error rate (%) threshold that triggers a CloudWatch alarm | F7: Yes | G7: Number | H7: 0.01-100 | I7: Public | J7: Operations | K7: monitoring.alarm_sns_topic_arn | L7: 1% prod threshold per SOW green baseline criteria | M7: 2026-06-05
A8: monitoring.stepfunctions_failure_rate_alarm_threshold | B8: 2 | C8: 10 | D8: 2 | E8: Step Functions execution failure rate (%) threshold for alarm | F8: Yes | G8: Number | H8: 0.01-100 | I8: Public | J8: Operations | K8: monitoring.alarm_sns_topic_arn | L8: 2% prod threshold per SOW green baseline criteria | M8: 2026-06-05
A9: monitoring.bedrock_daily_spend_alarm_pct | B9: 110 | C9: 150 | D9: 110 | E9: Daily Bedrock spend as a percentage of daily budget target that triggers alarm | F9: Yes | G9: Integer | H9: 50-500 | I9: Public | J9: Operations | K9: monitoring.alarm_sns_topic_arn,bedrock.monthly_token_budget_millions | L9: 110% threshold per SOW; catches runaway token spend before monthly cap | M9: 2026-06-05
A10: monitoring.token_usage_metric_name | B10: TokenUsage | C10: TokenUsage | D10: TokenUsage | E10: CloudWatch custom metric name for per-phase agent token usage | F10: Yes | G10: String | H10: Non-empty alphanumeric underscores | I10: Public | J10: ML/AI Team | K10: monitoring.metrics_namespace | L10: Surfaced in CLI status command and GET /admin/usage endpoint per SOW | M10: 2026-06-05

Sheet Integration
A1: Integration Parameters
A2: Parameter Name | B2: Production | C2: Test | D2: DR | E2: Description | F2: Required | G2: Data Type | H2: Validation Rules | I2: Security Level | J2: Owner Team | K2: Dependencies | L2: Notes | M2: Last Updated
A3: integration.github.pat | B3: [github-pat] | C3: [github-pat] | D3: [github-pat] | E3: GitHub Personal Access Token for automated artifact commits | F3: Yes | G3: String | H3: Valid GitHub PAT | I3: Secret | J3: Integration Team | K3: secrets.manager.github_pat_secret_name | L3: Stored in Secrets Manager; rotated every 90 days via Lambda rotation function | M3: 2026-06-05
A4: integration.github.repository_url | B4: [github-repo-url] | C4: [github-repo-url] | D4: [github-repo-url] | E4: Public GitHub repository URL for artifact commit and versioning | F4: Yes | G4: String | H4: Valid HTTPS GitHub URL | I4: Confidential | J4: Integration Team | K4: integration.github.pat | L4: Public repo per SOW; write access granted via stored PAT | M4: 2026-06-05
A5: integration.github.default_branch | B5: main | C5: main | D5: main | E5: Default branch for automated artifact commits | F5: Yes | G5: String | H5: Valid git branch name | I5: Public | J5: Integration Team | K5: integration.github.repository_url | M5: 2026-06-05
A6: integration.github.commit_timeout_seconds | B6: 30 | C6: 30 | D6: 30 | E6: Timeout for GitHub API commit calls in seconds | F6: Yes | G6: Integer | H6: 1-300 | I6: Public | J6: Integration Team | K6: integration.github.pat | L6: PAT expiry triggers runbook procedure; resumption within 15 minutes per SOW | M6: 2026-06-05

Sheet Operations
A1: Operations Parameters
A2: Parameter Name | B2: Production | C2: Test | D2: DR | E2: Description | F2: Required | G2: Data Type | H2: Validation Rules | I2: Security Level | J2: Owner Team | K2: Dependencies | L2: Notes | M2: Last Updated
A3: operations.backup_enabled | B3: true | C3: false | D3: true | E3: Enable automated DynamoDB and S3 backup procedures | F3: Yes | G3: Boolean | H3: true|false | I3: Public | J3: Operations | L3: false in dev to reduce cost; PITR and S3 versioning cover prod backup | M3: 2026-06-05
A4: operations.quota_reset_schedule | B4: cron(0 0 1 * ? *) | C4: cron(0 0 1 * ? *) | D4: cron(0 0 1 * ? *) | E4: EventBridge cron expression for monthly quota counter reset Lambda | F4: Yes | G4: String | H4: Valid EventBridge cron expression | I4: Public | J4: Operations | K4: dynamodb.table.user_profiles | L4: Resets per-user and global quota counters at start of each calendar month | M4: 2026-06-05
A5: operations.scaling_min_lambda_concurrency | B5: 1 | C5: 1 | D5: 1 | E5: Minimum Lambda concurrency (reserved) per function | F5: Yes | G5: Integer | H5: 0-1000 | I5: Public | J5: Operations | K5: compute.lambda.reserved_concurrency | M5: 2026-06-05
A6: operations.scaling_max_lambda_concurrency | B6: 50 | C6: 10 | D6: 50 | E6: Maximum Lambda concurrency limit across all platform functions | F6: Yes | G6: Integer | H6: 1-3000 | I6: Public | J6: Operations | K6: operations.scaling_min_lambda_concurrency | L6: Sized for 200 solutions/month with burst headroom per SOW load target | M6: 2026-06-05
A7: operations.rto_hours | B7: 4 | C7: 4 | D7: 4 | E7: Recovery Time Objective in hours for full platform restoration | F7: Yes | G7: Integer | H7: 1-168 | I7: Public | J7: Operations | L7: 4-hour RTO per SOW operational design; serverless multi-AZ baseline | M7: 2026-06-05
A8: operations.rpo_hours | B8: 24 | C8: 24 | D8: 24 | E8: Recovery Point Objective in hours for DynamoDB data | F8: Yes | G8: Integer | H8: 0-168 | I8: Public | J8: Operations | K8: dynamodb.pitr_enabled | L8: 24-hour RPO for DynamoDB; 0-hour RPO for S3 (versioned) per SOW | M8: 2026-06-05
A9: operations.hypercare_weeks | B9: 8 | C9: 0 | D9: 8 | E9: Post-go-live hypercare support period in weeks | F9: Yes | G9: Integer | H9: 0-52 | I9: Public | J9: Operations | L9: Weeks 13-20 per SOW; P1 response 1 hour; P2 response 4 business hours | M9: 2026-06-05
A10: cicd.codepipeline_name | B10: amatra-prod-pipeline | C10: amatra-dev-pipeline | D10: amatra-prod-pipeline | E10: CodePipeline name for Docker image build and ECR push workflow | F10: Yes | G10: String | H10: Alphanumeric hyphens max 100 chars | I10: Confidential | J10: DevOps Team | K10: compute.ecr.repository_name | L10: CI gate: terraform validate must pass in CodeBuild before plan/apply | M10: 2026-06-05
A11: cicd.codebuilld_compute_type | B11: BUILD_GENERAL1_SMALL | C11: BUILD_GENERAL1_SMALL | D11: BUILD_GENERAL1_SMALL | E11: CodeBuild compute type for agent image build and smoke test | F11: Yes | G11: String | H11: BUILD_GENERAL1_SMALL|BUILD_GENERAL1_MEDIUM|BUILD_GENERAL1_LARGE | I11: Public | J11: DevOps Team | K11: cicd.codepipeline_name | L11: SMALL sufficient for Docker build; upgrade to MEDIUM if build times exceed 10 min | M11: 2026-06-05
A12: cicd.terraform_validate_gate | B12: true | C12: true | D12: true | E12: Enforce terraform validate as a CI syntax gate in CodeBuild | F12: Yes | G12: Boolean | H12: true|false | I12: Public | J12: DevOps Team | K12: cicd.codepipeline_name | L12: Mandatory gate per SOW; blocks plan/apply if validation fails | M12: 2026-06-05
