Workbook

Sheet Cover
B3: Configuration Parameters
B5: Generated: | C5: June 09, 2026
B6: Solution: | C6: Tmp5Alxzcob
B7: Customer: | C7: [Customer Name]
B8: Version: | C8: 1.0
B9: Status: | C9: Draft
C12: eoframework.org

Sheet All Parameters (Read Only)
A1: Total Parameters | B1: Categories | C1: Required | D1: Confidential/Secret
A2: 101 | B2: 11 | C2: 101 | D2: 30
A4: Parameter Name | B4: Category | C4: Production | D4: Test | E4: DR | F4: Description | G4: Required | H4: Data Type | I4: Validation Rules | J4: Security Level | K4: Owner Team | L4: Dependencies | M4: Notes | N4: Last Updated
A5: =IF('Project'!A3="","",'Project'!A3) | B5: Project | C5: =IF('Project'!B3="","",'Project'!B3) | D5: =IF('Project'!C3="","",'Project'!C3) | E5: =IF('Project'!D3="","",'Project'!D3) | F5: =IF('Project'!E3="","",'Project'!E3) | G5: =IF('Project'!F3="","",'Project'!F3) | H5: =IF('Project'!G3="","",'Project'!G3) | I5: =IF('Project'!H3="","",'Project'!H3) | J5: =IF('Project'!I3="","",'Project'!I3) | ... N5: =IF('Project'!M3="","",'Project'!M3)
A6: =IF('Project'!A4="","",'Project'!A4) | B6: Project | C6: =IF('Project'!B4="","",'Project'!B4) | D6: =IF('Project'!C4="","",'Project'!C4) | E6: =IF('Project'!D4="","",'Project'!D4) | F6: =IF('Project'!E4="","",'Project'!E4) | G6: =IF('Project'!F4="","",'Project'!F4) | H6: =IF('Project'!G4="","",'Project'!G4) | I6: =IF('Project'!H4="","",'Project'!H4) | J6: =IF('Project'!I4="","",'Project'!I4) | ... N6: =IF('Project'!M4="","",'Project'!M4)
A7: =IF('Project'!A5="","",'Project'!A5) | B7: Project | C7: =IF('Project'!B5="","",'Project'!B5) | D7: =IF('Project'!C5="","",'Project'!C5) | E7: =IF('Project'!D5="","",'Project'!D5) | F7: =IF('Project'!E5="","",'Project'!E5) | G7: =IF('Project'!F5="","",'Project'!F5) | H7: =IF('Project'!G5="","",'Project'!G5) | I7: =IF('Project'!H5="","",'Project'!H5) | J7: =IF('Project'!I5="","",'Project'!I5) | ... N7: =IF('Project'!M5="","",'Project'!M5)
A8: =IF('Project'!A6="","",'Project'!A6) | B8: Project | C8: =IF('Project'!B6="","",'Project'!B6) | D8: =IF('Project'!C6="","",'Project'!C6) | E8: =IF('Project'!D6="","",'Project'!D6) | F8: =IF('Project'!E6="","",'Project'!E6) | G8: =IF('Project'!F6="","",'Project'!F6) | H8: =IF('Project'!G6="","",'Project'!G6) | I8: =IF('Project'!H6="","",'Project'!H6) | J8: =IF('Project'!I6="","",'Project'!I6) | ... N8: =IF('Project'!M6="","",'Project'!M6)
A9: =IF('Project'!A7="","",'Project'!A7) | B9: Project | C9: =IF('Project'!B7="","",'Project'!B7) | D9: =IF('Project'!C7="","",'Project'!C7) | E9: =IF('Project'!D7="","",'Project'!D7) | F9: =IF('Project'!E7="","",'Project'!E7) | G9: =IF('Project'!F7="","",'Project'!F7) | H9: =IF('Project'!G7="","",'Project'!G7) | I9: =IF('Project'!H7="","",'Project'!H7) | J9: =IF('Project'!I7="","",'Project'!I7) | ... N9: =IF('Project'!M7="","",'Project'!M7)
A10: =IF('Project'!A8="","",'Project'!A8) | B10: Project | C10: =IF('Project'!B8="","",'Project'!B8) | D10: =IF('Project'!C8="","",'Project'!C8) | E10: =IF('Project'!D8="","",'Project'!D8) | F10: =IF('Project'!E8="","",'Project'!E8) | G10: =IF('Project'!F8="","",'Project'!F8) | H10: =IF('Project'!G8="","",'Project'!G8) | I10: =IF('Project'!H8="","",'Project'!H8) | J10: =IF('Project'!I8="","",'Project'!I8) | ... N10: =IF('Project'!M8="","",'Project'!M8)
A11: =IF('Project'!A9="","",'Project'!A9) | B11: Project | C11: =IF('Project'!B9="","",'Project'!B9) | D11: =IF('Project'!C9="","",'Project'!C9) | E11: =IF('Project'!D9="","",'Project'!D9) | F11: =IF('Project'!E9="","",'Project'!E9) | G11: =IF('Project'!F9="","",'Project'!F9) | H11: =IF('Project'!G9="","",'Project'!G9) | I11: =IF('Project'!H9="","",'Project'!H9) | J11: =IF('Project'!I9="","",'Project'!I9) | ... N11: =IF('Project'!M9="","",'Project'!M9)
A12: =IF('Project'!A10="","",'Project'!A10) | B12: Project | C12: =IF('Project'!B10="","",'Project'!B10) | D12: =IF('Project'!C10="","",'Project'!C10) | E12: =IF('Project'!D10="","",'Project'!D10) | F12: =IF('Project'!E10="","",'Project'!E10) | G12: =IF('Project'!F10="","",'Project'!F10) | H12: =IF('Project'!G10="","",'Project'!G10) | I12: =IF('Project'!H10="","",'Project'!H10) | J12: =IF('Project'!I10="","",'Project'!I10) | ... N12: =IF('Project'!M10="","",'Project'!M10)
A13: =IF('Project'!A11="","",'Project'!A11) | B13: Project | C13: =IF('Project'!B11="","",'Project'!B11) | D13: =IF('Project'!C11="","",'Project'!C11) | E13: =IF('Project'!D11="","",'Project'!D11) | F13: =IF('Project'!E11="","",'Project'!E11) | G13: =IF('Project'!F11="","",'Project'!F11) | H13: =IF('Project'!G11="","",'Project'!G11) | I13: =IF('Project'!H11="","",'Project'!H11) | J13: =IF('Project'!I11="","",'Project'!I11) | ... N13: =IF('Project'!M11="","",'Project'!M11)
A14: =IF('Networking'!A3="","",'Networking'!A3) | B14: Networking | C14: =IF('Networking'!B3="","",'Networking'!B3) | D14: =IF('Networking'!C3="","",'Networking'!C3) | E14: =IF('Networking'!D3="","",'Networking'!D3) | F14: =IF('Networking'!E3="","",'Networking'!E3) | G14: =IF('Networking'!F3="","",'Networking'!F3) | H14: =IF('Networking'!G3="","",'Networking'!G3) | I14: =IF('Networking'!H3="","",'Networking'!H3) | J14: =IF('Networking'!I3="","",'Networking'!I3) | ... N14: =IF('Networking'!M3="","",'Networking'!M3)
A15: =IF('Networking'!A4="","",'Networking'!A4) | B15: Networking | C15: =IF('Networking'!B4="","",'Networking'!B4) | D15: =IF('Networking'!C4="","",'Networking'!C4) | E15: =IF('Networking'!D4="","",'Networking'!D4) | F15: =IF('Networking'!E4="","",'Networking'!E4) | G15: =IF('Networking'!F4="","",'Networking'!F4) | H15: =IF('Networking'!G4="","",'Networking'!G4) | I15: =IF('Networking'!H4="","",'Networking'!H4) | J15: =IF('Networking'!I4="","",'Networking'!I4) | ... N15: =IF('Networking'!M4="","",'Networking'!M4)
A16: =IF('Networking'!A5="","",'Networking'!A5) | B16: Networking | C16: =IF('Networking'!B5="","",'Networking'!B5) | D16: =IF('Networking'!C5="","",'Networking'!C5) | E16: =IF('Networking'!D5="","",'Networking'!D5) | F16: =IF('Networking'!E5="","",'Networking'!E5) | G16: =IF('Networking'!F5="","",'Networking'!F5) | H16: =IF('Networking'!G5="","",'Networking'!G5) | I16: =IF('Networking'!H5="","",'Networking'!H5) | J16: =IF('Networking'!I5="","",'Networking'!I5) | ... N16: =IF('Networking'!M5="","",'Networking'!M5)
A17: =IF('Networking'!A6="","",'Networking'!A6) | B17: Networking | C17: =IF('Networking'!B6="","",'Networking'!B6) | D17: =IF('Networking'!C6="","",'Networking'!C6) | E17: =IF('Networking'!D6="","",'Networking'!D6) | F17: =IF('Networking'!E6="","",'Networking'!E6) | G17: =IF('Networking'!F6="","",'Networking'!F6) | H17: =IF('Networking'!G6="","",'Networking'!G6) | I17: =IF('Networking'!H6="","",'Networking'!H6) | J17: =IF('Networking'!I6="","",'Networking'!I6) | ... N17: =IF('Networking'!M6="","",'Networking'!M6)
A18: =IF('Networking'!A7="","",'Networking'!A7) | B18: Networking | C18: =IF('Networking'!B7="","",'Networking'!B7) | D18: =IF('Networking'!C7="","",'Networking'!C7) | E18: =IF('Networking'!D7="","",'Networking'!D7) | F18: =IF('Networking'!E7="","",'Networking'!E7) | G18: =IF('Networking'!F7="","",'Networking'!F7) | H18: =IF('Networking'!G7="","",'Networking'!G7) | I18: =IF('Networking'!H7="","",'Networking'!H7) | J18: =IF('Networking'!I7="","",'Networking'!I7) | ... N18: =IF('Networking'!M7="","",'Networking'!M7)
A19: =IF('Networking'!A8="","",'Networking'!A8) | B19: Networking | C19: =IF('Networking'!B8="","",'Networking'!B8) | D19: =IF('Networking'!C8="","",'Networking'!C8) | E19: =IF('Networking'!D8="","",'Networking'!D8) | F19: =IF('Networking'!E8="","",'Networking'!E8) | G19: =IF('Networking'!F8="","",'Networking'!F8) | H19: =IF('Networking'!G8="","",'Networking'!G8) | I19: =IF('Networking'!H8="","",'Networking'!H8) | J19: =IF('Networking'!I8="","",'Networking'!I8) | ... N19: =IF('Networking'!M8="","",'Networking'!M8)
A20: =IF('Networking'!A9="","",'Networking'!A9) | B20: Networking | C20: =IF('Networking'!B9="","",'Networking'!B9) | D20: =IF('Networking'!C9="","",'Networking'!C9) | E20: =IF('Networking'!D9="","",'Networking'!D9) | F20: =IF('Networking'!E9="","",'Networking'!E9) | G20: =IF('Networking'!F9="","",'Networking'!F9) | H20: =IF('Networking'!G9="","",'Networking'!G9) | I20: =IF('Networking'!H9="","",'Networking'!H9) | J20: =IF('Networking'!I9="","",'Networking'!I9) | ... N20: =IF('Networking'!M9="","",'Networking'!M9)
A21: =IF('Networking'!A10="","",'Networking'!A10) | B21: Networking | C21: =IF('Networking'!B10="","",'Networking'!B10) | D21: =IF('Networking'!C10="","",'Networking'!C10) | E21: =IF('Networking'!D10="","",'Networking'!D10) | F21: =IF('Networking'!E10="","",'Networking'!E10) | G21: =IF('Networking'!F10="","",'Networking'!F10) | H21: =IF('Networking'!G10="","",'Networking'!G10) | I21: =IF('Networking'!H10="","",'Networking'!H10) | J21: =IF('Networking'!I10="","",'Networking'!I10) | ... N21: =IF('Networking'!M10="","",'Networking'!M10)
A22: =IF('Networking'!A11="","",'Networking'!A11) | B22: Networking | C22: =IF('Networking'!B11="","",'Networking'!B11) | D22: =IF('Networking'!C11="","",'Networking'!C11) | E22: =IF('Networking'!D11="","",'Networking'!D11) | F22: =IF('Networking'!E11="","",'Networking'!E11) | G22: =IF('Networking'!F11="","",'Networking'!F11) | H22: =IF('Networking'!G11="","",'Networking'!G11) | I22: =IF('Networking'!H11="","",'Networking'!H11) | J22: =IF('Networking'!I11="","",'Networking'!I11) | ... N22: =IF('Networking'!M11="","",'Networking'!M11)
A23: =IF('Networking'!A12="","",'Networking'!A12) | B23: Networking | C23: =IF('Networking'!B12="","",'Networking'!B12) | D23: =IF('Networking'!C12="","",'Networking'!C12) | E23: =IF('Networking'!D12="","",'Networking'!D12) | F23: =IF('Networking'!E12="","",'Networking'!E12) | G23: =IF('Networking'!F12="","",'Networking'!F12) | H23: =IF('Networking'!G12="","",'Networking'!G12) | I23: =IF('Networking'!H12="","",'Networking'!H12) | J23: =IF('Networking'!I12="","",'Networking'!I12) | ... N23: =IF('Networking'!M12="","",'Networking'!M12)
A24: =IF('Networking'!A13="","",'Networking'!A13) | B24: Networking | C24: =IF('Networking'!B13="","",'Networking'!B13) | D24: =IF('Networking'!C13="","",'Networking'!C13) | E24: =IF('Networking'!D13="","",'Networking'!D13) | F24: =IF('Networking'!E13="","",'Networking'!E13) | G24: =IF('Networking'!F13="","",'Networking'!F13) | H24: =IF('Networking'!G13="","",'Networking'!G13) | I24: =IF('Networking'!H13="","",'Networking'!H13) | J24: =IF('Networking'!I13="","",'Networking'!I13) | ... N24: =IF('Networking'!M13="","",'Networking'!M13)
A25: =IF('Security'!A3="","",'Security'!A3) | B25: Security | C25: =IF('Security'!B3="","",'Security'!B3) | D25: =IF('Security'!C3="","",'Security'!C3) | E25: =IF('Security'!D3="","",'Security'!D3) | F25: =IF('Security'!E3="","",'Security'!E3) | G25: =IF('Security'!F3="","",'Security'!F3) | H25: =IF('Security'!G3="","",'Security'!G3) | I25: =IF('Security'!H3="","",'Security'!H3) | J25: =IF('Security'!I3="","",'Security'!I3) | ... N25: =IF('Security'!M3="","",'Security'!M3)
A26: =IF('Security'!A4="","",'Security'!A4) | B26: Security | C26: =IF('Security'!B4="","",'Security'!B4) | D26: =IF('Security'!C4="","",'Security'!C4) | E26: =IF('Security'!D4="","",'Security'!D4) | F26: =IF('Security'!E4="","",'Security'!E4) | G26: =IF('Security'!F4="","",'Security'!F4) | H26: =IF('Security'!G4="","",'Security'!G4) | I26: =IF('Security'!H4="","",'Security'!H4) | J26: =IF('Security'!I4="","",'Security'!I4) | ... N26: =IF('Security'!M4="","",'Security'!M4)
A27: =IF('Security'!A5="","",'Security'!A5) | B27: Security | C27: =IF('Security'!B5="","",'Security'!B5) | D27: =IF('Security'!C5="","",'Security'!C5) | E27: =IF('Security'!D5="","",'Security'!D5) | F27: =IF('Security'!E5="","",'Security'!E5) | G27: =IF('Security'!F5="","",'Security'!F5) | H27: =IF('Security'!G5="","",'Security'!G5) | I27: =IF('Security'!H5="","",'Security'!H5) | J27: =IF('Security'!I5="","",'Security'!I5) | ... N27: =IF('Security'!M5="","",'Security'!M5)
A28: =IF('Security'!A6="","",'Security'!A6) | B28: Security | C28: =IF('Security'!B6="","",'Security'!B6) | D28: =IF('Security'!C6="","",'Security'!C6) | E28: =IF('Security'!D6="","",'Security'!D6) | F28: =IF('Security'!E6="","",'Security'!E6) | G28: =IF('Security'!F6="","",'Security'!F6) | H28: =IF('Security'!G6="","",'Security'!G6) | I28: =IF('Security'!H6="","",'Security'!H6) | J28: =IF('Security'!I6="","",'Security'!I6) | ... N28: =IF('Security'!M6="","",'Security'!M6)
A29: =IF('Security'!A7="","",'Security'!A7) | B29: Security | C29: =IF('Security'!B7="","",'Security'!B7) | D29: =IF('Security'!C7="","",'Security'!C7) | E29: =IF('Security'!D7="","",'Security'!D7) | F29: =IF('Security'!E7="","",'Security'!E7) | G29: =IF('Security'!F7="","",'Security'!F7) | H29: =IF('Security'!G7="","",'Security'!G7) | I29: =IF('Security'!H7="","",'Security'!H7) | J29: =IF('Security'!I7="","",'Security'!I7) | ... N29: =IF('Security'!M7="","",'Security'!M7)
A30: =IF('Security'!A8="","",'Security'!A8) | B30: Security | C30: =IF('Security'!B8="","",'Security'!B8) | D30: =IF('Security'!C8="","",'Security'!C8) | E30: =IF('Security'!D8="","",'Security'!D8) | F30: =IF('Security'!E8="","",'Security'!E8) | G30: =IF('Security'!F8="","",'Security'!F8) | H30: =IF('Security'!G8="","",'Security'!G8) | I30: =IF('Security'!H8="","",'Security'!H8) | J30: =IF('Security'!I8="","",'Security'!I8) | ... N30: =IF('Security'!M8="","",'Security'!M8)
A31: =IF('Security'!A9="","",'Security'!A9) | B31: Security | C31: =IF('Security'!B9="","",'Security'!B9) | D31: =IF('Security'!C9="","",'Security'!C9) | E31: =IF('Security'!D9="","",'Security'!D9) | F31: =IF('Security'!E9="","",'Security'!E9) | G31: =IF('Security'!F9="","",'Security'!F9) | H31: =IF('Security'!G9="","",'Security'!G9) | I31: =IF('Security'!H9="","",'Security'!H9) | J31: =IF('Security'!I9="","",'Security'!I9) | ... N31: =IF('Security'!M9="","",'Security'!M9)
A32: =IF('Security'!A10="","",'Security'!A10) | B32: Security | C32: =IF('Security'!B10="","",'Security'!B10) | D32: =IF('Security'!C10="","",'Security'!C10) | E32: =IF('Security'!D10="","",'Security'!D10) | F32: =IF('Security'!E10="","",'Security'!E10) | G32: =IF('Security'!F10="","",'Security'!F10) | H32: =IF('Security'!G10="","",'Security'!G10) | I32: =IF('Security'!H10="","",'Security'!H10) | J32: =IF('Security'!I10="","",'Security'!I10) | ... N32: =IF('Security'!M10="","",'Security'!M10)
A33: =IF('Security'!A11="","",'Security'!A11) | B33: Security | C33: =IF('Security'!B11="","",'Security'!B11) | D33: =IF('Security'!C11="","",'Security'!C11) | E33: =IF('Security'!D11="","",'Security'!D11) | F33: =IF('Security'!E11="","",'Security'!E11) | G33: =IF('Security'!F11="","",'Security'!F11) | H33: =IF('Security'!G11="","",'Security'!G11) | I33: =IF('Security'!H11="","",'Security'!H11) | J33: =IF('Security'!I11="","",'Security'!I11) | ... N33: =IF('Security'!M11="","",'Security'!M11)
A34: =IF('Security'!A12="","",'Security'!A12) | B34: Security | C34: =IF('Security'!B12="","",'Security'!B12) | D34: =IF('Security'!C12="","",'Security'!C12) | E34: =IF('Security'!D12="","",'Security'!D12) | F34: =IF('Security'!E12="","",'Security'!E12) | G34: =IF('Security'!F12="","",'Security'!F12) | H34: =IF('Security'!G12="","",'Security'!G12) | I34: =IF('Security'!H12="","",'Security'!H12) | J34: =IF('Security'!I12="","",'Security'!I12) | ... N34: =IF('Security'!M12="","",'Security'!M12)
A35: =IF('Security'!A13="","",'Security'!A13) | B35: Security | C35: =IF('Security'!B13="","",'Security'!B13) | D35: =IF('Security'!C13="","",'Security'!C13) | E35: =IF('Security'!D13="","",'Security'!D13) | F35: =IF('Security'!E13="","",'Security'!E13) | G35: =IF('Security'!F13="","",'Security'!F13) | H35: =IF('Security'!G13="","",'Security'!G13) | I35: =IF('Security'!H13="","",'Security'!H13) | J35: =IF('Security'!I13="","",'Security'!I13) | ... N35: =IF('Security'!M13="","",'Security'!M13)
A36: =IF('Security'!A14="","",'Security'!A14) | B36: Security | C36: =IF('Security'!B14="","",'Security'!B14) | D36: =IF('Security'!C14="","",'Security'!C14) | E36: =IF('Security'!D14="","",'Security'!D14) | F36: =IF('Security'!E14="","",'Security'!E14) | G36: =IF('Security'!F14="","",'Security'!F14) | H36: =IF('Security'!G14="","",'Security'!G14) | I36: =IF('Security'!H14="","",'Security'!H14) | J36: =IF('Security'!I14="","",'Security'!I14) | ... N36: =IF('Security'!M14="","",'Security'!M14)
... A45: =IF('Security'!A23="","",'Security'!A23) | B45: Security | C45: =IF('Security'!B23="","",'Security'!B23) | D45: =IF('Security'!C23="","",'Security'!C23) | E45: =IF('Security'!D23="","",'Security'!D23) | F45: =IF('Security'!E23="","",'Security'!E23) | G45: =IF('Security'!F23="","",'Security'!F23) | H45: =IF('Security'!G23="","",'Security'!G23) | I45: =IF('Security'!H23="","",'Security'!H23) | J45: =IF('Security'!I23="","",'Security'!I23) | ... N45: =IF('Security'!M23="","",'Security'!M23)
A46: =IF('Compute'!A3="","",'Compute'!A3) | B46: Compute | C46: =IF('Compute'!B3="","",'Compute'!B3) | D46: =IF('Compute'!C3="","",'Compute'!C3) | E46: =IF('Compute'!D3="","",'Compute'!D3) | F46: =IF('Compute'!E3="","",'Compute'!E3) | G46: =IF('Compute'!F3="","",'Compute'!F3) | H46: =IF('Compute'!G3="","",'Compute'!G3) | I46: =IF('Compute'!H3="","",'Compute'!H3) | J46: =IF('Compute'!I3="","",'Compute'!I3) | ... N46: =IF('Compute'!M3="","",'Compute'!M3)
A47: =IF('Compute'!A4="","",'Compute'!A4) | B47: Compute | C47: =IF('Compute'!B4="","",'Compute'!B4) | D47: =IF('Compute'!C4="","",'Compute'!C4) | E47: =IF('Compute'!D4="","",'Compute'!D4) | F47: =IF('Compute'!E4="","",'Compute'!E4) | G47: =IF('Compute'!F4="","",'Compute'!F4) | H47: =IF('Compute'!G4="","",'Compute'!G4) | I47: =IF('Compute'!H4="","",'Compute'!H4) | J47: =IF('Compute'!I4="","",'Compute'!I4) | ... N47: =IF('Compute'!M4="","",'Compute'!M4)
A48: =IF('Compute'!A5="","",'Compute'!A5) | B48: Compute | C48: =IF('Compute'!B5="","",'Compute'!B5) | D48: =IF('Compute'!C5="","",'Compute'!C5) | E48: =IF('Compute'!D5="","",'Compute'!D5) | F48: =IF('Compute'!E5="","",'Compute'!E5) | G48: =IF('Compute'!F5="","",'Compute'!F5) | H48: =IF('Compute'!G5="","",'Compute'!G5) | I48: =IF('Compute'!H5="","",'Compute'!H5) | J48: =IF('Compute'!I5="","",'Compute'!I5) | ... N48: =IF('Compute'!M5="","",'Compute'!M5)
A49: =IF('Compute'!A6="","",'Compute'!A6) | B49: Compute | C49: =IF('Compute'!B6="","",'Compute'!B6) | D49: =IF('Compute'!C6="","",'Compute'!C6) | E49: =IF('Compute'!D6="","",'Compute'!D6) | F49: =IF('Compute'!E6="","",'Compute'!E6) | G49: =IF('Compute'!F6="","",'Compute'!F6) | H49: =IF('Compute'!G6="","",'Compute'!G6) | I49: =IF('Compute'!H6="","",'Compute'!H6) | J49: =IF('Compute'!I6="","",'Compute'!I6) | ... N49: =IF('Compute'!M6="","",'Compute'!M6)
...

Sheet Project
A1: Project Parameters
A2: Parameter Name | B2: Production | C2: Test | D2: DR | E2: Description | F2: Required | G2: Data Type | H2: Validation Rules | I2: Security Level | J2: Owner Team | K2: Dependencies | L2: Notes | M2: Last Updated
A3: solution.name | B3: aws-governance-platform | C3: aws-governance-platform | D3: aws-governance-platform | E3: Solution identifier used for resource naming and tagging across all accounts | F3: Yes | G3: String | H3: lowercase alphanumeric hyphens only | I3: Public | J3: Cloud CoE | L3: Must match AFT pipeline variable and all Terraform module references | M3: 2025-06-01
A4: solution.region.primary | B4: ap-southeast-2 | C4: ap-southeast-2 | D4: ap-southeast-4 | E4: Primary AWS region for all solution resources; DR uses ap-southeast-4 | F4: Yes | G4: String | H4: Valid AWS region code | I4: Public | J4: Cloud CoE | L4: Region-lock SCP enforces ap-southeast-2 and ap-southeast-4 only — data sovereignty requirement | M4: 2025-06-01
A5: solution.environment | B5: prod | C5: nonprod | D5: prod | E5: Deployment environment identifier used in resource tagging and SCP conditions | F5: Yes | G5: String | H5: prod|nonprod|sandbox | I5: Public | J5: Cloud CoE | L5: DR environment mirrors production configuration | M5: 2025-06-01
A6: aws.account_id.log_archive | B6: [account-id] | C6: [account-id] | D6: [account-id] | E6: AWS Log Archive account identifier hosting centralised CloudTrail and Config S3 buckets | F6: Yes | G6: String | H6: 12-digit numeric | I6: Confidential | J6: Cloud CoE | K6: solution.region.primary | L6: Receives CloudTrail and Config delivery from all member accounts | M6: 2025-06-01
A7: aws.account_id.audit | B7: [account-id] | C7: [account-id] | D7: [account-id] | E7: AWS Audit account identifier hosting Security Hub aggregator and GuardDuty org detector | F7: Yes | G7: String | H7: 12-digit numeric | I7: Confidential | J7: Cloud CoE | K7: solution.region.primary | L7: Delegated admin account for Security Hub and GuardDuty org services | M7: 2025-06-01
A8: aws.account_id.security | B8: [account-id] | C8: [account-id] | D8: [account-id] | E8: AWS Security account identifier hosting IAM Identity Center SSO portal and SAML connector | F8: Yes | G8: String | H8: 12-digit numeric | I8: Confidential | J8: Cloud CoE | K8: solution.region.primary | L8: Hosts IAM Identity Center — org-level SSO service deployed here | M8: 2025-06-01
A9: aws.account_id.network | B9: [account-id] | C9: [account-id] | D9: [account-id] | E9: AWS Network account identifier hosting Transit Gateway and Network Firewall | F9: Yes | G9: String | H9: 12-digit numeric | I9: Confidential | J9: Cloud CoE | K9: solution.region.primary | L9: Hub account for all inter-account and on-premises traffic routing | M9: 2025-06-01
A10: aws.organizations.id | B10: [org-id] | C10: [org-id] | D10: [org-id] | E10: AWS Organizations root organisation ID used by Control Tower and SCP targeting | F10: Yes | G10: String | H10: ^o-[a-z0-9]{10,32}$ | I10: Confidential | J10: Cloud CoE | K10: aws.account_id.management | L10: Required for EventBridge org event bus rules and GuardDuty org detector configuration | M10: 2025-06-01
A11: aws.control_tower.home_region | B11: ap-southeast-2 | C11: ap-southeast-2 | D11: ap-southeast-2 | E11: AWS Control Tower home region; must match solution.region.primary | F11: Yes | G11: String | H11: Valid AWS region code | I11: Public | J11: Cloud CoE | K11: solution.region.primary | L11: Control Tower home region cannot change post-deployment without full re-deployment | M11: 2025-06-01

Sheet Networking
A1: Networking Parameters
A2: Parameter Name | B2: Production | C2: Test | D2: DR | E2: Description | F2: Required | G2: Data Type | H2: Validation Rules | I2: Security Level | J2: Owner Team | K2: Dependencies | L2: Notes | M2: Last Updated
A3: networking.transit_gateway.primary_id | B3: [tgw-id] | C3: [tgw-id] | D3: [tgw-id] | E3: AWS Transit Gateway ID in ap-southeast-2 (primary) for hub-spoke routing | F3: Yes | G3: String | H3: ^tgw-[a-f0-9]{17}$ | I3: Confidential | J3: Network Team | K3: aws.account_id.network | L3: Central hub for all inter-account and on-premises traffic; hosted in Network account | M3: 2025-06-01
A4: networking.transit_gateway.dr_id | B4: [tgw-id] | C4: [tgw-id] | D4: [tgw-id] | E4: AWS Transit Gateway ID in ap-southeast-4 (DR) for failover connectivity | F4: Yes | G4: String | H4: ^tgw-[a-f0-9]{17}$ | I4: Confidential | J4: Network Team | K4: aws.account_id.network | L4: Activated during DR failover drill and regional failover events; mirrors primary TGW route tables | M4: 2025-06-01
A5: networking.vpc.cidr_network_account | B5: 10.0.0.0/24 | C5: 10.0.0.0/24 | D5: 10.1.0.0/24 | E5: VPC CIDR block for the Network Account inspection VPC | F5: Yes | G5: String | H5: Valid CIDR /24 or smaller | I5: Confidential | J5: Network Team | K5: networking.transit_gateway.primary_id | L5: Dedicated /24 for Network Account; must not overlap with any workload account CIDR allocations | M5: 2025-06-01
A6: networking.vpc.cidr_master_pool | B6: 10.0.0.0/16 | C6: 10.0.0.0/16 | D6: 10.1.0.0/16 | E6: Master RFC 1918 address pool from which workload account VPC /24s are allocated by AFT | F6: Yes | G6: String | H6: Valid CIDR /16 or smaller | I6: Confidential | J6: Network Team | K6: aft.pipeline.itsm_approval_required | L6: Centrally managed to prevent route conflicts; AFT account customisation allocates /24 per new account | M6: 2025-06-01
A7: networking.nat_gateway.count | B7: 2 | C7: 1 | D7: 2 | E7: Number of NAT Gateway instances deployed in the Network Account for outbound patch traffic | F7: Yes | G7: Integer | H7: 1-3 | I7: Public | J7: Network Team | K7: networking.vpc.cidr_network_account | L7: 2 NAT Gateways for production HA (one per AZ); 1 for nonprod cost saving; workload VPCs have no IGW | M7: 2025-06-01
A8: networking.direct_connect.primary_bandwidth_gbps | B8: 1 | C8: 1 | D8: 1 | E8: Bandwidth in Gbps for the primary AWS Direct Connect hosted connection in ap-southeast-2 | F8: Yes | G8: Integer | H8: 1-100 | I8: Public | J8: Network Team | K8: aws.account_id.network | L8: SOW: 1 Gbps hosted connection; ordered by Contoso Financial before Phase 2 start (Week 7) | M8: 2025-06-01
A9: networking.direct_connect.dr_bandwidth_gbps | B9: 1 | C9: 1 | D9: 1 | E9: Bandwidth in Gbps for the DR AWS Direct Connect hosted connection in ap-southeast-4 | F9: Yes | G9: Integer | H9: 1-100 | I9: Public | J9: Network Team | K9: aws.account_id.network | L9: SOW: 1 Gbps hosted connection to ap-southeast-4; VPN provides backup path if circuit unavailable | M9: 2025-06-01
A10: networking.direct_connect.macsec_enabled | B10: true | C10: true | D10: true | E10: Enable MACsec encryption on both Direct Connect hosted connections | F10: Yes | G10: Boolean | H10: true|false | I10: Public | J10: Network Team | K10: networking.direct_connect.primary_bandwidth_gbps | L10: ISO 27001 A.13 in-transit encryption requirement for private circuit; L2 MACsec per SOW security design | M10: 2025-06-01
A11: networking.vpn.backup_enabled | B11: true | C11: true | D11: true | E11: Enable Site-to-Site VPN as resilient backup path for management and federation traffic | F11: Yes | G11: Boolean | H11: true|false | I11: Public | J11: Network Team | K11: networking.direct_connect.primary_bandwidth_gbps | L11: VPN activated automatically if Direct Connect BGP session drops (BFD sub-second failover detection) | M11: 2025-06-01
A12: networking.firewall.inspection_enabled | B12: true | C12: true | D12: true | E12: Enable AWS Network Firewall stateful inspection for all east-west and on-premises traffic | F12: Yes | G12: Boolean | H12: true|false | I12: Public | J12: Network Team | K12: networking.transit_gateway.primary_id | L12: Network Firewall deployed in 2 AZs (ap-southeast-2a and ap-southeast-2b) for HA | M12: 2025-06-01
A13: networking.vpc_endpoints.enabled_services | B13: s3,ssm,ssmmessages,ec2messages,kms,secretsmanager,config,cloudtrail | C13: s3,ssm,ssmmessages,ec2messages,kms,secretsmanager,config,cloudtrail | D13: s3,ssm,ssmmessages,ec2messages,kms,secretsmanager,config,cloudtrail | E13: Comma-separated list of AWS services with interface VPC endpoints in all workload accounts | F13: Yes | G13: List(String) | H13: Valid AWS service names | I13: Public | J13: Network Team | K13: networking.vpc.cidr_master_pool | L13: Ensures all service API calls stay on AWS private network; no internet traversal for platform services | M13: 2025-06-01

Sheet Security
A1: Security Parameters
A2: Parameter Name | B2: Production | C2: Test | D2: DR | E2: Description | F2: Required | G2: Data Type | H2: Validation Rules | I2: Security Level | J2: Owner Team | K2: Dependencies | L2: Notes | M2: Last Updated
A3: security.kms.log_archive_key_arn | B3: [kms-key-arn] | C3: [kms-key-arn] | D3: [kms-key-arn] | E3: KMS CMK ARN used to encrypt the Log Archive S3 bucket (CloudTrail and Config logs) | F3: Yes | G3: String | H3: Valid KMS key ARN | I3: Secret | J3: Security Team | K3: aws.account_id.log_archive | L3: Stored in Secrets Manager; annual auto-rotation enabled; no human identity has direct admin access in prod | M3: 2025-06-01
A4: security.kms.terraform_state_key_arn | B4: [kms-key-arn] | C4: [kms-key-arn] | D4: [kms-key-arn] | E4: KMS CMK ARN used to encrypt the Terraform state S3 bucket | F4: Yes | G4: String | H4: Valid KMS key ARN | I4: Secret | J4: Security Team | K4: aws.account_id.management | L4: Stored in Secrets Manager; annual auto-rotation enabled; rotation schedule tracked in Secrets Manager | M4: 2025-06-01
A5: security.kms.aft_dynamodb_key_arn | B5: [kms-key-arn] | C5: [kms-key-arn] | D5: [kms-key-arn] | E5: KMS CMK ARN used to encrypt the AFT workflow DynamoDB table | F5: Yes | G5: String | H5: Valid KMS key ARN | I5: Secret | J5: Security Team | K5: database.aft_workflow.table_name | L5: Stored in Secrets Manager; decryption restricted to AFT pipeline IAM role only | M5: 2025-06-01
A6: security.kms.rotation_enabled | B6: true | C6: true | D6: true | E6: Enable automatic annual KMS CMK rotation for all platform keys | F6: Yes | G6: Boolean | H6: true|false | I6: Public | J6: Security Team | K6: security.kms.log_archive_key_arn | L6: ISO 27001 A.10 key management requirement; annual rotation via KMS automatic rotation feature | M6: 2025-06-01
A7: security.cloudtrail.log_retention_years | B7: 1 | C7: 1 | D7: 1 | E7: CloudTrail log retention in years enforced via S3 Object Lock Compliance mode | F7: Yes | G7: Integer | H7: 1-10 | I7: Public | J7: Security Team | K7: storage.log_archive.object_lock_mode | L7: SOW scope: 12-month tamper-evident retention for regulatory evidence; maps to ISO 27001 A.12.4 | M7: 2025-06-01
A8: security.cloudtrail.log_integrity_enabled | B8: true | C8: true | D8: true | E8: Enable SHA-256 CloudTrail log file integrity validation | F8: Yes | G8: Boolean | H8: true|false | I8: Public | J8: Security Team | K8: security.cloudtrail.log_retention_years | L8: Required for tamper-evident audit trail; digest files included in regulatory evidence package | M8: 2025-06-01
A9: security.mfa_enabled | B9: true | C9: true | D9: true | E9: Require MFA enforced at on-premises IdP before SAML assertions issued to AWS | F9: Yes | G9: Boolean | H9: true|false | I9: Public | J9: Security Team | K9: identity.sso.saml_idp_metadata_url | L9: MFA enforced at IdP level — cannot be bypassed at AWS layer; no AWS-level MFA fallback permitted | M9: 2025-06-01
A10: security.session_timeout_minutes | B10: 60 | C10: 120 | D10: 60 | E10: Maximum IAM Identity Center SSO session duration in minutes for standard roles | F10: Yes | G10: Integer | H10: 5-480 | I10: Public | J10: Security Team | K10: identity.sso.permission_set.breakglass_session_minutes | L10: SOW: BreakGlass role limited to 4-hour (240 min) max; standard roles use 60 min in production | M10: 2025-06-01
A11: security.console_access_blocked_in_prod | B11: true | C11: false | D11: true | E11: SCP deny for IAM user creation and console sign-in enforced in production OU | F11: Yes | G11: Boolean | H11: true|false | I11: Public | J11: Security Team | K11: scp.deny_console_access.policy_name | L11: Hard SOW requirement: no manual console access in production; break-glass procedure is the sole exception | M11: 2025-06-01
A12: security.credentials_rotation_days | B12: 90 | C12: 90 | D12: 90 | E12: Maximum age in days for integration API credentials before mandatory rotation | F12: Yes | G12: Integer | H12: 30-365 | I12: Public | J12: Security Team | K12: security.kms.log_archive_key_arn | L12: Applies to SIEM and ITSM API credentials stored in Secrets Manager; Lambda rotation functions deployed | M12: 2025-06-01
A13: security.access_review_frequency | B13: quarterly | C13: quarterly | D13: quarterly | E13: Frequency of CISO-led IAM Identity Center permission set assignment reviews | F13: Yes | G13: String | H13: quarterly|monthly|annually | I13: Public | J13: Security Team | K13: identity.sso.permission_set.operator | L13: ISO 27001 A.9.2 access review control; results retained as compliance evidence | M13: 2025-06-01
... A16: scp.encryption_enforce.policy_name | B16: cntso-enforce-encryption-org | C16: cntso-enforce-encryption-org | D16: cntso-enforce-encryption-org | E16: Name of the SCP mandating encryption at rest for S3 and EBS across all accounts | F16: Yes | G16: String | H16: Non-empty string matching naming convention | I16: Confidential | J16: Security Team | K16: security.kms.log_archive_key_arn | L16: Denies PutObject without KMS key; denies EBS volume creation without encryption; applied at org root OU | M16: 2025-06-01
A17: identity.sso.idp_connector_count | B17: 1 | C17: 1 | D17: 1 | E17: Number of on-premises IdP connectors configured in IAM Identity Center (SOW: 1 IdP) | F17: Yes | G17: Integer | H17: 1-5 | I17: Public | J17: Security Team | L17: SOW scope parameter; single on-premises enterprise directory federation via SAML 2.0 | M17: 2025-06-01
A18: identity.sso.saml_idp_metadata_url | B18: [idp-metadata-url] | C18: [idp-metadata-url] | D18: [idp-metadata-url] | E18: SAML 2.0 metadata URL of the on-premises enterprise directory identity provider | F18: Yes | G18: String | H18: Valid HTTPS URL | I18: Confidential | J18: Security Team | K18: identity.sso.idp_connector_count | L18: Obtained from on-premises IdP team during Week 3 federation design workshop | M18: 2025-06-01
A19: identity.sso.saml_signing_cert | B19: [saml-signing-cert] | C19: [saml-signing-cert] | D19: [saml-signing-cert] | E19: SAML 2.0 signing certificate PEM from the on-premises IdP pinned in IAM Identity Center | F19: Yes | G19: String | H19: Valid PEM certificate | I19: Secret | J19: Security Team | K19: identity.sso.saml_idp_metadata_url | L19: Stored in Secrets Manager; must be updated in IAM Identity Center on each IdP cert rotation | M19: 2025-06-01
A20: identity.sso.permission_set.developer | B20: Developer | C20: Developer | D20: Developer | E20: IAM Identity Center permission set name for developer read-only access to own workload accounts | F20: Yes | G20: String | H20: Non-empty alphanumeric | I20: Public | J20: Security Team | K20: identity.sso.idp_connector_count | L20: Read access to own workload account only; no IAM modifications; no production access per SOW | M20: 2025-06-01
A21: identity.sso.permission_set.operator | B21: PlatformOperator | C21: PlatformOperator | D21: PlatformOperator | E21: IAM Identity Center permission set name for operator read/write access to non-production accounts | F21: Yes | G21: String | H21: Non-empty alphanumeric | I21: Public | J21: Security Team | K21: identity.sso.idp_connector_count | L21: Read/write non-prod via IaC pipeline roles; read-only production; ITSM change required for prod | M21: 2025-06-01
A22: identity.sso.permission_set.security_viewer | B22: SecurityViewer | C22: SecurityViewer | D22: SecurityViewer | E22: IAM Identity Center permission set name for read-only Security Hub and Config access in Audit account | F22: Yes | G22: String | H22: Non-empty alphanumeric | I22: Public | J22: Security Team | K22: identity.sso.idp_connector_count | L22: Read-only to Security Hub / Config / GuardDuty in Audit and Log Archive accounts only | M22: 2025-06-01
A23: identity.sso.permission_set.breakglass_session_minutes | B23: 240 | C23: 240 | D23: 240 | E23: Maximum session duration in minutes for the BreakGlass emergency access role | F23: Yes | G23: Integer | H23: 60-480 | I23: Public | J23: Security Team | K23: security.console_access_blocked_in_prod | L23: SOW: 4-hour (240 min) maximum break-glass session; requires CISO approval via ITSM; fully logged | M23: 2025-06-01

Sheet Compute
A1: Compute Parameters
A2: Parameter Name | B2: Production | C2: Test | D2: DR | E2: Description | F2: Required | G2: Data Type | H2: Validation Rules | I2: Security Level | J2: Owner Team | K2: Dependencies | L2: Notes | M2: Last Updated
A3: compute.lambda.siem_forward.memory_mb | B3: 1024 | C3: 1024 | D3: 1024 | E3: Memory allocation in MB for the SIEM forwarding Lambda function | F3: Yes | G3: Integer | H3: 128-10240 | I3: Public | J3: Cloud CoE | K3: integration.siem.api_endpoint | L3: 1024 MB provides sufficient headroom for JSON transformation; adjust based on Phase 3 X-Ray profiling | M3: 2025-06-01
A4: compute.lambda.siem_forward.timeout_seconds | B4: 30 | C4: 30 | D4: 30 | E4: Timeout in seconds for the SIEM forwarding Lambda function | F4: Yes | G4: Integer | H4: 1-900 | I4: Public | J4: Cloud CoE | K4: integration.siem.delivery_sla_minutes | L4: 30-second timeout well within 5-minute SIEM delivery SLA; Lambda DLQ handles retries on timeout | M4: 2025-06-01
A5: compute.lambda.siem_forward.reserved_concurrency | B5: 10 | C5: 10 | D5: 10 | E5: Reserved concurrency for SIEM forwarding Lambda to prevent throttling on peak finding volumes | F5: Yes | G5: Integer | H5: 1-1000 | I5: Public | J5: Cloud CoE | K5: monitoring.securityhub.finding_volume_monthly | L5: Sized for ~1000 findings/month per SOW scope; increase if finding volume exceeds this estimate | M5: 2025-06-01
A6: compute.lambda.itsm_integration.memory_mb | B6: 512 | C6: 512 | D6: 512 | E6: Memory allocation in MB for the ITSM change-approval integration Lambda function | F6: Yes | G6: Integer | H6: 128-10240 | I6: Public | J6: Cloud CoE | K6: integration.itsm.api_endpoint | L6: 512 MB sufficient for JSON payload processing and OAuth token management | M6: 2025-06-01
A7: compute.lambda.itsm_integration.reserved_concurrency | B7: 5 | C7: 5 | D7: 5 | E7: Reserved concurrency for ITSM integration Lambda to prevent API rate limit exhaustion | F7: Yes | G7: Integer | H7: 1-1000 | I7: Public | J7: Cloud CoE | K7: integration.itsm.api_endpoint | L7: 5 concurrent executions sufficient for expected account vending request rate; aligns with AFT max concurrent | M7: 2025-06-01
A8: compute.lambda.config_remediation.memory_mb | B8: 512 | C8: 512 | D8: 512 | E8: Memory allocation in MB for the Config auto-remediation Lambda function | F8: Yes | G8: Integer | H8: 128-10240 | I8: Public | J8: Security Team | K8: monitoring.config.rule_count | L8: Auto-remediation scoped to governance resources only via IAM role; not executed against workload resources | M8: 2025-06-01
A9: compute.lambda.config_remediation.max_concurrency | B9: 20 | C9: 20 | D9: 20 | E9: Maximum concurrency for Config auto-remediation Lambda to control remediation blast radius | F9: Yes | G9: Integer | H9: 1-1000 | I9: Public | J9: Security Team | K9: compute.lambda.config_remediation.memory_mb | L9: Capped at 20 to avoid simultaneous remediation of too many resources; P2 alert if threshold approached | M9: 2025-06-01
A10: compute.lambda.aft_pipeline.memory_mb | B10: 3008 | C10: 3008 | D10: 3008 | E10: Memory allocation in MB for AFT account vending Lambda functions | F10: Yes | G10: Integer | H10: 128-10240 | I10: Public | J10: Cloud CoE | K10: aft.pipeline.itsm_approval_required | L10: 3008 MB (max for 6 vCPU Lambda) used for AFT account provisioning functions; reduces cold start latency | M10: 2025-06-01

Sheet Storage
A1: Storage Parameters
A2: Parameter Name | B2: Production | C2: Test | D2: DR | E2: Description | F2: Required | G2: Data Type | H2: Validation Rules | I2: Security Level | J2: Owner Team | K2: Dependencies | L2: Notes | M2: Last Updated
A3: storage.log_archive.bucket_name | B3: [bucket-name] | C3: [bucket-name] | D3: [bucket-name] | E3: S3 bucket name in Log Archive account for centralised CloudTrail and Config log storage | F3: Yes | G3: String | H3: Globally unique bucket name; lowercase alphanumeric hyphens | I3: Confidential | J3: Operations | K3: aws.account_id.log_archive | L3: Object Lock (Compliance mode) must be enabled at bucket creation; cannot be disabled post-creation | M3: 2025-06-01
A4: storage.log_archive.object_lock_mode | B4: COMPLIANCE | C4: COMPLIANCE | D4: COMPLIANCE | E4: S3 Object Lock mode enforcing WORM retention on log archive bucket | F4: Yes | G4: String | H4: COMPLIANCE|GOVERNANCE | I4: Confidential | J4: Security Team | K4: storage.log_archive.bucket_name | L4: COMPLIANCE mode prevents deletion by any identity including root; required for ISO 27001 evidence immutability | M4: 2025-06-01
A5: storage.log_archive.crr_destination_bucket | B5: [bucket-name] | C5: [bucket-name] | D5: [bucket-name] | E5: S3 bucket name in ap-southeast-4 as the cross-region replication destination for log archive data | F5: Yes | G5: String | H5: Globally unique bucket name; lowercase alphanumeric hyphens | I5: Confidential | J5: Operations | K5: storage.log_archive.bucket_name | L5: Sub-minute CRR lag ensures RPO < 1 hour; destination bucket in DR region ap-southeast-4 | M5: 2025-06-01
A6: storage.log_archive.cloudtrail_log_volume_gb_monthly | B6: 200 | C6: 50 | D6: 200 | E6: Expected monthly CloudTrail log volume in GB used for S3 capacity planning | F6: Yes | G6: Integer | H6: 1-10000 | I6: Public | J6: Operations | K6: storage.log_archive.bucket_name | L6: SOW scope: 50–200 GB/month medium tier; S3 Standard used (Intelligent-Tiering incompatible with Object Lock) | M6: 2025-06-01
A7: storage.terraform_state.bucket_name | B7: [bucket-name] | C7: [bucket-name] | D7: [bucket-name] | E7: S3 bucket name in Management account for Terraform state files across all workspaces | F7: Yes | G7: String | H7: Globally unique bucket name; lowercase alphanumeric hyphens | I7: Confidential | J7: Cloud CoE | K7: aws.account_id.management | L7: Versioning enabled; access restricted to AFT pipeline IAM role only; backed up daily by AWS Backup | M7: 2025-06-01
A8: storage.terraform_state.versioning_enabled | B8: true | C8: true | D8: true | E8: Enable S3 versioning on Terraform state bucket to support state file rollback | F8: Yes | G8: Boolean | H8: true|false | I8: Public | J8: Cloud CoE | K8: storage.terraform_state.bucket_name | L8: Required for Terraform state rollback capability; previous state versions retained per backup policy | M8: 2025-06-01

Sheet Database
A1: Database Parameters
A2: Parameter Name | B2: Production | C2: Test | D2: DR | E2: Description | F2: Required | G2: Data Type | H2: Validation Rules | I2: Security Level | J2: Owner Team | K2: Dependencies | L2: Notes | M2: Last Updated
A3: database.aft_workflow.table_name | B3: cntso-aft-workflow-prod | C3: cntso-aft-workflow-nonprod | D3: cntso-aft-workflow-dr | E3: DynamoDB table name storing AFT account vending workflow state | F3: Yes | G3: String | H3: Alphanumeric hyphens max 255 chars | I3: Confidential | J3: Cloud CoE | K3: solution.name | L3: Must match AFT pipeline configuration; used for idempotent re-run tracking | M3: 2025-06-01
A4: database.aft_workflow.billing_mode | B4: PAY_PER_REQUEST | C4: PAY_PER_REQUEST | D4: PAY_PER_REQUEST | E4: DynamoDB billing mode for AFT workflow state table | F4: Yes | G4: String | H4: PROVISIONED|PAY_PER_REQUEST | I4: Public | J4: Cloud CoE | K4: database.aft_workflow.table_name | L4: On-demand capacity chosen for variable vending workload; aligns with serverless-first cost model | M4: 2025-06-01
A5: database.aft_workflow.backup_enabled | B5: true | C5: true | D5: true | E5: Enable DynamoDB point-in-time recovery on AFT workflow state table | F5: Yes | G5: Boolean | H5: true|false | I5: Public | J5: Cloud CoE | K5: database.aft_workflow.table_name | L5: Required by AWS Backup daily plan; 30-day retention per SOW backup policy | M5: 2025-06-01
A6: database.terraform_state.lock_table | B6: cntso-tf-state-lock-prod | C6: cntso-tf-state-lock-nonprod | D6: cntso-tf-state-lock-dr | E6: DynamoDB table name for Terraform state locking across all workspaces | F6: Yes | G6: String | H6: Alphanumeric hyphens max 255 chars | I6: Confidential | J6: Cloud CoE | K6: storage.terraform_state.bucket_name | L6: Prevents concurrent Terraform runs from corrupting shared state; required for all workspaces | M6: 2025-06-01

Sheet Application
A1: Application Parameters
A2: Parameter Name | B2: Production | C2: Test | D2: DR | E2: Description | F2: Required | G2: Data Type | H2: Validation Rules | I2: Security Level | J2: Owner Team | K2: Dependencies | L2: Notes | M2: Last Updated
A3: application.version | B3: 1.0.0 | C3: 1.0.0 | D3: 1.0.0 | E3: Current governance platform release version used in tagging and runbook documentation | F3: Yes | G3: String | H3: Semantic versioning X.Y.Z | I3: Public | J3: Cloud CoE | L3: Increment on each phase delivery milestone; tag all IaC commits with matching version | M3: 2025-06-01
A4: application.log_level | B4: info | C4: debug | D4: info | E4: Logging verbosity level for Lambda functions across the platform | F4: Yes | G4: String | H4: debug|info|warn|error | I4: Public | J4: Cloud CoE | L4: Debug level enabled in nonprod only to avoid CloudWatch log volume impact in production | M4: 2025-06-01
A5: application.accounts_at_golive | B5: 8 | C5: 8 | D5: 8 | E5: Total AWS accounts at go-live: Management + Log Archive + Audit + Security + Network + 3 Workload | F5: Yes | G5: Integer | H5: Positive integer | I5: Public | J5: Cloud CoE | K5: aws.account_id.management | L5: Matches SOW Scope Parameters: 8 accounts at go-live; drives Config billing estimate | M5: 2025-06-01
A6: application.platform_users | B6: 150 | C6: 150 | D6: 150 | E6: Total platform team and workload account owner users federated via IAM Identity Center | F6: Yes | G6: Integer | H6: Positive integer | I6: Public | J6: Cloud CoE | K6: identity.sso.idp_connector_count | L6: SOW scope parameter — ~150 platform team plus workload account owners | M6: 2025-06-01
A7: aft.pipeline.itsm_approval_required | B7: true | C7: true | D7: true | E7: Require ITSM change-approval before AFT pipeline executes account vending | F7: Yes | G7: Boolean | H7: true|false | I7: Public | J7: Cloud CoE | K7: integration.itsm.api_endpoint | L7: Must remain true in all environments; ISO 27001 change management control requirement | M7: 2025-06-01
A8: aft.pipeline.max_concurrent_requests | B8: 5 | C8: 5 | D8: 5 | E8: Maximum concurrent account vending requests the AFT pipeline processes simultaneously | F8: Yes | G8: Integer | H8: 1-20 | I8: Public | J8: Cloud CoE | K8: aft.pipeline.itsm_approval_required | L8: Load-tested to 5 concurrent requests in Phase 3 per SOW performance test requirements | M8: 2025-06-01
A9: aft.pipeline.account_provisioning_timeout_minutes | B9: 60 | C9: 60 | D9: 60 | E9: Maximum time allowed for end-to-end AFT account vending before pipeline fails | F9: Yes | G9: Integer | H9: 30-180 | I9: Public | J9: Cloud CoE | K9: aft.pipeline.max_concurrent_requests | L9: SOW success metric: account provisioned within 60 minutes of ITSM approval | M9: 2025-06-01

Sheet Monitoring
A1: Monitoring Parameters
A2: Parameter Name | B2: Production | C2: Test | D2: DR | E2: Description | F2: Required | G2: Data Type | H2: Validation Rules | I2: Security Level | J2: Owner Team | K2: Dependencies | L2: Notes | M2: Last Updated
A3: monitoring.cloudwatch.dashboard_platform_ops | B3: cntso-platform-operations | C3: cntso-platform-operations | D3: cntso-platform-operations-dr | E3: CloudWatch dashboard name for AFT pipeline health and Config compliance trend | F3: Yes | G3: String | H3: Non-empty string | I3: Public | J3: Operations | K3: aws.account_id.management | L3: One of three operational dashboards deployed as IaC; reviewed daily by platform team | M3: 2025-06-01
A4: monitoring.cloudwatch.dashboard_identity | B4: cntso-identity-access | C4: cntso-identity-access | D4: cntso-identity-access-dr | E4: CloudWatch dashboard name for IAM Identity Center login events and break-glass usage | F4: Yes | G4: String | H4: Non-empty string | I4: Public | J4: Operations | K4: aws.account_id.security | L4: Displays IAM Identity Center logins; permission set assignments; break-glass usage events | M4: 2025-06-01
A5: monitoring.cloudwatch.dashboard_dr | B5: cntso-dr-replication | C5: cntso-dr-replication | D5: cntso-dr-replication-dr | E5: CloudWatch dashboard name for S3 CRR lag and DR region replication health | F5: Yes | G5: String | H5: Non-empty string | I5: Public | J5: Operations | K5: storage.log_archive.crr_destination_bucket | L5: Tracks S3 CRR replication lag against < 1 hour RPO target; reviewed before each DR drill | M5: 2025-06-01
A6: monitoring.cloudwatch.log_retention_days | B6: 90 | C6: 30 | D6: 90 | E6: CloudWatch Logs retention in days before log group expiry; S3 export extends to 12 months | F6: Yes | G6: Integer | H6: 1-3653 | I6: Public | J6: Operations | K6: storage.log_archive.bucket_name | L6: 90-day in-service retention; nightly export to Log Archive S3 bucket achieves 12-month total retention | M6: 2025-06-01
A7: monitoring.cloudwatch.alert_sns_topic_arn | B7: [sns-topic-arn] | C7: [sns-topic-arn] | D7: [sns-topic-arn] | E7: SNS topic ARN routing P1 and P2 CloudWatch alarms to the on-call platform engineer | F7: Yes | G7: String | H7: Valid SNS ARN | I7: Confidential | J7: Operations | K7: aws.account_id.audit | L7: P1 alerts (AFT failure; DLQ depth; CRR lag; BGP state change) use 2-minute evaluation period | M7: 2025-06-01
A8: monitoring.guardduty.org_detector_enabled | B8: true | C8: true | D8: true | E8: Enable GuardDuty organisational detector in the Audit account for all member accounts | F8: Yes | G8: Boolean | H8: true|false | I8: Public | J8: Security Team | K8: aws.account_id.audit | L8: GuardDuty auto-enrolls new AFT-vended accounts; SCP denies DeleteDetector to prevent disabling | M8: 2025-06-01
A9: monitoring.securityhub.standards_aws_fsbp | B9: true | C9: true | D9: true | E9: Enable AWS Foundational Security Best Practices standard in Security Hub | F9: Yes | G9: Boolean | H9: true|false | I9: Public | J9: Security Team | K9: aws.account_id.audit | L9: One of three Security Hub standards enabled; findings aggregated from all member accounts | M9: 2025-06-01
A10: monitoring.securityhub.standards_cis | B10: true | C10: true | D10: true | E10: Enable CIS AWS Foundations Benchmark standard in Security Hub | F10: Yes | G10: Boolean | H10: true|false | I10: Public | J10: Security Team | K10: aws.account_id.audit | L10: CIS Benchmark enabled alongside FSBP and internal baseline standard in Security Hub | M10: 2025-06-01
A11: monitoring.securityhub.finding_volume_monthly | B11: 1000 | C11: 1000 | D11: 1000 | E11: Expected Security Hub finding volume per month used for Lambda concurrency and SIEM sizing | F11: Yes | G11: Integer | H11: 1-1000000 | I11: Public | J11: Operations | K11: monitoring.cloudwatch.alert_sns_topic_arn | L11: SOW scope parameter: ~1000 findings/month; drives EventBridge rule and Lambda reserved concurrency | M11: 2025-06-01
A12: monitoring.config.rule_count | B12: 80 | C12: 80 | D12: 80 | E12: Approximate number of AWS Config rules deployed (ISO 27001 conformance pack + internal baseline) | F12: Yes | G12: Integer | H12: 1-500 | I12: Public | J12: Security Team | K12: aws.account_id.audit | L12: SOW scope: ~80 rules; drives Config billing estimate; exact count confirmed in Phase 1 control mapping | M12: 2025-06-01
A13: monitoring.config.evaluation_lag_seconds | B13: 60 | C13: 60 | D13: 60 | E13: Maximum acceptable time from resource change to Config rule evaluation firing in seconds | F13: Yes | G13: Integer | H13: 30-300 | I13: Public | J13: Security Team | K13: monitoring.config.rule_count | L13: SOW success metric: Config rule evaluation ≤ 60 seconds; validated in Phase 3 security testing | M13: 2025-06-01

Sheet Integration
A1: Integration Parameters
A2: Parameter Name | B2: Production | C2: Test | D2: DR | E2: Description | F2: Required | G2: Data Type | H2: Validation Rules | I2: Security Level | J2: Owner Team | K2: Dependencies | L2: Notes | M2: Last Updated
A3: integration.siem.api_endpoint | B3: [siem-api-endpoint] | C3: [siem-api-endpoint] | D3: [siem-api-endpoint] | E3: HTTPS endpoint for the on-premises SIEM event ingestion API used by the forwarding Lambda | F3: Yes | G3: String | H3: Valid HTTPS URL | I3: Confidential | J3: Integration Team | K3: integration.siem.api_key | L3: Collected from SIEM administrator by Week 9; stored in Secrets Manager | M3: 2025-06-01
A4: integration.siem.api_key | B4: [siem-api-key] | C4: [siem-api-key] | D4: [siem-api-key] | E4: Bearer token for authenticating Lambda-to-SIEM API calls | F4: Yes | G4: String | H4: Provider-specific token format | I4: Secret | J4: Integration Team | K4: integration.siem.api_endpoint | L4: Stored in Secrets Manager; rotated every 90 days via automated Lambda rotation function | M4: 2025-06-01
A5: integration.siem.delivery_sla_minutes | B5: 5 | C5: 5 | D5: 5 | E5: Maximum acceptable end-to-end latency from Security Hub finding to SIEM ingestion in minutes | F5: Yes | G5: Integer | H5: 1-60 | I5: Public | J5: Integration Team | K5: integration.siem.api_endpoint | L5: SOW success metric: Security Hub findings forwarded within 5 minutes of detection | M5: 2025-06-01
A6: integration.siem.finding_severity_threshold | B6: HIGH | C6: HIGH | D6: HIGH | E6: Minimum Security Hub finding severity forwarded to SIEM (CRITICAL, HIGH, MEDIUM, LOW, INFORMATIONAL) | F6: Yes | G6: String | H6: CRITICAL|HIGH|MEDIUM|LOW|INFORMATIONAL | I6: Public | J6: Integration Team | K6: integration.siem.api_endpoint | L6: SOW: CRITICAL and HIGH forwarded immediately; can be lowered to MEDIUM during hypercare tuning | M6: 2025-06-01
A7: integration.siem.dlq_name | B7: cntso-siem-forward-dlq-prod | C7: cntso-siem-forward-dlq-nonprod | D7: cntso-siem-forward-dlq-dr | E7: SQS dead-letter queue name for failed SIEM forwarding Lambda invocations | F7: Yes | G7: String | H7: Non-empty string matching naming convention | I7: Confidential | J7: Integration Team | K7: integration.siem.api_endpoint | L7: DLQ depth alarm threshold > 0 for > 5 minutes triggers P1 alert to platform team | M7: 2025-06-01
A8: integration.siem.dlq_alarm_threshold | B8: 0 | C8: 0 | D8: 0 | E8: SQS DLQ message count threshold above which a P1 CloudWatch alarm fires | F8: Yes | G8: Integer | H8: 0-100 | I8: Public | J8: Integration Team | K8: integration.siem.dlq_name | L8: Any DLQ message indicates a SIEM delivery failure; threshold 0 ensures immediate alerting | M8: 2025-06-01
A9: integration.itsm.api_endpoint | B9: [itsm-api-endpoint] | C9: [itsm-api-endpoint] | D9: [itsm-api-endpoint] | E9: HTTPS endpoint for the on-premises ITSM ticketing platform change-approval API | F9: Yes | G9: String | H9: Valid HTTPS URL | I9: Confidential | J9: Integration Team | K9: integration.itsm.oauth_client_id | L9: Collected from ITSM administrator by Week 8; stored in Secrets Manager | M9: 2025-06-01
A10: integration.itsm.oauth_client_id | B10: [itsm-oauth-client-id] | C10: [itsm-oauth-client-id] | D10: [itsm-oauth-client-id] | E10: OAuth 2.0 client ID for authenticating Lambda-to-ITSM API calls | F10: Yes | G10: String | H10: Non-empty alphanumeric | I10: Confidential | J10: Integration Team | K10: integration.itsm.api_endpoint | L10: OAuth 2.0 client credentials flow; client secret stored separately in Secrets Manager | M10: 2025-06-01
A11: integration.itsm.oauth_client_secret | B11: [itsm-oauth-client-secret] | C11: [itsm-oauth-client-secret] | D11: [itsm-oauth-client-secret] | E11: OAuth 2.0 client secret for ITSM API authentication | F11: Yes | G11: String | H11: Non-empty string | I11: Secret | J11: Integration Team | K11: integration.itsm.oauth_client_id | L11: Stored in Secrets Manager; rotated every 90 days; Lambda rotation function deployed | M11: 2025-06-01
A12: integration.itsm.approval_poll_interval_seconds | B12: 120 | C12: 120 | D12: 120 | E12: Interval in seconds at which the AFT pipeline polls ITSM for change record approval status | F12: Yes | G12: Integer | H12: 30-600 | I12: Public | J12: Integration Team | K12: integration.itsm.api_endpoint | L12: 2-minute polling interval per detailed design; balances ITSM API rate limits with provisioning latency | M12: 2025-06-01
A13: integration.itsm.change_freeze_scp_condition | B13: true | C13: false | D13: true | E13: Enable SCP condition that denies AFT pipeline execution without approved ITSM change record during change freeze | F13: Yes | G13: Boolean | H13: true|false | I13: Public | J13: Integration Team | K13: integration.itsm.api_endpoint | L13: SOW: 14-day change freeze before Q2 2026 regulatory review; freeze window set in ITSM change calendar | M13: 2025-06-01

Sheet Operations
A1: Operations Parameters
A2: Parameter Name | B2: Production | C2: Test | D2: DR | E2: Description | F2: Required | G2: Data Type | H2: Validation Rules | I2: Security Level | J2: Owner Team | K2: Dependencies | L2: Notes | M2: Last Updated
A3: operations.backup.plan_name | B3: cntso-platform-backup-prod | C3: cntso-platform-backup-nonprod | D3: cntso-platform-backup-dr | E3: AWS Backup plan name covering DynamoDB and S3 configuration buckets | F3: Yes | G3: String | H3: Non-empty string matching naming convention | I3: Public | J3: Operations | K3: aws.account_id.management | L3: Daily backups with 30-day retention per SOW operational design; replicated to ap-southeast-4 | M3: 2025-06-01
A4: operations.backup.retention_days | B4: 30 | C4: 7 | D4: 30 | E4: Backup retention period in days for AWS Backup daily plan | F4: Yes | G4: Integer | H4: 7-365 | I4: Public | J4: Operations | K4: operations.backup.plan_name | L4: SOW: 30-day retention for platform state protection; 7-day retention in nonprod for cost saving | M4: 2025-06-01
A5: operations.backup.dr_replication_enabled | B5: true | C5: false | D5: true | E5: Enable AWS Backup cross-region replication to ap-southeast-4 DR region | F5: Yes | G5: Boolean | H5: true|false | I5: Public | J5: Operations | K5: operations.backup.plan_name | L5: Replication to DR region ensures backup availability during ap-southeast-2 regional failure | M5: 2025-06-01
A6: operations.dr.rto_hours | B6: 4 | C6: 4 | D6: 4 | E6: Recovery Time Objective in hours for governance platform DR failover | F6: Yes | G6: Integer | H6: 1-24 | I6: Public | J6: Operations | K6: networking.transit_gateway.dr_id | L6: SOW hard requirement: RTO < 4 hours; validated via Phase 3 DR failover drill; result in evidence package | M6: 2025-06-01
A7: operations.dr.rpo_hours | B7: 1 | C7: 1 | D7: 1 | E7: Recovery Point Objective in hours for governance platform DR failover | F7: Yes | G7: Integer | H7: 1-24 | I7: Public | J7: Operations | K7: storage.log_archive.crr_destination_bucket | L7: SOW hard requirement: RPO < 1 hour; met by S3 CRR sub-minute lag; validated in Phase 3 | M7: 2025-06-01
A8: operations.dr.failover_activation_criteria_minutes | B8: 30 | C8: 30 | D8: 30 | E8: Minutes of governance evidence collection failure before DR activation is triggered | F8: Yes | G8: Integer | H8: 15-120 | I8: Public | J8: Operations | K8: operations.dr.rto_hours | L8: DR activated if compliance evidence collection is disrupted for > 30 minutes per detailed design | M8: 2025-06-01
A9: operations.patch.baseline_schedule | B9: monthly | C9: monthly | D9: monthly | E9: Patch Manager patching baseline schedule frequency for any platform instances | F9: Yes | G9: String | H9: daily|weekly|monthly | I9: Public | J9: Operations | K9: aws.account_id.management | L9: No direct SSH/RDP; all patching via SSM Patch Manager and Session Manager per no-console-access mandate | M9: 2025-06-01
A10: operations.compliance.evidence_package_schedule | B10: Phase3 | C10: Phase3 | D10: Phase3 | E10: Phase deliverable in which the ISO 27001 compliance evidence package is compiled and delivered | F10: Yes | G10: String | H10: Phase1|Phase2|Phase3 | I10: Public | J10: Security Team | K10: monitoring.config.rule_count | L10: SOW: evidence package delivered by end of Phase 3 (Week 15) for CISO review before April 2026 deadline | M10: 2025-06-01
A11: operations.platform_availability_target | B11: 99.9 | C11: 99.9 | D11: 99.9 | E11: Platform availability target percentage for governance services per SOW SLA | F11: Yes | G11: Float | H11: 0-100 | I11: Public | J11: Operations | K11: monitoring.cloudwatch.alert_sns_topic_arn | L11: SOW commitment: 99.9% availability for platform services; measured via CloudWatch uptime monitoring | M11: 2025-06-01
