Workbook

Sheet Cover
B3: Configuration Parameters
B5: Generated: | C5: June 30, 2026
B6: Solution: | C6: Tmp69J9L8V7
B7: Customer: | C7: [Customer Name]
B8: Version: | C8: 1.0
B9: Status: | C9: Draft
C12: eoframework.org

Sheet All Parameters (Read Only)
A1: Total Parameters | B1: Categories | C1: Required | D1: Confidential/Secret
A2: 161 | B2: 12 | C2: 161 | D2: 48
A4: Parameter Name | B4: Category | C4: Production | D4: Test | E4: DR | F4: Description | G4: Required | H4: Data Type | I4: Validation Rules | J4: Security Level | K4: Owner Team | L4: Dependencies | M4: Notes | N4: Last Updated
A5: =IF('Project'!A3="","",'Project'!A3) | B5: Project | C5: =IF('Project'!B3="","",'Project'!B3) | D5: =IF('Project'!C3="","",'Project'!C3) | E5: =IF('Project'!D3="","",'Project'!D3) | F5: =IF('Project'!E3="","",'Project'!E3) | G5: =IF('Project'!F3="","",'Project'!F3) | H5: =IF('Project'!G3="","",'Project'!G3) | I5: =IF('Project'!H3="","",'Project'!H3) | J5: =IF('Project'!I3="","",'Project'!I3) | ... N5: =IF('Project'!M3="","",'Project'!M3)
A6: =IF('Project'!A4="","",'Project'!A4) | B6: Project | C6: =IF('Project'!B4="","",'Project'!B4) | D6: =IF('Project'!C4="","",'Project'!C4) | E6: =IF('Project'!D4="","",'Project'!D4) | F6: =IF('Project'!E4="","",'Project'!E4) | G6: =IF('Project'!F4="","",'Project'!F4) | H6: =IF('Project'!G4="","",'Project'!G4) | I6: =IF('Project'!H4="","",'Project'!H4) | J6: =IF('Project'!I4="","",'Project'!I4) | ... N6: =IF('Project'!M4="","",'Project'!M4)
A7: =IF('Project'!A5="","",'Project'!A5) | B7: Project | C7: =IF('Project'!B5="","",'Project'!B5) | D7: =IF('Project'!C5="","",'Project'!C5) | E7: =IF('Project'!D5="","",'Project'!D5) | F7: =IF('Project'!E5="","",'Project'!E5) | G7: =IF('Project'!F5="","",'Project'!F5) | H7: =IF('Project'!G5="","",'Project'!G5) | I7: =IF('Project'!H5="","",'Project'!H5) | J7: =IF('Project'!I5="","",'Project'!I5) | ... N7: =IF('Project'!M5="","",'Project'!M5)
A8: =IF('Project'!A6="","",'Project'!A6) | B8: Project | C8: =IF('Project'!B6="","",'Project'!B6) | D8: =IF('Project'!C6="","",'Project'!C6) | E8: =IF('Project'!D6="","",'Project'!D6) | F8: =IF('Project'!E6="","",'Project'!E6) | G8: =IF('Project'!F6="","",'Project'!F6) | H8: =IF('Project'!G6="","",'Project'!G6) | I8: =IF('Project'!H6="","",'Project'!H6) | J8: =IF('Project'!I6="","",'Project'!I6) | ... N8: =IF('Project'!M6="","",'Project'!M6)
A9: =IF('Project'!A7="","",'Project'!A7) | B9: Project | C9: =IF('Project'!B7="","",'Project'!B7) | D9: =IF('Project'!C7="","",'Project'!C7) | E9: =IF('Project'!D7="","",'Project'!D7) | F9: =IF('Project'!E7="","",'Project'!E7) | G9: =IF('Project'!F7="","",'Project'!F7) | H9: =IF('Project'!G7="","",'Project'!G7) | I9: =IF('Project'!H7="","",'Project'!H7) | J9: =IF('Project'!I7="","",'Project'!I7) | ... N9: =IF('Project'!M7="","",'Project'!M7)
A10: =IF('Project'!A8="","",'Project'!A8) | B10: Project | C10: =IF('Project'!B8="","",'Project'!B8) | D10: =IF('Project'!C8="","",'Project'!C8) | E10: =IF('Project'!D8="","",'Project'!D8) | F10: =IF('Project'!E8="","",'Project'!E8) | G10: =IF('Project'!F8="","",'Project'!F8) | H10: =IF('Project'!G8="","",'Project'!G8) | I10: =IF('Project'!H8="","",'Project'!H8) | J10: =IF('Project'!I8="","",'Project'!I8) | ... N10: =IF('Project'!M8="","",'Project'!M8)
A11: =IF('Project'!A9="","",'Project'!A9) | B11: Project | C11: =IF('Project'!B9="","",'Project'!B9) | D11: =IF('Project'!C9="","",'Project'!C9) | E11: =IF('Project'!D9="","",'Project'!D9) | F11: =IF('Project'!E9="","",'Project'!E9) | G11: =IF('Project'!F9="","",'Project'!F9) | H11: =IF('Project'!G9="","",'Project'!G9) | I11: =IF('Project'!H9="","",'Project'!H9) | J11: =IF('Project'!I9="","",'Project'!I9) | ... N11: =IF('Project'!M9="","",'Project'!M9)
A12: =IF('Project'!A10="","",'Project'!A10) | B12: Project | C12: =IF('Project'!B10="","",'Project'!B10) | D12: =IF('Project'!C10="","",'Project'!C10) | E12: =IF('Project'!D10="","",'Project'!D10) | F12: =IF('Project'!E10="","",'Project'!E10) | G12: =IF('Project'!F10="","",'Project'!F10) | H12: =IF('Project'!G10="","",'Project'!G10) | I12: =IF('Project'!H10="","",'Project'!H10) | J12: =IF('Project'!I10="","",'Project'!I10) | ... N12: =IF('Project'!M10="","",'Project'!M10)
A13: =IF('Networking'!A3="","",'Networking'!A3) | B13: Networking | C13: =IF('Networking'!B3="","",'Networking'!B3) | D13: =IF('Networking'!C3="","",'Networking'!C3) | E13: =IF('Networking'!D3="","",'Networking'!D3) | F13: =IF('Networking'!E3="","",'Networking'!E3) | G13: =IF('Networking'!F3="","",'Networking'!F3) | H13: =IF('Networking'!G3="","",'Networking'!G3) | I13: =IF('Networking'!H3="","",'Networking'!H3) | J13: =IF('Networking'!I3="","",'Networking'!I3) | ... N13: =IF('Networking'!M3="","",'Networking'!M3)
A14: =IF('Networking'!A4="","",'Networking'!A4) | B14: Networking | C14: =IF('Networking'!B4="","",'Networking'!B4) | D14: =IF('Networking'!C4="","",'Networking'!C4) | E14: =IF('Networking'!D4="","",'Networking'!D4) | F14: =IF('Networking'!E4="","",'Networking'!E4) | G14: =IF('Networking'!F4="","",'Networking'!F4) | H14: =IF('Networking'!G4="","",'Networking'!G4) | I14: =IF('Networking'!H4="","",'Networking'!H4) | J14: =IF('Networking'!I4="","",'Networking'!I4) | ... N14: =IF('Networking'!M4="","",'Networking'!M4)
A15: =IF('Networking'!A5="","",'Networking'!A5) | B15: Networking | C15: =IF('Networking'!B5="","",'Networking'!B5) | D15: =IF('Networking'!C5="","",'Networking'!C5) | E15: =IF('Networking'!D5="","",'Networking'!D5) | F15: =IF('Networking'!E5="","",'Networking'!E5) | G15: =IF('Networking'!F5="","",'Networking'!F5) | H15: =IF('Networking'!G5="","",'Networking'!G5) | I15: =IF('Networking'!H5="","",'Networking'!H5) | J15: =IF('Networking'!I5="","",'Networking'!I5) | ... N15: =IF('Networking'!M5="","",'Networking'!M5)
A16: =IF('Networking'!A6="","",'Networking'!A6) | B16: Networking | C16: =IF('Networking'!B6="","",'Networking'!B6) | D16: =IF('Networking'!C6="","",'Networking'!C6) | E16: =IF('Networking'!D6="","",'Networking'!D6) | F16: =IF('Networking'!E6="","",'Networking'!E6) | G16: =IF('Networking'!F6="","",'Networking'!F6) | H16: =IF('Networking'!G6="","",'Networking'!G6) | I16: =IF('Networking'!H6="","",'Networking'!H6) | J16: =IF('Networking'!I6="","",'Networking'!I6) | ... N16: =IF('Networking'!M6="","",'Networking'!M6)
A17: =IF('Networking'!A7="","",'Networking'!A7) | B17: Networking | C17: =IF('Networking'!B7="","",'Networking'!B7) | D17: =IF('Networking'!C7="","",'Networking'!C7) | E17: =IF('Networking'!D7="","",'Networking'!D7) | F17: =IF('Networking'!E7="","",'Networking'!E7) | G17: =IF('Networking'!F7="","",'Networking'!F7) | H17: =IF('Networking'!G7="","",'Networking'!G7) | I17: =IF('Networking'!H7="","",'Networking'!H7) | J17: =IF('Networking'!I7="","",'Networking'!I7) | ... N17: =IF('Networking'!M7="","",'Networking'!M7)
A18: =IF('Networking'!A8="","",'Networking'!A8) | B18: Networking | C18: =IF('Networking'!B8="","",'Networking'!B8) | D18: =IF('Networking'!C8="","",'Networking'!C8) | E18: =IF('Networking'!D8="","",'Networking'!D8) | F18: =IF('Networking'!E8="","",'Networking'!E8) | G18: =IF('Networking'!F8="","",'Networking'!F8) | H18: =IF('Networking'!G8="","",'Networking'!G8) | I18: =IF('Networking'!H8="","",'Networking'!H8) | J18: =IF('Networking'!I8="","",'Networking'!I8) | ... N18: =IF('Networking'!M8="","",'Networking'!M8)
A19: =IF('Networking'!A9="","",'Networking'!A9) | B19: Networking | C19: =IF('Networking'!B9="","",'Networking'!B9) | D19: =IF('Networking'!C9="","",'Networking'!C9) | E19: =IF('Networking'!D9="","",'Networking'!D9) | F19: =IF('Networking'!E9="","",'Networking'!E9) | G19: =IF('Networking'!F9="","",'Networking'!F9) | H19: =IF('Networking'!G9="","",'Networking'!G9) | I19: =IF('Networking'!H9="","",'Networking'!H9) | J19: =IF('Networking'!I9="","",'Networking'!I9) | ... N19: =IF('Networking'!M9="","",'Networking'!M9)
A20: =IF('Networking'!A10="","",'Networking'!A10) | B20: Networking | C20: =IF('Networking'!B10="","",'Networking'!B10) | D20: =IF('Networking'!C10="","",'Networking'!C10) | E20: =IF('Networking'!D10="","",'Networking'!D10) | F20: =IF('Networking'!E10="","",'Networking'!E10) | G20: =IF('Networking'!F10="","",'Networking'!F10) | H20: =IF('Networking'!G10="","",'Networking'!G10) | I20: =IF('Networking'!H10="","",'Networking'!H10) | J20: =IF('Networking'!I10="","",'Networking'!I10) | ... N20: =IF('Networking'!M10="","",'Networking'!M10)
A21: =IF('Networking'!A11="","",'Networking'!A11) | B21: Networking | C21: =IF('Networking'!B11="","",'Networking'!B11) | D21: =IF('Networking'!C11="","",'Networking'!C11) | E21: =IF('Networking'!D11="","",'Networking'!D11) | F21: =IF('Networking'!E11="","",'Networking'!E11) | G21: =IF('Networking'!F11="","",'Networking'!F11) | H21: =IF('Networking'!G11="","",'Networking'!G11) | I21: =IF('Networking'!H11="","",'Networking'!H11) | J21: =IF('Networking'!I11="","",'Networking'!I11) | ... N21: =IF('Networking'!M11="","",'Networking'!M11)
A22: =IF('Networking'!A12="","",'Networking'!A12) | B22: Networking | C22: =IF('Networking'!B12="","",'Networking'!B12) | D22: =IF('Networking'!C12="","",'Networking'!C12) | E22: =IF('Networking'!D12="","",'Networking'!D12) | F22: =IF('Networking'!E12="","",'Networking'!E12) | G22: =IF('Networking'!F12="","",'Networking'!F12) | H22: =IF('Networking'!G12="","",'Networking'!G12) | I22: =IF('Networking'!H12="","",'Networking'!H12) | J22: =IF('Networking'!I12="","",'Networking'!I12) | ... N22: =IF('Networking'!M12="","",'Networking'!M12)
A23: =IF('Networking'!A13="","",'Networking'!A13) | B23: Networking | C23: =IF('Networking'!B13="","",'Networking'!B13) | D23: =IF('Networking'!C13="","",'Networking'!C13) | E23: =IF('Networking'!D13="","",'Networking'!D13) | F23: =IF('Networking'!E13="","",'Networking'!E13) | G23: =IF('Networking'!F13="","",'Networking'!F13) | H23: =IF('Networking'!G13="","",'Networking'!G13) | I23: =IF('Networking'!H13="","",'Networking'!H13) | J23: =IF('Networking'!I13="","",'Networking'!I13) | ... N23: =IF('Networking'!M13="","",'Networking'!M13)
A24: =IF('Networking'!A14="","",'Networking'!A14) | B24: Networking | C24: =IF('Networking'!B14="","",'Networking'!B14) | D24: =IF('Networking'!C14="","",'Networking'!C14) | E24: =IF('Networking'!D14="","",'Networking'!D14) | F24: =IF('Networking'!E14="","",'Networking'!E14) | G24: =IF('Networking'!F14="","",'Networking'!F14) | H24: =IF('Networking'!G14="","",'Networking'!G14) | I24: =IF('Networking'!H14="","",'Networking'!H14) | J24: =IF('Networking'!I14="","",'Networking'!I14) | ... N24: =IF('Networking'!M14="","",'Networking'!M14)
... A26: =IF('Networking'!A16="","",'Networking'!A16) | B26: Networking | C26: =IF('Networking'!B16="","",'Networking'!B16) | D26: =IF('Networking'!C16="","",'Networking'!C16) | E26: =IF('Networking'!D16="","",'Networking'!D16) | F26: =IF('Networking'!E16="","",'Networking'!E16) | G26: =IF('Networking'!F16="","",'Networking'!F16) | H26: =IF('Networking'!G16="","",'Networking'!G16) | I26: =IF('Networking'!H16="","",'Networking'!H16) | J26: =IF('Networking'!I16="","",'Networking'!I16) | ... N26: =IF('Networking'!M16="","",'Networking'!M16)
A27: =IF('Security'!A3="","",'Security'!A3) | B27: Security | C27: =IF('Security'!B3="","",'Security'!B3) | D27: =IF('Security'!C3="","",'Security'!C3) | E27: =IF('Security'!D3="","",'Security'!D3) | F27: =IF('Security'!E3="","",'Security'!E3) | G27: =IF('Security'!F3="","",'Security'!F3) | H27: =IF('Security'!G3="","",'Security'!G3) | I27: =IF('Security'!H3="","",'Security'!H3) | J27: =IF('Security'!I3="","",'Security'!I3) | ... N27: =IF('Security'!M3="","",'Security'!M3)
A28: =IF('Security'!A4="","",'Security'!A4) | B28: Security | C28: =IF('Security'!B4="","",'Security'!B4) | D28: =IF('Security'!C4="","",'Security'!C4) | E28: =IF('Security'!D4="","",'Security'!D4) | F28: =IF('Security'!E4="","",'Security'!E4) | G28: =IF('Security'!F4="","",'Security'!F4) | H28: =IF('Security'!G4="","",'Security'!G4) | I28: =IF('Security'!H4="","",'Security'!H4) | J28: =IF('Security'!I4="","",'Security'!I4) | ... N28: =IF('Security'!M4="","",'Security'!M4)
A29: =IF('Security'!A5="","",'Security'!A5) | B29: Security | C29: =IF('Security'!B5="","",'Security'!B5) | D29: =IF('Security'!C5="","",'Security'!C5) | E29: =IF('Security'!D5="","",'Security'!D5) | F29: =IF('Security'!E5="","",'Security'!E5) | G29: =IF('Security'!F5="","",'Security'!F5) | H29: =IF('Security'!G5="","",'Security'!G5) | I29: =IF('Security'!H5="","",'Security'!H5) | J29: =IF('Security'!I5="","",'Security'!I5) | ... N29: =IF('Security'!M5="","",'Security'!M5)
A30: =IF('Security'!A6="","",'Security'!A6) | B30: Security | C30: =IF('Security'!B6="","",'Security'!B6) | D30: =IF('Security'!C6="","",'Security'!C6) | E30: =IF('Security'!D6="","",'Security'!D6) | F30: =IF('Security'!E6="","",'Security'!E6) | G30: =IF('Security'!F6="","",'Security'!F6) | H30: =IF('Security'!G6="","",'Security'!G6) | I30: =IF('Security'!H6="","",'Security'!H6) | J30: =IF('Security'!I6="","",'Security'!I6) | ... N30: =IF('Security'!M6="","",'Security'!M6)
A31: =IF('Security'!A7="","",'Security'!A7) | B31: Security | C31: =IF('Security'!B7="","",'Security'!B7) | D31: =IF('Security'!C7="","",'Security'!C7) | E31: =IF('Security'!D7="","",'Security'!D7) | F31: =IF('Security'!E7="","",'Security'!E7) | G31: =IF('Security'!F7="","",'Security'!F7) | H31: =IF('Security'!G7="","",'Security'!G7) | I31: =IF('Security'!H7="","",'Security'!H7) | J31: =IF('Security'!I7="","",'Security'!I7) | ... N31: =IF('Security'!M7="","",'Security'!M7)
A32: =IF('Security'!A8="","",'Security'!A8) | B32: Security | C32: =IF('Security'!B8="","",'Security'!B8) | D32: =IF('Security'!C8="","",'Security'!C8) | E32: =IF('Security'!D8="","",'Security'!D8) | F32: =IF('Security'!E8="","",'Security'!E8) | G32: =IF('Security'!F8="","",'Security'!F8) | H32: =IF('Security'!G8="","",'Security'!G8) | I32: =IF('Security'!H8="","",'Security'!H8) | J32: =IF('Security'!I8="","",'Security'!I8) | ... N32: =IF('Security'!M8="","",'Security'!M8)
A33: =IF('Security'!A9="","",'Security'!A9) | B33: Security | C33: =IF('Security'!B9="","",'Security'!B9) | D33: =IF('Security'!C9="","",'Security'!C9) | E33: =IF('Security'!D9="","",'Security'!D9) | F33: =IF('Security'!E9="","",'Security'!E9) | G33: =IF('Security'!F9="","",'Security'!F9) | H33: =IF('Security'!G9="","",'Security'!G9) | I33: =IF('Security'!H9="","",'Security'!H9) | J33: =IF('Security'!I9="","",'Security'!I9) | ... N33: =IF('Security'!M9="","",'Security'!M9)
A34: =IF('Security'!A10="","",'Security'!A10) | B34: Security | C34: =IF('Security'!B10="","",'Security'!B10) | D34: =IF('Security'!C10="","",'Security'!C10) | E34: =IF('Security'!D10="","",'Security'!D10) | F34: =IF('Security'!E10="","",'Security'!E10) | G34: =IF('Security'!F10="","",'Security'!F10) | H34: =IF('Security'!G10="","",'Security'!G10) | I34: =IF('Security'!H10="","",'Security'!H10) | J34: =IF('Security'!I10="","",'Security'!I10) | ... N34: =IF('Security'!M10="","",'Security'!M10)
A35: =IF('Security'!A11="","",'Security'!A11) | B35: Security | C35: =IF('Security'!B11="","",'Security'!B11) | D35: =IF('Security'!C11="","",'Security'!C11) | E35: =IF('Security'!D11="","",'Security'!D11) | F35: =IF('Security'!E11="","",'Security'!E11) | G35: =IF('Security'!F11="","",'Security'!F11) | H35: =IF('Security'!G11="","",'Security'!G11) | I35: =IF('Security'!H11="","",'Security'!H11) | J35: =IF('Security'!I11="","",'Security'!I11) | ... N35: =IF('Security'!M11="","",'Security'!M11)
A36: =IF('Security'!A12="","",'Security'!A12) | B36: Security | C36: =IF('Security'!B12="","",'Security'!B12) | D36: =IF('Security'!C12="","",'Security'!C12) | E36: =IF('Security'!D12="","",'Security'!D12) | F36: =IF('Security'!E12="","",'Security'!E12) | G36: =IF('Security'!F12="","",'Security'!F12) | H36: =IF('Security'!G12="","",'Security'!G12) | I36: =IF('Security'!H12="","",'Security'!H12) | J36: =IF('Security'!I12="","",'Security'!I12) | ... N36: =IF('Security'!M12="","",'Security'!M12)
A37: =IF('Security'!A13="","",'Security'!A13) | B37: Security | C37: =IF('Security'!B13="","",'Security'!B13) | D37: =IF('Security'!C13="","",'Security'!C13) | E37: =IF('Security'!D13="","",'Security'!D13) | F37: =IF('Security'!E13="","",'Security'!E13) | G37: =IF('Security'!F13="","",'Security'!F13) | H37: =IF('Security'!G13="","",'Security'!G13) | I37: =IF('Security'!H13="","",'Security'!H13) | J37: =IF('Security'!I13="","",'Security'!I13) | ... N37: =IF('Security'!M13="","",'Security'!M13)
A38: =IF('Security'!A14="","",'Security'!A14) | B38: Security | C38: =IF('Security'!B14="","",'Security'!B14) | D38: =IF('Security'!C14="","",'Security'!C14) | E38: =IF('Security'!D14="","",'Security'!D14) | F38: =IF('Security'!E14="","",'Security'!E14) | G38: =IF('Security'!F14="","",'Security'!F14) | H38: =IF('Security'!G14="","",'Security'!G14) | I38: =IF('Security'!H14="","",'Security'!H14) | J38: =IF('Security'!I14="","",'Security'!I14) | ... N38: =IF('Security'!M14="","",'Security'!M14)
... A51: =IF('Security'!A27="","",'Security'!A27) | B51: Security | C51: =IF('Security'!B27="","",'Security'!B27) | D51: =IF('Security'!C27="","",'Security'!C27) | E51: =IF('Security'!D27="","",'Security'!D27) | F51: =IF('Security'!E27="","",'Security'!E27) | G51: =IF('Security'!F27="","",'Security'!F27) | H51: =IF('Security'!G27="","",'Security'!G27) | I51: =IF('Security'!H27="","",'Security'!H27) | J51: =IF('Security'!I27="","",'Security'!I27) | ... N51: =IF('Security'!M27="","",'Security'!M27)
A52: =IF('Compute'!A3="","",'Compute'!A3) | B52: Compute | C52: =IF('Compute'!B3="","",'Compute'!B3) | D52: =IF('Compute'!C3="","",'Compute'!C3) | E52: =IF('Compute'!D3="","",'Compute'!D3) | F52: =IF('Compute'!E3="","",'Compute'!E3) | G52: =IF('Compute'!F3="","",'Compute'!F3) | H52: =IF('Compute'!G3="","",'Compute'!G3) | I52: =IF('Compute'!H3="","",'Compute'!H3) | J52: =IF('Compute'!I3="","",'Compute'!I3) | ... N52: =IF('Compute'!M3="","",'Compute'!M3)
A53: =IF('Compute'!A4="","",'Compute'!A4) | B53: Compute | C53: =IF('Compute'!B4="","",'Compute'!B4) | D53: =IF('Compute'!C4="","",'Compute'!C4) | E53: =IF('Compute'!D4="","",'Compute'!D4) | F53: =IF('Compute'!E4="","",'Compute'!E4) | G53: =IF('Compute'!F4="","",'Compute'!F4) | H53: =IF('Compute'!G4="","",'Compute'!G4) | I53: =IF('Compute'!H4="","",'Compute'!H4) | J53: =IF('Compute'!I4="","",'Compute'!I4) | ... N53: =IF('Compute'!M4="","",'Compute'!M4)
A54: =IF('Compute'!A5="","",'Compute'!A5) | B54: Compute | C54: =IF('Compute'!B5="","",'Compute'!B5) | D54: =IF('Compute'!C5="","",'Compute'!C5) | E54: =IF('Compute'!D5="","",'Compute'!D5) | F54: =IF('Compute'!E5="","",'Compute'!E5) | G54: =IF('Compute'!F5="","",'Compute'!F5) | H54: =IF('Compute'!G5="","",'Compute'!G5) | I54: =IF('Compute'!H5="","",'Compute'!H5) | J54: =IF('Compute'!I5="","",'Compute'!I5) | ... N54: =IF('Compute'!M5="","",'Compute'!M5)
...

Sheet Project
A1: Project Parameters
A2: Parameter Name | B2: Production | C2: Test | D2: DR | E2: Description | F2: Required | G2: Data Type | H2: Validation Rules | I2: Security Level | J2: Owner Team | K2: Dependencies | L2: Notes | M2: Last Updated
A3: solution.name | B3: medcore-cds | C3: medcore-cds | D3: medcore-cds | E3: Solution identifier used for resource naming and tagging across all environments | F3: Yes | G3: String | H3: lowercase alphanumeric hyphens only max 50 chars | I3: Public | J3: Cloud CoE | M3: 2025-06-18
A4: solution.region.primary | B4: us-east-1 | C4: us-east-1 | D4: us-west-2 | E4: Primary AWS region for all active CDS Platform resources | F4: Yes | G4: String | H4: Valid AWS region code | I4: Public | J4: Cloud CoE | L4: DR region is us-west-2 passive standby per SOW multi-region design | M4: 2025-06-18
A5: solution.region.dr | B5: us-west-2 | C5: us-west-2 | D5: us-west-2 | E5: Passive disaster recovery AWS region for CDS Platform | F5: Yes | G5: String | H5: Valid AWS region code | I5: Public | J5: Cloud CoE | K5: solution.region.primary | L5: Route 53 health-check failover promotes DR region; RTO target ≤ 4 hours | M5: 2025-06-18
A6: solution.environment | B6: prod | C6: qa | D6: prod | E6: Deployment environment identifier used in all resource names and tags | F6: Yes | G6: String | H6: prod|staging|qa|dev | I6: Public | J6: Cloud CoE | L6: DR environment mirrors production configuration | M6: 2025-06-18
A7: solution.account_id | B7: [aws-account-id] | C7: [aws-account-id] | D7: [aws-account-id] | E7: Dedicated AWS account ID under MedCore Clinical Applications OU | F7: Yes | G7: String | H7: 12-digit numeric | I7: Confidential | J7: Cloud CoE | L7: Dedicated CDS account under Clinical Applications OU per SOW scope | M7: 2025-06-18
A8: solution.opportunity_no | B8: OPP-2026-0047 | C8: OPP-2026-0047 | D8: OPP-2026-0047 | E8: Amatra opportunity number for cost allocation and billing reference | F8: Yes | G8: String | H8: OPP-YYYY-NNNN format | I8: Public | J8: Cloud CoE | L8: Referenced on all Amatra invoices per SOW Terms section | M8: 2025-06-18
A9: solution.phase | B9: phase1 | C9: phase1 | D9: phase1 | E9: Current active delivery phase; updated at each phase go-live milestone | F9: Yes | G9: String | H9: phase1|phase2|phase3 | I9: Public | J9: Cloud CoE | L9: Phase 1 go-live target 2026-10-31; Phase 2 by 2027-02-28; Phase 3 by 2027-06-30 | M9: 2025-06-18
A10: aws.organization_ou | B10: Clinical Applications OU | C10: Clinical Applications OU | D10: Clinical Applications OU | E10: AWS Organizations OU under which the CDS account is provisioned | F10: Yes | G10: String | H10: Valid OU name or ID | I10: Confidential | J10: Cloud CoE | K10: solution.account_id | L10: SCPs at OU level prevent PHI leaving US regions and block direct console changes in production | M10: 2025-06-18

Sheet Networking
A1: Networking Parameters
A2: Parameter Name | B2: Production | C2: Test | D2: DR | E2: Description | F2: Required | G2: Data Type | H2: Validation Rules | I2: Security Level | J2: Owner Team | K2: Dependencies | L2: Notes | M2: Last Updated
A3: networking.vpc_cidr_primary | B3: 10.10.0.0/16 | C3: 10.20.0.0/16 | D3: 10.11.0.0/16 | E3: VPC CIDR block for the CDS Platform in the primary region (us-east-1) | F3: Yes | G3: String | H3: Valid /16 CIDR block | I3: Confidential | J3: Network Team | L3: All PHI traffic on private subnets; no public internet traversal for data paths per security design | M3: 2025-06-18
A4: networking.subnet_cidr_public_az1 | B4: 10.10.0.0/24 | C4: 10.20.0.0/24 | D4: 10.11.0.0/24 | E4: Public subnet CIDR for AZ1 (ALB and NAT Gateway only; no application workloads) | F4: Yes | G4: String | H4: Valid CIDR within VPC CIDR | I4: Confidential | J4: Network Team | K4: networking.vpc_cidr_primary | L4: Only ALBs and NAT Gateways deployed in public subnets per network segmentation design | M4: 2025-06-18
A5: networking.subnet_cidr_public_az2 | B5: 10.10.1.0/24 | C5: 10.20.1.0/24 | D5: 10.11.1.0/24 | E5: Public subnet CIDR for AZ2 (ALB and NAT Gateway only; no application workloads) | F5: Yes | G5: String | H5: Valid CIDR within VPC CIDR | I5: Confidential | J5: Network Team | K5: networking.vpc_cidr_primary | M5: 2025-06-18
A6: networking.subnet_cidr_app_az1 | B6: 10.10.10.0/23 | C6: 10.20.10.0/23 | D6: 10.11.10.0/23 | E6: Private application subnet CIDR for AZ1 hosting ECS Fargate tasks and VPC-attached Lambdas | F6: Yes | G6: String | H6: Valid CIDR within VPC CIDR | I6: Confidential | J6: Network Team | K6: networking.vpc_cidr_primary | L6: No direct internet routing; all egress via NAT Gateway or PrivateLink | M6: 2025-06-18
A7: networking.subnet_cidr_app_az2 | B7: 10.10.12.0/23 | C7: 10.20.12.0/23 | D7: 10.11.12.0/23 | E7: Private application subnet CIDR for AZ2 hosting ECS Fargate tasks and VPC-attached Lambdas | F7: Yes | G7: String | H7: Valid CIDR within VPC CIDR | I7: Confidential | J7: Network Team | K7: networking.vpc_cidr_primary | M7: 2025-06-18
A8: networking.subnet_cidr_app_az3 | B8: 10.10.14.0/23 | C8: 10.20.14.0/23 | D8: 10.11.14.0/23 | E8: Private application subnet CIDR for AZ3 hosting ECS Fargate tasks and VPC-attached Lambdas | F8: Yes | G8: String | H8: Valid CIDR within VPC CIDR | I8: Confidential | J8: Network Team | K8: networking.vpc_cidr_primary | L8: Three AZs required for 99.95% availability SLA per high availability design | M8: 2025-06-18
A9: networking.subnet_cidr_data_az1 | B9: 10.10.20.0/24 | C9: 10.20.20.0/24 | D9: 10.11.20.0/24 | E9: Private data subnet CIDR for AZ1 hosting RDS Aurora and ElastiCache Redis | F9: Yes | G9: String | H9: Valid CIDR within VPC CIDR | I9: Confidential | J9: Network Team | K9: networking.vpc_cidr_primary | L9: Data tier subnets allow inbound only from application tier Security Groups | M9: 2025-06-18
A10: networking.subnet_cidr_data_az2 | B10: 10.10.21.0/24 | C10: 10.20.21.0/24 | D10: 10.11.21.0/24 | E10: Private data subnet CIDR for AZ2 hosting RDS Aurora replica and ElastiCache replica | F10: Yes | G10: String | H10: Valid CIDR within VPC CIDR | I10: Confidential | J10: Network Team | K10: networking.vpc_cidr_primary | M10: 2025-06-18
A11: networking.nat_gateway_count | B11: 2 | C11: 1 | D11: 2 | E11: Number of NAT Gateway instances for outbound AWS control-plane calls | F11: Yes | G11: Integer | H11: 1-3 | I11: Public | J11: Network Team | K11: networking.vpc_cidr_primary | L11: One per AZ (us-east-1a and us-east-1b); PrivateLink eliminates NAT for PHI data paths | M11: 2025-06-18
A12: networking.direct_connect_bandwidth_gbps | B12: 1 | C12: 0 | D12: 1 | E12: Direct Connect hosted connection bandwidth in Gbps from MedCore Nashville DC to AWS us-east-1 | F12: Yes | G12: Integer | H12: 1-100 | I12: Public | J12: Network Team | L12: Must be provisioned by MedCore by Week 8 per SOW critical path dependency | M12: 2025-06-18
A13: networking.vpn_enabled | B13: true | C13: false | D13: true | E13: Enable site-to-site VPN as secondary failover path for Direct Connect | F13: Yes | G13: Boolean | H13: true|false | I13: Public | J13: Network Team | K13: networking.direct_connect_bandwidth_gbps | L13: IKEv2 with AES-256 encryption; maintains connectivity during any Direct Connect disruption | M13: 2025-06-18
A14: networking.alb_dashboard_id | B14: [alb-dashboard-id] | C14: [alb-dashboard-id] | D14: [alb-dashboard-id] | E14: Application Load Balancer ARN or ID for the clinical dashboard and API backend (multi-AZ) | F14: Yes | G14: String | H14: Valid ALB ARN or ID | I14: Confidential | J14: Network Team | K14: networking.vpc_cidr_primary | L14: HTTPS only; WAF attached; terminates TLS 1.2+ at edge per security design | M14: 2025-06-18
A15: networking.alb_fhir_inbound_id | B15: [alb-fhir-inbound-id] | C15: [alb-fhir-inbound-id] | D15: [alb-fhir-inbound-id] | E15: Application Load Balancer ARN or ID for the Epic FHIR R4 subscription inbound endpoint | F15: Yes | G15: String | H15: Valid ALB ARN or ID | I15: Confidential | J15: Network Team | K15: networking.vpc_cidr_primary | L15: Receives Epic FHIR subscription events over Direct Connect; WAF and rate limiting attached | M15: 2025-06-18
A16: networking.privatelink_endpoints_enabled | B16: true | C16: true | D16: true | E16: Enable VPC Interface Endpoints (PrivateLink) for all AWS managed service communications | F16: Yes | G16: Boolean | H16: true|false | I16: Public | J16: Network Team | L16: Eliminates PHI egress to public internet; covers HealthLake + SageMaker + Bedrock + KMS + S3 | M16: 2025-06-18

Sheet Security
A1: Security Parameters
A2: Parameter Name | B2: Production | C2: Test | D2: DR | E2: Description | F2: Required | G2: Data Type | H2: Validation Rules | I2: Security Level | J2: Owner Team | K2: Dependencies | L2: Notes | M2: Last Updated
A3: security.kms.healthlake_key_id | B3: [kms-healthlake-key-id] | C3: [kms-healthlake-key-id] | D3: [kms-healthlake-key-id] | E3: KMS CMK ARN for encrypting Amazon HealthLake PHI FHIR datastore | F3: Yes | G3: String | H3: Valid KMS key ARN or alias | I3: Secret | J3: Security Team | L3: Dedicated CMK per datastore for blast-radius isolation; annual auto-rotation; CISO holds admin | M3: 2025-06-18
A4: security.kms.aurora_key_id | B4: [kms-aurora-key-id] | C4: [kms-aurora-key-id] | D4: [kms-aurora-key-id] | E4: KMS CMK ARN for encrypting RDS Aurora PostgreSQL data at rest | F4: Yes | G4: String | H4: Valid KMS key ARN or alias | I4: Secret | J4: Security Team | L4: Separate CMK from HealthLake CMK; key deletion requires 30-day waiting period and CISO approval | M4: 2025-06-18
A5: security.kms.s3_datalake_key_id | B5: [kms-s3-datalake-key-id] | C5: [kms-s3-datalake-key-id] | D5: [kms-s3-datalake-key-id] | E5: KMS CMK ARN for encrypting S3 data lake buckets (HL7 event archive and ML artefacts) | F5: Yes | G5: String | H5: Valid KMS key ARN or alias | I5: Secret | J5: Security Team | L5: PHI classified as Restricted; separate CMK from audit bucket for blast-radius isolation | M5: 2025-06-18
A6: security.kms.s3_audit_key_id | B6: [kms-s3-audit-key-id] | C6: [kms-s3-audit-key-id] | D6: [kms-s3-audit-key-id] | E6: KMS CMK ARN for encrypting S3 CloudTrail audit log delivery bucket | F6: Yes | G6: String | H6: Valid KMS key ARN or alias | I6: Secret | J6: Security Team | L6: 7-year WORM retention via S3 Object Lock Compliance mode; HIPAA §164.312(b) requirement | M6: 2025-06-18
A7: security.kms.elasticache_key_id | B7: [kms-elasticache-key-id] | C7: [kms-elasticache-key-id] | D7: [kms-elasticache-key-id] | E7: KMS CMK ARN for encrypting ElastiCache Redis at rest | F7: Yes | G7: String | H7: Valid KMS key ARN or alias | I7: Secret | J7: Security Team | K7: cache.elasticache.cluster_id | L7: Patient feature vectors contain PHI-adjacent data; dedicated CMK per security design | M7: 2025-06-18
A8: security.kms.ebs_key_id | B8: [kms-ebs-key-id] | C8: [kms-ebs-key-id] | D8: [kms-ebs-key-id] | E8: KMS CMK ARN for encrypting EBS volumes attached to MSK brokers and SageMaker instances | F8: Yes | G8: String | H8: Valid KMS key ARN or alias | I8: Secret | J8: Security Team | L8: Covers MSK broker EBS and SageMaker training job storage; annual auto-rotation enabled | M8: 2025-06-18
A9: security.kms.key_rotation_enabled | B9: true | C9: true | D9: true | E9: Enable automatic annual rotation for all KMS Customer Managed Keys | F9: Yes | G9: Boolean | H9: true|false | I9: Public | J9: Security Team | L9: HIPAA and SOC 2 control; AWS Config rule generates non-compliant finding if rotation disabled | M9: 2025-06-18
A10: security.cognito.user_pool_id | B10: [cognito-user-pool-id] | C10: [cognito-user-pool-id] | D10: [cognito-user-pool-id] | E10: Amazon Cognito User Pool ID for SAML 2.0 federation and RBAC enforcement | F10: Yes | G10: String | H10: Valid Cognito User Pool ID format | I10: Confidential | J10: Security Team | L10: Federated to Azure AD via SAML 2.0; enforces 4 clinical role types per IAM design | M10: 2025-06-18
A11: security.cognito.client_id | B11: [cognito-app-client-id] | C11: [cognito-app-client-id] | D11: [cognito-app-client-id] | E11: Cognito App Client ID for the clinical dashboard SPA OAuth 2.0 flow | F11: Yes | G11: String | H11: Alphanumeric Cognito client ID | I11: Confidential | J11: Security Team | K11: security.cognito.user_pool_id | L11: JWT issued to this client; validated by Lambda authorizer on all API Gateway calls | M11: 2025-06-18
A12: security.saml.azure_ad_metadata_url | B12: [azure-ad-saml-metadata-url] | C12: [azure-ad-saml-metadata-url] | D12: [azure-ad-saml-metadata-url] | E12: Azure Active Directory SAML 2.0 IdP metadata endpoint URL for Cognito federation | F12: Yes | G12: String | H12: Valid HTTPS URL | I12: Confidential | J12: Security Team | K12: security.cognito.user_pool_id | L12: MedCore identity admin must provide SAML metadata by Week 10 per SOW dependency schedule | M12: 2025-06-18
A13: security.mfa_enabled | B13: true | C13: false | D13: true | E13: Require multi-factor authentication; enforced at Azure AD layer per MedCore policy | F13: Yes | G13: Boolean | H13: true|false | I13: Public | J13: Security Team | K13: security.saml.azure_ad_metadata_url | L13: MFA enforced by Azure AD (Microsoft Authenticator); Amatra does not modify Azure AD MFA config | M13: 2025-06-18
A14: security.cloudtrail_trail_arn | B14: [cloudtrail-trail-arn] | C14: [cloudtrail-trail-arn] | D14: [cloudtrail-trail-arn] | E14: ARN of the organization-level CloudTrail trail for PHI audit logging | F14: Yes | G14: String | H14: Valid CloudTrail trail ARN | I14: Confidential | J14: Security Team | K14: storage.s3.audit_bucket_name | L14: 7-year WORM retention; log file validation enabled; disabling generates Critical Security Hub finding | M14: 2025-06-18
A15: security.audit_log_retention_years | B15: 7 | C15: 1 | D15: 7 | E15: Audit log retention period in years for CloudTrail PHI access events per HIPAA minimum | F15: Yes | G15: Integer | H15: 1-10 | I15: Public | J15: Security Team | K15: security.cloudtrail_trail_arn | L15: HIPAA §164.312(b) requires 7-year retention; S3 Object Lock Compliance mode enforces immutability | M15: 2025-06-18
A16: security.cloudwatch_log_retention_days | B16: 90 | C16: 30 | D16: 90 | E16: CloudWatch Logs retention period in days for application and infrastructure logs | F16: Yes | G16: Integer | H16: 1-3653 | I16: Public | J16: Operations | L16: 90-day hot retention; older logs archived to S3 Glacier for cost optimization | M16: 2025-06-18
A17: security.waf_enabled | B17: true | C17: false | D17: true | E17: Enable AWS WAF on all ALBs and API Gateway endpoints | F17: Yes | G17: Boolean | H17: true|false | I17: Public | J17: Security Team | K17: networking.alb_dashboard_id | L17: OWASP Top 10 + AWS managed rules + healthcare-specific rule set; WAF logs retained 90 days | M17: 2025-06-18
A18: security.guardduty_enabled | B18: true | C18: true | D18: true | E18: Enable Amazon GuardDuty threat detection across the Clinical Applications OU | F18: Yes | G18: Boolean | H18: true|false | I18: Public | J18: Security Team | L18: Continuous ML-driven threat detection; High/Critical findings page CISO on-call via PagerDuty | M18: 2025-06-18
A19: security.config_enabled | B19: true | C19: true | D19: true | E19: Enable AWS Config with HIPAA rule set for continuous compliance monitoring | F19: Yes | G19: Boolean | H19: true|false | I19: Public | J19: Security Team | L19: HIPAA configuration drift detected within 15 minutes; Critical findings remediated in 24h per SLA | M19: 2025-06-18
A20: security.security_hub_enabled | B20: true | C20: true | D20: true | E20: Enable AWS Security Hub for aggregated compliance and security findings | F20: Yes | G20: Boolean | H20: true|false | I20: Public | J20: Security Team | K20: security.config_enabled | L20: Aggregates GuardDuty + Config + Inspector + Macie findings; CISO audit pane for SOC 2 Type II | M20: 2025-06-18
A21: security.macie_enabled | B21: true | C21: false | D21: true | E21: Enable Amazon Macie for automated PHI data classification in S3 buckets | F21: Yes | G21: Boolean | H21: true|false | I21: Public | J21: Security Team | K21: storage.s3.datalake_bucket_name | L21: Alerts if PHI found in non-production or non-encrypted buckets; SOC 2 CC6 detective control | M21: 2025-06-18
A22: security.secrets_manager.aurora_secret_arn | B22: [aurora-secret-arn] | C22: [aurora-secret-arn] | D22: [aurora-secret-arn] | E22: ARN of the Secrets Manager secret storing Aurora PostgreSQL credentials | F22: Yes | G22: String | H22: Valid Secrets Manager ARN | I22: Secret | J22: Security Team | K22: database.aurora.cluster_identifier | L22: 30-day automatic rotation via built-in RDS Lambda; every GetSecretValue call logged to CloudTrail | M22: 2025-06-18
A23: security.secrets_manager.epic_oauth_secret_arn | B23: [epic-oauth-secret-arn] | C23: [epic-oauth-secret-arn] | D23: [epic-oauth-secret-arn] | E23: ARN of the Secrets Manager secret storing Epic FHIR R4 SMART on FHIR OAuth 2.0 client credentials | F23: Yes | G23: String | H23: Valid Secrets Manager ARN | I23: Secret | J23: Security Team | K23: integration.epic.fhir_base_url | L23: Rotated per Epic 90-day OAuth token expiry; automatic re-issuance configured in rotation Lambda | M23: 2025-06-18
A24: security.secrets_manager.mirth_api_key_arn | B24: [mirth-api-key-arn] | C24: [mirth-api-key-arn] | D24: [mirth-api-key-arn] | E24: ARN of the Secrets Manager secret storing Mirth Connect integration API key | F24: Yes | G24: String | H24: Valid Secrets Manager ARN | I24: Secret | J24: Security Team | K24: integration.mirth.endpoint_url | L24: 30-day automatic rotation; never stored in Lambda environment variables or IaC configuration files | M24: 2025-06-18
A25: security.secrets_manager.datadog_api_key_arn | B25: [datadog-api-key-arn] | C25: [datadog-api-key-arn] | D25: [datadog-api-key-arn] | E25: ARN of the Secrets Manager secret storing Datadog APM API key | F25: Yes | G25: String | H25: Valid Secrets Manager ARN | I25: Secret | J25: Security Team | K25: monitoring.datadog.site | L25: Rotated annually; injected into ECS task definition at deploy time via Secrets Manager integration | M25: 2025-06-18
A26: security.iam.access_analyzer_enabled | B26: true | C26: true | D26: true | E26: Enable IAM Access Analyzer to detect overly permissive resource policies | F26: Yes | G26: Boolean | H26: true|false | I26: Public | J26: Security Team | L26: Continuously identifies IAM policies granting unintended cross-account or public access | M26: 2025-06-18
A27: security.tls_minimum_version | B27: TLSv1.2 | C27: TLSv1.2 | D27: TLSv1.2 | E27: Minimum TLS version enforced on all ALB listeners and API Gateway endpoints | F27: Yes | G27: String | H27: TLSv1.2|TLSv1.3 | I27: Public | J27: Security Team | L27: HIPAA §164.312(e) mandate; HTTP redirected to HTTPS with 301 on all ALB listeners | M27: 2025-06-18

Sheet Compute
A1: Compute Parameters
A2: Parameter Name | B2: Production | C2: Test | D2: DR | E2: Description | F2: Required | G2: Data Type | H2: Validation Rules | I2: Security Level | J2: Owner Team | K2: Dependencies | L2: Notes | M2: Last Updated
A3: compute.ecs.cluster_name | B3: medcore-cds-prod-cluster | C3: medcore-cds-qa-cluster | D3: medcore-cds-prod-cluster | E3: ECS cluster name for dashboard and API backend Fargate tasks | F3: Yes | G3: String | H3: medcore-cds-{env}-cluster pattern | I3: Public | J3: Cloud CoE | K3: solution.environment | M3: 2025-06-18
A4: compute.ecs.task_cpu | B4: 2048 | C4: 1024 | D4: 2048 | E4: CPU units allocated per ECS Fargate task (1024 = 1 vCPU) | F4: Yes | G4: Integer | H4: 256|512|1024|2048|4096 | I4: Public | J4: Development | L4: 2 vCPU per task per detailed design compute sizing; scale to 4096 if P95 latency elevated | M4: 2025-06-18
A5: compute.ecs.task_memory_mb | B5: 4096 | C5: 2048 | D5: 4096 | E5: Memory in MB allocated per ECS Fargate task | F5: Yes | G5: Integer | H5: 512|1024|2048|4096|8192|16384 | I5: Public | J5: Development | K5: compute.ecs.task_cpu | L5: Must be a valid Fargate CPU/memory combination per AWS documentation | M5: 2025-06-18
A6: compute.ecs.scaling_min | B6: 4 | C6: 2 | D6: 4 | E6: Minimum ECS Fargate task count across all AZs for dashboard and API tiers | F6: Yes | G6: Integer | H6: 1-100 | I6: Public | J6: Operations | L6: Minimum 4 tasks ensures at least 2 per AZ across 2 AZs; supports 99.95% availability SLA | M6: 2025-06-18
A7: compute.ecs.scaling_max | B7: 12 | C7: 4 | D7: 12 | E7: Maximum ECS Fargate task count for auto-scaling ceiling | F7: Yes | G7: Integer | H7: 1-200 | I7: Public | J7: Operations | K7: compute.ecs.scaling_min | L7: Ceiling sized for 18-hospital concurrent peak; scale-out on ALB request count metric | M7: 2025-06-18
A8: compute.lambda.fhir_connector.memory_mb | B8: 1024 | C8: 512 | D8: 1024 | E8: Memory in MB for Epic FHIR R4 connector Lambda function | F8: Yes | G8: Integer | H8: 128-10240 | I8: Public | J8: Development | L8: Sized for JSON parsing and Kinesis produce operations; increase if P99 latency exceeds 500ms | M8: 2025-06-18
A9: compute.lambda.fhir_connector.timeout_seconds | B9: 30 | C9: 30 | D9: 30 | E9: Timeout in seconds for Epic FHIR R4 connector Lambda function | F9: Yes | G9: Integer | H9: 1-900 | I9: Public | J9: Development | K9: compute.lambda.fhir_connector.memory_mb | L9: Must complete within 30s including schema validation and Kinesis produce | M9: 2025-06-18
A10: compute.lambda.hl7_adapter.memory_mb | B10: 1024 | C10: 512 | D10: 1024 | E10: Memory in MB for HL7 v2.3 Mirth Connect adapter Lambda function | F10: Yes | G10: Integer | H10: 128-10240 | I10: Public | J10: Development | L10: Processes ADT and ORU message types from Mirth Connect via PrivateLink | M10: 2025-06-18
A11: compute.lambda.hl7_adapter.timeout_seconds | B11: 30 | C11: 30 | D11: 30 | E11: Timeout in seconds for HL7 v2.3 Mirth Connect adapter Lambda function | F11: Yes | G11: Integer | H11: 1-900 | I11: Public | J11: Development | K11: compute.lambda.hl7_adapter.memory_mb | L11: Must complete within 30s including HL7 segment parsing and Kinesis produce | M11: 2025-06-18
A12: compute.lambda.inference_orchestrator.memory_mb | B12: 2048 | C12: 1024 | D12: 2048 | E12: Memory in MB for inference orchestrator Lambda (retrieves features and invokes SageMaker endpoints) | F12: Yes | G12: Integer | H12: 128-10240 | I12: Public | J12: Development | L12: Must accommodate ElastiCache read + SageMaker invoke + Bedrock invoke within 3-second budget | M12: 2025-06-18
A13: compute.lambda.alert_router.memory_mb | B13: 512 | C13: 256 | D13: 512 | E13: Memory in MB for alert routing Lambda (EventBridge to SNS and Epic CDS Hooks write-back) | F13: Yes | G13: Integer | H13: 128-10240 | I13: Public | J13: Development | K13: cache.elasticache.cluster_id | L13: Handles duplicate suppression via Redis and alert persistence to RDS Aurora | M13: 2025-06-18
A14: compute.sagemaker.sepsis_endpoint.instance_type | B14: ml.m5.xlarge | C14: ml.m5.large | D14: ml.m5.xlarge | E14: SageMaker real-time inference endpoint instance type for sepsis risk model | F14: Yes | G14: String | H14: Valid SageMaker instance type | I14: Public | J14: Cloud CoE | K14: compute.sagemaker.sepsis_endpoint.min_instances | L14: Upgrade to ml.m5.2xlarge if CPU exceeds 70% at peak load per monitoring thresholds | M14: 2025-06-18
A15: compute.sagemaker.sepsis_endpoint.min_instances | B15: 2 | C15: 1 | D15: 2 | E15: Minimum instance count for sepsis SageMaker endpoint; ensures multi-AZ coverage | F15: Yes | G15: Integer | H15: 1-10 | I15: Public | J15: Cloud CoE | L15: Minimum 2 required for 99.95% availability SLA; auto-scales up to 6 at peak load | M15: 2025-06-18
A16: compute.sagemaker.sepsis_endpoint.max_instances | B16: 6 | C16: 2 | D16: 6 | E16: Maximum instance count for sepsis SageMaker endpoint auto-scaling policy | F16: Yes | G16: Integer | H16: 1-100 | I16: Public | J16: Cloud CoE | K16: compute.sagemaker.sepsis_endpoint.min_instances | L16: Scale-out on SageMakerVariantInvocationsPerInstance metric at 70% CPU threshold | M16: 2025-06-18
A17: compute.sagemaker.readmission_endpoint.instance_type | B17: ml.m5.xlarge | C17: ml.m5.large | D17: ml.m5.xlarge | E17: SageMaker real-time inference endpoint instance type for 30-day readmission model (Phase 2) | F17: Yes | G17: String | H17: Valid SageMaker instance type | I17: Public | J17: Cloud CoE | K17: compute.sagemaker.readmission_endpoint.min_instances | L17: Phase 2 model; deployed by 2027-02-28 per SOW milestone M6 | M17: 2025-06-18
A18: compute.sagemaker.readmission_endpoint.min_instances | B18: 2 | C18: 1 | D18: 2 | E18: Minimum instance count for readmission SageMaker endpoint | F18: Yes | G18: Integer | H18: 1-10 | I18: Public | J18: Cloud CoE | L18: Phase 2 deployment; same sizing pattern as sepsis endpoint | M18: 2025-06-18
A19: compute.sagemaker.rapid_response_endpoint.instance_type | B19: ml.m5.xlarge | C19: ml.m5.large | D19: ml.m5.xlarge | E19: SageMaker real-time inference endpoint instance type for rapid-response / early deterioration model (Phase 2) | F19: Yes | G19: String | H19: Valid SageMaker instance type | I19: Public | J19: Cloud CoE | K19: compute.sagemaker.rapid_response_endpoint.min_instances | L19: Phase 2 model; deployed by 2027-02-28 per SOW milestone M6 | M19: 2025-06-18
A20: compute.sagemaker.rapid_response_endpoint.min_instances | B20: 2 | C20: 1 | D20: 2 | E20: Minimum instance count for rapid-response SageMaker endpoint | F20: Yes | G20: Integer | H20: 1-10 | I20: Public | J20: Cloud CoE | L20: Phase 2 deployment; same HA sizing pattern as sepsis endpoint | M20: 2025-06-18
A21: compute.sagemaker.training.instance_type | B21: ml.p3.2xlarge | C21: ml.m5.xlarge | D21: ml.p3.2xlarge | E21: SageMaker training job instance type for weekly model retraining pipelines | F21: Yes | G21: String | H21: Valid SageMaker instance type | I21: Public | J21: Cloud CoE | L21: On-demand only; no standing instances; Spot training available for non-critical retraining runs | M21: 2025-06-18

Sheet Storage
A1: Storage Parameters
A2: Parameter Name | B2: Production | C2: Test | D2: DR | E2: Description | F2: Required | G2: Data Type | H2: Validation Rules | I2: Security Level | J2: Owner Team | K2: Dependencies | L2: Notes | M2: Last Updated
A3: storage.s3.datalake_bucket_name | B3: [s3-datalake-bucket-name] | C3: [s3-datalake-bucket-name] | D3: [s3-datalake-bucket-name] | E3: S3 bucket name for PHI data lake (HL7 event archives and ML model artefacts) | F3: Yes | G3: String | H3: Globally unique; medcore-cds-{env}-datalake-{account-id} pattern | I3: Confidential | J3: Operations | K3: solution.account_id | L3: Cross-region replication to us-west-2 in real-time; KMS encrypted; Macie PHI classification scans | M3: 2025-06-18
A4: storage.s3.audit_bucket_name | B4: [s3-audit-bucket-name] | C4: [s3-audit-bucket-name] | D4: [s3-audit-bucket-name] | E4: S3 bucket name for CloudTrail PHI audit log delivery | F4: Yes | G4: String | H4: Globally unique; medcore-cds-{env}-audit-{account-id} pattern | I4: Confidential | J4: Security Team | K4: security.cloudtrail_trail_arn | L4: S3 Object Lock Compliance mode; 7-year WORM retention; HIPAA §164.312(b) compliance bucket | M4: 2025-06-18
A5: storage.s3.model_artefacts_bucket_name | B5: [s3-model-artefacts-bucket-name] | C5: [s3-model-artefacts-bucket-name] | D5: [s3-model-artefacts-bucket-name] | E5: S3 bucket name for SageMaker model artefacts and training job outputs | F5: Yes | G5: String | H5: Globally unique; medcore-cds-{env}-models-{account-id} pattern | I5: Confidential | J5: Cloud CoE | K5: solution.account_id | L5: SageMaker Model Registry references this bucket; versioning enabled; KMS encrypted | M5: 2025-06-18
A6: storage.s3.object_lock_retention_years | B6: 7 | C6: 0 | D6: 7 | E6: S3 Object Lock compliance retention period in years for the audit log bucket | F6: Yes | G6: Integer | H6: 1-100 | I6: Public | J6: Security Team | K6: storage.s3.audit_bucket_name | L6: 7-year WORM retention per HIPAA; Compliance mode prevents deletion even by bucket owner | M6: 2025-06-18
A7: storage.s3.cross_region_replication_enabled | B7: true | C7: false | D7: true | E7: Enable S3 cross-region replication from us-east-1 to us-west-2 for all data lake buckets | F7: Yes | G7: Boolean | H7: true|false | I7: Public | J7: Operations | K7: storage.s3.datalake_bucket_name | L7: Supports RPO ≤ 15 minutes target for multi-region DR; real-time replication in production | M7: 2025-06-18
A8: storage.healthlake.datastore_id | B8: [healthlake-datastore-id] | C8: [healthlake-datastore-id] | D8: [healthlake-datastore-id] | E8: Amazon HealthLake FHIR R4 datastore ID for PHI persistence and longitudinal patient records | F8: Yes | G8: String | H8: Valid HealthLake datastore ID | I8: Confidential | J8: Cloud CoE | L8: HIPAA-eligible FHIR R4 datastore; daily FHIR export to S3 with Object Lock for 7-year retention | M8: 2025-06-18
A9: storage.healthlake.fhir_version | B9: R4 | C9: R4 | D9: R4 | E9: FHIR version for Amazon HealthLake datastore configuration | F9: Yes | G9: String | H9: R4 | I9: Public | J9: Cloud CoE | K9: storage.healthlake.datastore_id | L9: FHIR R4 required for Epic SMART on FHIR OAuth 2.0 integration per SOW scope | M9: 2025-06-18
A10: storage.healthlake.active_storage_tb | B10: 1 | C10: 0.1 | D10: 1 | E10: Expected active FHIR store storage in TB at full 18-hospital utilization | F10: Yes | G10: Number | H10: 0.1-100.0 | I10: Public | J10: Cloud CoE | K10: storage.healthlake.datastore_id | L10: 1 TB active + 500 GB/month import per SOW scope parameters; review annually at full utilization | M10: 2025-06-18
A11: storage.healthlake.retention_years | B11: 7 | C11: 1 | D11: 7 | E11: Minimum retention period in years for HealthLake FHIR patient data | F11: Yes | G11: Integer | H11: 1-10 | I11: Public | J11: Security Team | K11: storage.healthlake.datastore_id | L11: HIPAA minimum 7-year retention; HealthLake exports backed up to S3 with Object Lock | M11: 2025-06-18
A12: storage.redshift.cluster_identifier | B12: medcore-cds-prod-redshift | C12: medcore-cds-qa-redshift | D12: medcore-cds-prod-redshift | E12: Amazon Redshift cluster identifier for longitudinal outcomes warehouse | F12: Yes | G12: String | H12: medcore-cds-{env}-redshift pattern | I12: Confidential | J12: Cloud CoE | K12: solution.environment | L12: ra3.xlplus single node; stores sepsis events and readmission instances for model performance monitoring | M12: 2025-06-18
A13: storage.redshift.node_type | B13: ra3.xlplus | C13: dc2.large | D13: ra3.xlplus | E13: Amazon Redshift node type for the outcomes analytics warehouse | F13: Yes | G13: String | H13: Valid Redshift node type | I13: Public | J13: Cloud CoE | K13: storage.redshift.cluster_identifier | L13: ra3.xlplus per detailed design compute sizing; Reserved Node pricing applied at steady state | M13: 2025-06-18
A14: storage.redshift.snapshot_retention_days | B14: 7 | C14: 1 | D14: 7 | E14: Automated snapshot retention in days for Redshift cluster | F14: Yes | G14: Integer | H14: 1-35 | I14: Public | J14: Cloud CoE | K14: storage.redshift.cluster_identifier | L14: Analytics only; no SLA impact on clinical workload; 7-day retention sufficient per data design | M14: 2025-06-18

Sheet Database
A1: Database Parameters
A2: Parameter Name | B2: Production | C2: Test | D2: DR | E2: Description | F2: Required | G2: Data Type | H2: Validation Rules | I2: Security Level | J2: Owner Team | K2: Dependencies | L2: Notes | M2: Last Updated
A3: database.aurora.cluster_identifier | B3: medcore-cds-prod-aurora-cluster | C3: medcore-cds-qa-aurora-cluster | D3: medcore-cds-prod-aurora-cluster | E3: RDS Aurora PostgreSQL cluster identifier for risk scores and alert history | F3: Yes | G3: String | H3: medcore-cds-{env}-aurora-cluster pattern | I3: Confidential | J3: Database Team | K3: solution.environment | L3: Stores risk scores and alert history; PHI-adjacent data; KMS encrypted at rest | M3: 2025-06-18
A4: database.aurora.instance_type | B4: db.r6g.large | C4: db.r6g.medium | D4: db.r6g.large | E4: RDS Aurora PostgreSQL instance class for primary and replica nodes | F4: Yes | G4: String | H4: Valid RDS instance class | I4: Public | J4: Database Team | K4: database.aurora.cluster_identifier | L4: db.r6g.large per detailed design compute sizing; scale up if replica lag exceeds 5 seconds | M4: 2025-06-18
A5: database.aurora.multi_az_enabled | B5: true | C5: false | D5: true | E5: Enable Multi-AZ replication for Aurora PostgreSQL primary instance | F5: Yes | G5: Boolean | H5: true|false | I5: Public | J5: Database Team | K5: database.aurora.cluster_identifier | L5: Must be true in production and DR to meet 99.95% availability SLA; 30-60s automatic failover | M5: 2025-06-18
A6: database.aurora.backup_retention_days | B6: 35 | C6: 7 | D6: 35 | E6: Automated snapshot retention period in days for Aurora PostgreSQL | F6: Yes | G6: Integer | H6: 1-35 | I6: Public | J6: Database Team | K6: database.aurora.cluster_identifier | L6: 35-day maximum enables PITR for full audit window; HIPAA archive via S3 for 7-year minimum | M6: 2025-06-18
A7: database.aurora.db_name | B7: medcore_cds | C7: medcore_cds | D7: medcore_cds | E7: Database name within the Aurora PostgreSQL cluster | F7: Yes | G7: String | H7: Lowercase alphanumeric underscores | I7: Confidential | J7: Database Team | K7: database.aurora.cluster_identifier | M7: 2025-06-18
A8: database.aurora.master_username | B8: [aurora-master-username] | C8: [aurora-master-username] | D8: [aurora-master-username] | E8: Aurora PostgreSQL master username stored in Secrets Manager; never in plaintext | F8: Yes | G8: String | H8: Valid PostgreSQL username | I8: Secret | J8: Database Team | K8: security.secrets_manager.aurora_secret_arn | L8: Rotated automatically every 30 days via Secrets Manager RDS rotation Lambda | M8: 2025-06-18
A9: database.aurora.master_password | B9: [aurora-master-password] | C9: [aurora-master-password] | D9: [aurora-master-password] | E9: Aurora PostgreSQL master password stored in Secrets Manager; never committed to IaC or code | F9: Yes | G9: String | H9: Min 16 chars with complexity requirements | I9: Secret | J9: Database Team | K9: security.secrets_manager.aurora_secret_arn | L9: 30-day automatic rotation via Secrets Manager; never stored in environment variables or logs | M9: 2025-06-18
A10: database.aurora.ssl_mode | B10: require | C10: require | D10: require | E10: SSL enforcement mode for Aurora PostgreSQL client connections | F10: Yes | G10: String | H10: disable|allow|prefer|require|verify-ca|verify-full | I10: Confidential | J10: Security Team | K10: database.aurora.cluster_identifier | L10: HIPAA TLS 1.2+ mandate; all application connections must present valid SSL | M10: 2025-06-18
A11: database.aurora.deletion_protection | B11: true | C11: false | D11: true | E11: Enable deletion protection on Aurora cluster to prevent accidental drops | F11: Yes | G11: Boolean | H11: true|false | I11: Public | J11: Database Team | K11: database.aurora.cluster_identifier | L11: Must be true in production and DR; AWS Config rule enforces compliance | M11: 2025-06-18

Sheet Cache
A1: Cache Parameters
A2: Parameter Name | B2: Production | C2: Test | D2: DR | E2: Description | F2: Required | G2: Data Type | H2: Validation Rules | I2: Security Level | J2: Owner Team | K2: Dependencies | L2: Notes | M2: Last Updated
A3: cache.elasticache.cluster_id | B3: medcore-cds-prod-redis | C3: medcore-cds-qa-redis | D3: medcore-cds-prod-redis | E3: ElastiCache Redis cluster identifier for patient context and feature vector caching | F3: Yes | G3: String | H3: medcore-cds-{env}-redis pattern | I3: Confidential | J3: Infrastructure | K3: solution.environment | L3: Sub-3-second inference SLA requires sub-millisecond cache reads; target cache hit ratio ≥ 90% | M3: 2025-06-18
A4: cache.elasticache.node_type | B4: cache.r7g.large | C4: cache.r6g.medium | D4: cache.r7g.large | E4: ElastiCache Redis node instance type | F4: Yes | G4: String | H4: Valid ElastiCache node type | I4: Public | J4: Infrastructure | K4: cache.elasticache.cluster_id | L4: r7g.large provides 13GB memory; right-size after 90 days of production cache hit ratio data | M4: 2025-06-18
A5: cache.elasticache.multi_az_enabled | B5: true | C5: false | D5: true | E5: Enable Multi-AZ replication with automatic failover for ElastiCache Redis | F5: Yes | G5: Boolean | H5: true|false | I5: Public | J5: Infrastructure | K5: cache.elasticache.cluster_id | L5: Primary (us-east-1a) + replica (us-east-1b); 60-second automatic failover on primary failure | M5: 2025-06-18
A6: cache.elasticache.at_rest_encryption | B6: true | C6: true | D6: true | E6: Enable encryption at rest for ElastiCache Redis using dedicated KMS CMK | F6: Yes | G6: Boolean | H6: true|false | I6: Public | J6: Security Team | K6: cache.elasticache.cluster_id, security.kms.elasticache_key_id | L6: HIPAA PHI protection mandate; separate CMK per data store for blast-radius isolation | M6: 2025-06-18
A7: cache.elasticache.ttl_patient_context_seconds | B7: 14400 | C7: 14400 | D7: 14400 | E7: TTL in seconds for patient feature vector entries in Redis (4 hours = maximum clinical review window) | F7: Yes | G7: Integer | H7: 60-86400 | I7: Public | J7: Development | K7: cache.elasticache.cluster_id | L7: 4-hour TTL aligned to active inpatient clinical review window per data architecture design | M7: 2025-06-18
A8: cache.elasticache.duplicate_suppression_ttl_seconds | B8: 1800 | C8: 1800 | D8: 1800 | E8: TTL in seconds for alert duplicate suppression window in Redis (30 minutes per alert type) | F8: Yes | G8: Integer | H8: 60-3600 | I8: Public | J8: Development | K8: cache.elasticache.cluster_id | L8: Prevents repeated same-type alerts per patient within 30-minute window; configurable via SSM | M8: 2025-06-18

Sheet Application
A1: Application Parameters
A2: Parameter Name | B2: Production | C2: Test | D2: DR | E2: Description | F2: Required | G2: Data Type | H2: Validation Rules | I2: Security Level | J2: Owner Team | K2: Dependencies | L2: Notes | M2: Last Updated
A3: application.name | B3: medcore-cds | C3: medcore-cds | D3: medcore-cds | E3: Application identifier used for logging and monitoring across all tiers | F3: Yes | G3: String | H3: Alphanumeric and hyphens max 50 chars | I3: Public | J3: Development | K3: solution.name | M3: 2025-06-18
A4: application.version | B4: 1.0.0 | C4: 1.0.0 | D4: 1.0.0 | E4: Current application version; updated on each production deployment | F4: Yes | G4: String | H4: Semantic versioning X.Y.Z | I4: Public | J4: Development | L4: Follows blue/green deployment; version must match SageMaker Model Registry promoted version | M4: 2025-06-18
A5: application.log_level | B5: info | C5: debug | D5: info | E5: Logging verbosity for all ECS Fargate tasks and Lambda functions | F5: Yes | G5: String | H5: debug|info|warn|error | I5: Public | J5: Operations | L5: Production and DR use info; QA uses debug per SOW environment strategy | M5: 2025-06-18
A6: application.port | B6: 8080 | C6: 8080 | D6: 8080 | E6: Application server port for ECS Fargate clinical dashboard and API backend containers | F6: Yes | G6: Integer | H6: 1024-65535 | I6: Public | J6: Development | K6: networking.alb_dashboard_id | L6: ALB Security Group must allow inbound on this port from ALB only; no direct public access | M6: 2025-06-18
A7: application.timeout_seconds | B7: 30 | C7: 30 | D7: 30 | E7: HTTP request timeout in seconds for clinical dashboard API endpoints | F7: Yes | G7: Integer | H7: 1-300 | I7: Public | J7: Development | L7: Must exceed inference latency budget; dashboard API timeout aligned to 3-second SLA | M7: 2025-06-18
A8: application.concurrency_max | B8: 12 | C8: 4 | D8: 12 | E8: Maximum ECS Fargate task count for dashboard and API backend auto-scaling ceiling | F8: Yes | G8: Integer | H8: 1-100 | I8: Public | J8: Development | K8: compute.ecs.scaling_min | L8: Ceiling sized for 18-hospital peak load; scale-out triggered on ALB request count per task | M8: 2025-06-18
A9: application.session_timeout_hours | B9: 8 | C9: 8 | D9: 8 | E9: Clinical dashboard session token expiry in hours aligned to clinical shift length | F9: Yes | G9: Integer | H9: 1-24 | I9: Public | J9: Security Team | K9: security.cognito.user_pool_id | L9: Cognito session expiry must match; aligned to Azure AD SAML re-authentication policy per security design | M9: 2025-06-18

Sheet Monitoring
A1: Monitoring Parameters
A2: Parameter Name | B2: Production | C2: Test | D2: DR | E2: Description | F2: Required | G2: Data Type | H2: Validation Rules | I2: Security Level | J2: Owner Team | K2: Dependencies | L2: Notes | M2: Last Updated
A3: monitoring.cloudwatch.alarm_sns_topic | B3: [alarm-sns-topic-arn] | C3: [alarm-sns-topic-arn] | D3: [alarm-sns-topic-arn] | E3: SNS topic ARN for CloudWatch operational alarms routing to PagerDuty on-call rotation | F3: Yes | G3: String | H3: Valid SNS ARN | I3: Confidential | J3: Operations | L3: Critical alarms page on-call immediately; High alarms email with 4-hour SLA per monitoring design | M3: 2025-06-18
